Workbook

Sheet 360
A2: ក្រុមហ៊ុន ហ្រ្តេតហ្វ៊ូល សឹលូសិន (ខេមបូឌា) ឯ.ក | J2: ក្រុមហ៊ុន ហ្រ្តេតហ្វ៊ូល សឹលូសិន (ខេមបូឌា) ឯ.ក
A3: GRATEFUL SOLUTIONS (CAMBODIA) CO.,LTD. | J3: GRATEFUL SOLUTIONS (CAMBODIA) CO.,LTD.
C4: លេខអត្តសញ្ញាណកម្ម អតប ( VATTIN ) : K008-902404873 | L4: លេខអត្តសញ្ញាណកម្ម អតប ( VATTIN ) : K008-902404873
A5: អាស័យដ្ឋាន : # 7E0 ផ្លូវបេតុង ក្រុម 7 ភូមិទួលថ្ងាន់ សង្កាត់ទួលសង្កែទី2 ខណ្ឌឬស្សីកែវ រាជធានីភ្នំពេញ | J5: អាស័យដ្ឋាន : # 7E0 ផ្លូវបេតុង ក្រុម 7 ភូមិទួលថ្ងាន់ សង្កាត់ទួលសង្កែទី2 ខណ្ឌឬស្សីកែវ រាជធានីភ្នំពេញ
A6: លេខទូរស័ព្ទ:​098​ 484 ​414 | J6: លេខទូរស័ព្ទ:​098​ 484 ​414
A9: វិក្កយបត្រអាករ | J9: វិក្កយបត្របង់ជំនួស
A10: TAX INVOICE | J10: DISBURSEMENT
A12: ឈ្មោះអតិថិជន /Customer: ជេអ អឹភែរឹល ឯ.ក | F12: លេខវិក័យប័ត្រ: /Invoice No: | I12: GS26-360 | J12: =A12 -> ឈ្មោះអតិថិជន /Customer: ជេអ អឹភែរឹល ឯ.ក | O12: លេខវិក័យប័ត្រ: /DIS-No: | R12: DIS403 | S12: E 264562
A13: JR APPAREL CO.,LTD | E13: ការបរិច្ឆេទវិក្កយបត្រ/Invoice Date: | I13: 46268 | J13: =A13 -> JR APPAREL CO.,LTD | N13: ការបរិច្ឆេទវិក្កយបត្រ/DIS-Date: | R13: =I13 -> 46268
A14: អាស័យដ្ឋាន/Address: KAOH KNOR VILLAGE PREAEK ROKA COMMUNE KANDAL | J14: =A14 -> អាស័យដ្ឋាន/Address: KAOH KNOR VILLAGE PREAEK ROKA COMMUNE KANDAL
A15: STUENG DISTRICT, KANDAL STUENG, KANDAL, CAMBODIA | J15: =A15 -> STUENG DISTRICT, KANDAL STUENG, KANDAL, CAMBODIA
A16: លេខ អ ត ប (VATTIN) : L001-902501613 | J16: =A16 -> លេខ អ ត ប (VATTIN) : L001-902501613
A17: SHIPPER: | C17: JR APPAREL CO., LTD. | J17: =A17 -> SHIPPER: | L17: =C17 -> JR APPAREL CO., LTD.
A18: CONSIGNEE : | C18: CHAPTERONE SPORTSWEAR | G18: GROSS WEIGHT: | I18: 16864.8 | J18: =A18 -> CONSIGNEE : | L18: =C18 -> CHAPTERONE SPORTSWEAR | P18: =G18 -> GROSS WEIGHT: | R18: =I18 -> 16864.8
A19: HBL: | B19: COSU6464276980 | D19: VOLUME: | E19: 1X45'HQ | H19: POL: | I19: PNH PORT | J19: =A19 -> HBL: | K19: =B19 -> COSU6464276980 | M19: VOLUME: | N19: =E19 -> 1X45'HQ | Q19: POL: | R19: =I19 -> PNH PORT
A20: PKGS: | B20: 1,150 CTNS | D20: CTNR No: | E20: CXDU2223299 | H20: POD: | I20: USA | J20: =A20 -> PKGS: | K20: =B20 -> 1,150 CTNS | M20: CTNR No: | N20: =E20 -> CXDU2223299 | Q20: POD: | R20: =I20 -> USA
G21: 4047 | P21: =G21 -> 4047
A22: ល.រ | B22: បរិយាយមុខទំនិញ | D22: បរិមាណ | E22: ឯកតា | F22: ថ្លៃឯកតា | G22: សរុប | H22: អាករ10% | I22: ថ្លៃទំនិញ | J22: ល.រ | K22: បរិយាយមុខទំនិញ | M22: បរិមាណ | N22: ឯកតា | O22: ថ្លៃឯកតា | P22: សរុប | Q22: អាករ 0% | R22: ថ្លៃទំនិញ
A23: No | B23: Description | D23: Quatity | E23: Unit | F23: Unit Price | G23: Sub. Total | H23: VAT ( 10%) | I23: Amount | J23: No | K23: Description | M23: Quatity | N23: Unit | O23: Unit Price | P23: Sub. Total | Q23: VAT ( 0%) | R23: Amount
A25: 1 | B25: កំរៃសេវាបំពេញបែបបទនាំចេញ / EXPORT PROCESSING FEE | D25: 1 | E25: 45H | F25: 242 | G25: =ROUND(F25*D25,2) -> 242 | H25: =G25*10% -> 24.2 | I25: =H25+G25 -> 266.2 | J25: 1 | K25: LOLO AT PORT | M25: 1 | N25: 45H | O25: 77 | P25: =O25*M25 -> 77 | Q25: 0 | R25: =Q25+P25 -> 77
J26: 2 | K26: CUSTOM PROCESSING FEE | M26: 1 | N26: 45H | O26: 21.25 | P26: =O26*M26 -> 21.25 | Q26: 0 | R26: =Q26+P26 -> 21.25
J27: 3 | K27: HBL FEE | M27: 1 | N27: 45H | O27: 539 | P27: =O27*M27 -> 539 | Q27: 0 | R27: =Q27+P27 -> 539
C29: សរុប SUB TOTAL | E29: KHR | F29: =$I$29*G21 -> 979374 | H29: USD | I29: =SUM(G25:G28) -> 242 | L29: សរុប SUB TOTAL | Q29: USD | R29: =SUM(R24:R28) -> 637.25
C30: អារករលើតម្លៃបន្ថែម (VAT 10%) | E30: KHR | F30: =$I$30*$G$21 -> 97937.4 | H30: USD | I30: =ROUND(SUM(H25:H28),2) -> 24.2 | L30: អារករលើតម្លៃបន្ថែម (VAT 0%) | Q30: USD | R30: 0
C31: សរុបរួម GRAND TOTAL | E31: KHR | F31: =I31*$G$21 -> 1077311.4 | H31: USD | I31: =$I$29+$I$30 -> 266.2 | L31: សរុបរួម GRAND TOTAL | Q31: USD | R31: =SUM(R29:R30) -> 637.25 | S31: =SUM(I31+R31) -> 903.45
A33: Note: Can make payment by cross cheque to: | J33: Note: Can make payment by cross cheque to:
A34: GRATEFUL SOLUTIONS (CAMBODIA) CO.,LTD. | J34: GRATEFUL SOLUTIONS (CAMBODIA) CO.,LTD.
A35: or Deposit Cash/Cheque payment to bank as below: | J35: or Deposit Cash/Cheque payment to bank as below:
A36: KB BRASAC BANK PLC | J36: KB BRASAC BANK PLC
A37: A/NAME: GRATEFUL SOLUTIONS (CAMBODIA) CO.,LTD. | J37: A/NAME: GRATEFUL SOLUTIONS (CAMBODIA) CO.,LTD.
A38: AC/NO: 033 754 230 001 | J38: AC/NO: 033 754 230 001
A47: ________________________ | G47: _______________________________ | J47: ________________________ | P47: _______________________________
A48: ហត្ថលេខា និង ឈ្មោះអ្នកទិញ | G48: ​​​​​​​​​​​ ហត្ថលេខា និង ឈ្មោះអ្នកលក់ | J48: ហត្ថលេខា និង ឈ្មោះអ្នកទិញ | P48: ​​​​​​​​​​​ ហត្ថលេខា និង ឈ្មោះអ្នកលក់
A49: សម្គាល់ច្បាប់ដើមសំរាប់អ្នកទិញច្បាប់ចំលងសំរាប់អ្នកលក់ | J49: សម្គាល់ច្បាប់ដើមសំរាប់អ្នកទិញច្បាប់ចំលងសំរាប់អ្នកលក់
A50: Note ÷ Original invoice for customer , copies invoice for seller | J50: Note ÷ Original invoice for customer , copies invoice for seller

Sheet D001
A1: DEBIT NOTE
A4: CUSTOMER | B4: : | C4: JR APPAREL CO.,LTD | F4: DN NO | G4: JR2609001
A5: ADDRESS | B5: : | C5: KAOH KNOR VILLAGE PREAEK ROKA | F5: DATE | G5: ='360'!$I$13 -> 46268
C6: COMMUNE KANDALSTUENG DISTRICT,
C7: KANDAL STUENG, KANDAL, CAMBODIA
A9: HBL NO | B9: : | C9: ='360'!$B$19 -> COSU6464276980
A10: G.W | B10: : | C10: ='360'!$I$18 -> 16864.8 | F10: POL: | G10: ='360'!$I$19 -> PNH PORT
A11: VOLUME: | B11: : | C11: ='360'!$E$19 -> 1X45'HQ | F11: POD: | G11: ='360'!$I$20 -> USA
A12: CTNR No: | B12: : | C12: ='360'!$E$20 -> CXDU2223299 | F12: PKGS: | G12: ='360'!B20 -> 1,150 CTNS
A13: Shipper | B13: : | C13: ='360'!$C$17 -> JR APPAREL CO., LTD.
A14: Consignee | B14: : | C14: ='360'!$C$18 -> CHAPTERONE SPORTSWEAR
A16: NO | C16: DESCRIPTION | D16: Q'TY | E16: U/M | F16: PRICE | G16: TOTAL | H16: ='360'!S12 -> E 264562
A17: 1 | C17: TRUCKING FEE | D17: 1 | E17: 45H | F17: 260 | G17: =ROUND(F17*D17,2) -> 260
A18: 2 | C18: HANDLING FEE | D18: 1 | E18: 45H | F18: 35 | G18: =ROUND(F18*D18,2) -> 35
A19: 3 | C19: INCREASE TRUCKING FEE(65%) | D19: 1 | E19: TRUCK | F19: 169 | G19: =ROUND(F19*D19,2) -> 169 | H19: =G17*65% -> 169
A20: 4 | C20: DOCUMENT FEE | D20: 1 | E20: SET | F20: 25 | G20: =ROUND(F20*D20,2) -> 25
A21: 5 | C21: SERVICE TAXATION | D21: 1 | E21: SHIP | F21: 20 | G21: =ROUND(F21*D21,2) -> 20
A22: 6 | C22: PETROLL ALLOWANCE FEE | D22: 1 | E22: TIME | F22: 69 | G22: =ROUND(F22*D22,2) -> 69
A23: 7 | C23: FUEL SURCHARGE | D23: 1 | E23: 45H | F23: 40 | G23: =ROUND(F23*D23,2) -> 40
A24: 8 | C24: APPLY CO FOR INV: JRA26051 | D24: 1 | E24: INV | F24: 40 | G24: =ROUND(F24*D24,2) -> 40
A25: 9 | C25: LOLO EMPTY CONTAINER | D25: 1 | E25: 45H | F25: 49.5 | G25: =ROUND(F25*D25,2) -> 49.5
D26: GRAND TOTAL: | F26: USD | G26: =SUM(G17:G25) -> 707.5
A51: Thank you for your supporting | E51: AUTHORIZED SIGNATURE

Sheet 366
A2: ក្រុមហ៊ុន ហ្រ្តេតហ្វ៊ូល សឹលូសិន (ខេមបូឌា) ឯ.ក | J2: ក្រុមហ៊ុន ហ្រ្តេតហ្វ៊ូល សឹលូសិន (ខេមបូឌា) ឯ.ក
A3: GRATEFUL SOLUTIONS (CAMBODIA) CO.,LTD. | J3: GRATEFUL SOLUTIONS (CAMBODIA) CO.,LTD.
C4: លេខអត្តសញ្ញាណកម្ម អតប ( VATTIN ) : K008-902404873 | L4: លេខអត្តសញ្ញាណកម្ម អតប ( VATTIN ) : K008-902404873
A5: អាស័យដ្ឋាន : # 7E0 ផ្លូវបេតុង ក្រុម 7 ភូមិទួលថ្ងាន់ សង្កាត់ទួលសង្កែទី2 ខណ្ឌឬស្សីកែវ រាជធានីភ្នំពេញ | J5: អាស័យដ្ឋាន : # 7E0 ផ្លូវបេតុង ក្រុម 7 ភូមិទួលថ្ងាន់ សង្កាត់ទួលសង្កែទី2 ខណ្ឌឬស្សីកែវ រាជធានីភ្នំពេញ
A6: លេខទូរស័ព្ទ:​098​ 484 ​414 | J6: លេខទូរស័ព្ទ:​098​ 484 ​414
A9: វិក្កយបត្រអាករ | J9: វិក្កយបត្របង់ជំនួស
A10: TAX INVOICE | J10: DISBURSEMENT
A12: ឈ្មោះអតិថិជន /Customer: ជេអ អឹភែរឹល ឯ.ក | F12: លេខវិក័យប័ត្រ: /Invoice No: | I12: GS26-366 | J12: =A12 -> ឈ្មោះអតិថិជន /Customer: ជេអ អឹភែរឹល ឯ.ក | O12: លេខវិក័យប័ត្រ: /DIS-No: | R12: DIS409 | S12: E 272714
A13: JR APPAREL CO.,LTD | E13: ការបរិច្ឆេទវិក្កយបត្រ/Invoice Date: | I13: 46275 | J13: =A13 -> JR APPAREL CO.,LTD | N13: ការបរិច្ឆេទវិក្កយបត្រ/DIS-Date: | R13: =I13 -> 46275
A14: អាស័យដ្ឋាន/Address: KAOH KNOR VILLAGE PREAEK ROKA COMMUNE KANDAL | J14: =A14 -> អាស័យដ្ឋាន/Address: KAOH KNOR VILLAGE PREAEK ROKA COMMUNE KANDAL
A15: STUENG DISTRICT, KANDAL STUENG, KANDAL, CAMBODIA | J15: =A15 -> STUENG DISTRICT, KANDAL STUENG, KANDAL, CAMBODIA
A16: លេខ អ ត ប (VATTIN) : L001-902501613 | J16: =A16 -> លេខ អ ត ប (VATTIN) : L001-902501613
A17: SHIPPER: | C17: JR APPAREL CO., LTD. | J17: =A17 -> SHIPPER: | L17: =C17 -> JR APPAREL CO., LTD.
A18: CONSIGNEE : | C18: CHAPTERONE SPORTSWEAR | G18: GROSS WEIGHT: | I18: 16194.3 | J18: =A18 -> CONSIGNEE : | L18: =C18 -> CHAPTERONE SPORTSWEAR | P18: =G18 -> GROSS WEIGHT: | R18: =I18 -> 16194.3
A19: HBL: | B19: COSU6464270110 | D19: VOLUME: | E19: 1X45'HQ | H19: POL: | I19: PNH PORT | J19: =A19 -> HBL: | K19: =B19 -> COSU6464270110 | M19: VOLUME: | N19: =E19 -> 1X45'HQ | Q19: POL: | R19: =I19 -> PNH PORT
A20: PKGS: | B20: 982 CTNS | D20: CTNR No: | E20: CSNU9538620 | H20: POD: | I20: USA | J20: =A20 -> PKGS: | K20: =B20 -> 982 CTNS | M20: CTNR No: | N20: =E20 -> CSNU9538620 | Q20: POD: | R20: =I20 -> USA
G21: 4052 | P21: =G21 -> 4052
A22: ល.រ | B22: បរិយាយមុខទំនិញ | D22: បរិមាណ | E22: ឯកតា | F22: ថ្លៃឯកតា | G22: សរុប | H22: អាករ10% | I22: ថ្លៃទំនិញ | J22: ល.រ | K22: បរិយាយមុខទំនិញ | M22: បរិមាណ | N22: ឯកតា | O22: ថ្លៃឯកតា | P22: សរុប | Q22: អាករ 0% | R22: ថ្លៃទំនិញ
A23: No | B23: Description | D23: Quatity | E23: Unit | F23: Unit Price | G23: Sub. Total | H23: VAT ( 10%) | I23: Amount | J23: No | K23: Description | M23: Quatity | N23: Unit | O23: Unit Price | P23: Sub. Total | Q23: VAT ( 0%) | R23: Amount
A25: 1 | B25: កំរៃសេវាបំពេញបែបបទនាំចេញ / EXPORT PROCESSING FEE | D25: 1 | E25: 45H | F25: 242 | G25: =ROUND(F25*D25,2) -> 242 | H25: =G25*10% -> 24.2 | I25: =H25+G25 -> 266.2 | J25: 1 | K25: LOLO AT PORT | M25: 1 | N25: 45H | O25: 77 | P25: =O25*M25 -> 77 | Q25: 0 | R25: =Q25+P25 -> 77
J26: 2 | K26: CUSTOM PROCESSING FEE | M26: 1 | N26: 45H | O26: 21.25 | P26: =O26*M26 -> 21.25 | Q26: 0 | R26: =Q26+P26 -> 21.25
J27: 3 | K27: HBL FEE | M27: 1 | N27: 45H | O27: 539 | P27: =O27*M27 -> 539 | Q27: 0 | R27: =Q27+P27 -> 539
C29: សរុប SUB TOTAL | E29: KHR | F29: =$I$29*G21 -> 980584 | H29: USD | I29: =SUM(G25:G28) -> 242 | L29: សរុប SUB TOTAL | Q29: USD | R29: =SUM(R24:R28) -> 637.25
C30: អារករលើតម្លៃបន្ថែម (VAT 10%) | E30: KHR | F30: =$I$30*$G$21 -> 98058.4 | H30: USD | I30: =ROUND(SUM(H25:H28),2) -> 24.2 | L30: អារករលើតម្លៃបន្ថែម (VAT 0%) | Q30: USD | R30: 0
C31: សរុបរួម GRAND TOTAL | E31: KHR | F31: =I31*$G$21 -> 1078642.4 | H31: USD | I31: =$I$29+$I$30 -> 266.2 | L31: សរុបរួម GRAND TOTAL | Q31: USD | R31: =SUM(R29:R30) -> 637.25 | S31: =SUM(I31+R31) -> 903.45
A33: Note: Can make payment by cross cheque to: | J33: Note: Can make payment by cross cheque to:
A34: GRATEFUL SOLUTIONS (CAMBODIA) CO.,LTD. | J34: GRATEFUL SOLUTIONS (CAMBODIA) CO.,LTD.
A35: or Deposit Cash/Cheque payment to bank as below: | J35: or Deposit Cash/Cheque payment to bank as below:
A36: KB BRASAC BANK PLC | J36: KB BRASAC BANK PLC
A37: A/NAME: GRATEFUL SOLUTIONS (CAMBODIA) CO.,LTD. | J37: A/NAME: GRATEFUL SOLUTIONS (CAMBODIA) CO.,LTD.
A38: AC/NO: 033 754 230 001 | J38: AC/NO: 033 754 230 001
A49: ________________________ | G49: _______________________________ | J49: ________________________ | P49: _______________________________
A50: ហត្ថលេខា និង ឈ្មោះអ្នកទិញ | G50: ​​​​​​​​​​​ ហត្ថលេខា និង ឈ្មោះអ្នកលក់ | J50: ហត្ថលេខា និង ឈ្មោះអ្នកទិញ | P50: ​​​​​​​​​​​ ហត្ថលេខា និង ឈ្មោះអ្នកលក់
A51: សម្គាល់ច្បាប់ដើមសំរាប់អ្នកទិញច្បាប់ចំលងសំរាប់អ្នកលក់ | J51: សម្គាល់ច្បាប់ដើមសំរាប់អ្នកទិញច្បាប់ចំលងសំរាប់អ្នកលក់
A52: Note ÷ Original invoice for customer , copies invoice for seller | J52: Note ÷ Original invoice for customer , copies invoice for seller

Sheet D002
A1: DEBIT NOTE
A4: CUSTOMER | B4: : | C4: JR APPAREL CO.,LTD | F4: DN NO | G4: JR2609002
A5: ADDRESS | B5: : | C5: KAOH KNOR VILLAGE PREAEK ROKA | F5: DATE | G5: ='366'!$I$13 -> 46275
C6: COMMUNE KANDALSTUENG DISTRICT,
C7: KANDAL STUENG, KANDAL, CAMBODIA
A9: HBL NO | B9: : | C9: ='366'!$B$19 -> COSU6464270110
A10: G.W | B10: : | C10: ='366'!$I$18 -> 16194.3 | F10: POL: | G10: ='366'!$I$19 -> PNH PORT
A11: VOLUME: | B11: : | C11: ='366'!$E$19 -> 1X45'HQ | F11: POD: | G11: ='366'!$I$20 -> USA
A12: CTNR No: | B12: : | C12: ='366'!$E$20 -> CSNU9538620 | F12: PKGS: | G12: ='366'!$B$20 -> 982 CTNS
A13: Shipper | B13: : | C13: ='366'!$C$17 -> JR APPAREL CO., LTD.
A14: Consignee | B14: : | C14: ='366'!$C$18 -> CHAPTERONE SPORTSWEAR
A16: NO | C16: DESCRIPTION | D16: Q'TY | E16: U/M | F16: PRICE | G16: TOTAL | H16: ='366'!S12 -> E 272714
A17: 1 | C17: TRUCKING FEE | D17: 1 | E17: 45H | F17: 260 | G17: =ROUND(F17*D17,2) -> 260
A18: 2 | C18: HANDLING FEE | D18: 1 | E18: 45H | F18: 35 | G18: =ROUND(F18*D18,2) -> 35
A19: 3 | C19: INCREASE TRUCKING FEE(65%) | D19: 1 | E19: TRUCK | F19: 169 | G19: =ROUND(F19*D19,2) -> 169 | H19: =G17*65% -> 169
A20: 4 | C20: DOCUMENT FEE | D20: 1 | E20: SET | F20: 25 | G20: =ROUND(F20*D20,2) -> 25
A21: 5 | C21: SERVICE TAXATION | D21: 1 | E21: SHIP | F21: 20 | G21: =ROUND(F21*D21,2) -> 20
A22: 6 | C22: PETROLL ALLOWANCE FEE | D22: 1 | E22: TIME | F22: 69 | G22: =ROUND(F22*D22,2) -> 69
A23: 7 | C23: FUEL SURCHARGE | D23: 1 | E23: 45H | F23: 40 | G23: =ROUND(F23*D23,2) -> 40
A24: 8 | C24: APPLY CO FOR INV: JRA26053 | D24: 1 | E24: INV | F24: 40 | G24: =ROUND(F24*D24,2) -> 40
A25: 9 | C25: LOLO EMPTY CONTAINER | D25: 1 | E25: 45H | F25: 49.5 | G25: =ROUND(F25*D25,2) -> 49.5
D26: GRAND TOTAL: | F26: USD | G26: =SUM(G17:G25) -> 707.5
A51: Thank you for your supporting | E51: AUTHORIZED SIGNATURE

Sheet 370
A2: ក្រុមហ៊ុន ហ្រ្តេតហ្វ៊ូល សឹលូសិន (ខេមបូឌា) ឯ.ក | J2: ក្រុមហ៊ុន ហ្រ្តេតហ្វ៊ូល សឹលូសិន (ខេមបូឌា) ឯ.ក
A3: GRATEFUL SOLUTIONS (CAMBODIA) CO.,LTD. | J3: GRATEFUL SOLUTIONS (CAMBODIA) CO.,LTD.
C4: លេខអត្តសញ្ញាណកម្ម អតប ( VATTIN ) : K008-902404873 | L4: លេខអត្តសញ្ញាណកម្ម អតប ( VATTIN ) : K008-902404873
A5: អាស័យដ្ឋាន : # 7E0 ផ្លូវបេតុង ក្រុម 7 ភូមិទួលថ្ងាន់ សង្កាត់ទួលសង្កែទី2 ខណ្ឌឬស្សីកែវ រាជធានីភ្នំពេញ | J5: អាស័យដ្ឋាន : # 7E0 ផ្លូវបេតុង ក្រុម 7 ភូមិទួលថ្ងាន់ សង្កាត់ទួលសង្កែទី2 ខណ្ឌឬស្សីកែវ រាជធានីភ្នំពេញ
A6: លេខទូរស័ព្ទ:​098​ 484 ​414 | J6: លេខទូរស័ព្ទ:​098​ 484 ​414
A9: វិក្កយបត្រអាករ | J9: វិក្កយបត្របង់ជំនួស
A10: TAX INVOICE | J10: DISBURSEMENT
A12: ឈ្មោះអតិថិជន /Customer: ជេអ អឹភែរឹល ឯ.ក | F12: លេខវិក័យប័ត្រ: /Invoice No: | I12: GS26-370 | J12: =A12 -> ឈ្មោះអតិថិជន /Customer: ជេអ អឹភែរឹល ឯ.ក | O12: លេខវិក័យប័ត្រ: /DIS-No: | R12: DIS413 | S12: E 275226
A13: JR APPAREL CO.,LTD | E13: ការបរិច្ឆេទវិក្កយបត្រ/Invoice Date: | I13: 46279 | J13: =A13 -> JR APPAREL CO.,LTD | N13: ការបរិច្ឆេទវិក្កយបត្រ/DIS-Date: | R13: =I13 -> 46279
A14: អាស័យដ្ឋាន/Address: KAOH KNOR VILLAGE PREAEK ROKA COMMUNE KANDAL | J14: =A14 -> អាស័យដ្ឋាន/Address: KAOH KNOR VILLAGE PREAEK ROKA COMMUNE KANDAL
A15: STUENG DISTRICT, KANDAL STUENG, KANDAL, CAMBODIA | J15: =A15 -> STUENG DISTRICT, KANDAL STUENG, KANDAL, CAMBODIA
A16: លេខ អ ត ប (VATTIN) : L001-902501613 | J16: =A16 -> លេខ អ ត ប (VATTIN) : L001-902501613
A17: SHIPPER: | C17: JR APPAREL CO., LTD. | J17: =A17 -> SHIPPER: | L17: =C17 -> JR APPAREL CO., LTD.
A18: CONSIGNEE : | C18: CHAPTERONE SPORTSWEAR | G18: GROSS WEIGHT: | I18: 12454 | J18: =A18 -> CONSIGNEE : | L18: =C18 -> CHAPTERONE SPORTSWEAR | P18: =G18 -> GROSS WEIGHT: | R18: =I18 -> 12454
A19: HBL: | B19: COSU6464270310 | D19: VOLUME: | E19: 1X40'HC | H19: POL: | I19: PNH PORT | J19: =A19 -> HBL: | K19: =B19 -> COSU6464270310 | M19: VOLUME: | N19: =E19 -> 1X40'HC | Q19: POL: | R19: =I19 -> PNH PORT
A20: PKGS: | B20: 729 CTNS | D20: CTNR No: | E20: CSNU6351548 | H20: POD: | I20: USA | J20: =A20 -> PKGS: | K20: =B20 -> 729 CTNS | M20: CTNR No: | N20: =E20 -> CSNU6351548 | Q20: POD: | R20: =I20 -> USA
G21: 4052 | P21: =G21 -> 4052
A22: ល.រ | B22: បរិយាយមុខទំនិញ | D22: បរិមាណ | E22: ឯកតា | F22: ថ្លៃឯកតា | G22: សរុប | H22: អាករ10% | I22: ថ្លៃទំនិញ | J22: ល.រ | K22: បរិយាយមុខទំនិញ | M22: បរិមាណ | N22: ឯកតា | O22: ថ្លៃឯកតា | P22: សរុប | Q22: អាករ 0% | R22: ថ្លៃទំនិញ
A23: No | B23: Description | D23: Quatity | E23: Unit | F23: Unit Price | G23: Sub. Total | H23: VAT ( 10%) | I23: Amount | J23: No | K23: Description | M23: Quatity | N23: Unit | O23: Unit Price | P23: Sub. Total | Q23: VAT ( 0%) | R23: Amount
A25: 1 | B25: កំរៃសេវាបំពេញបែបបទនាំចេញ / EXPORT PROCESSING FEE | D25: 1 | E25: 40H | F25: 242 | G25: =ROUND(F25*D25,2) -> 242 | H25: =G25*10% -> 24.2 | I25: =H25+G25 -> 266.2 | J25: 1 | K25: LOLO AT PORT | M25: 1 | N25: 40H | O25: 77 | P25: =O25*M25 -> 77 | Q25: 0 | R25: =Q25+P25 -> 77 | S25: TBA
J26: 2 | K26: CUSTOM PROCESSING FEE | M26: 1 | N26: 40H | O26: 21.25 | P26: =O26*M26 -> 21.25 | Q26: 0 | R26: =Q26+P26 -> 21.25
J27: 3 | K27: HBL FEE | M27: 1 | N27: 40H | O27: 539 | P27: =O27*M27 -> 539 | Q27: 0 | R27: =Q27+P27 -> 539
C29: សរុប SUB TOTAL | E29: KHR | F29: =$I$29*G21 -> 980584 | H29: USD | I29: =SUM(G25:G28) -> 242 | L29: សរុប SUB TOTAL | Q29: USD | R29: =SUM(R25:R28) -> 637.25
C30: អារករលើតម្លៃបន្ថែម (VAT 10%) | E30: KHR | F30: =$I$30*$G$21 -> 98058.4 | H30: USD | I30: =ROUND(SUM(H25:H28),2) -> 24.2 | L30: អារករលើតម្លៃបន្ថែម (VAT 0%) | Q30: USD | R30: 0
C31: សរុបរួម GRAND TOTAL | E31: KHR | F31: =I31*$G$21 -> 1078642.4 | H31: USD | I31: =$I$29+$I$30 -> 266.2 | L31: សរុបរួម GRAND TOTAL | Q31: USD | R31: =SUM(R29:R30) -> 637.25 | S31: =SUM(I31+R31) -> 903.45
A33: Note: Can make payment by cross cheque to: | J33: Note: Can make payment by cross cheque to:
A34: GRATEFUL SOLUTIONS (CAMBODIA) CO.,LTD. | J34: GRATEFUL SOLUTIONS (CAMBODIA) CO.,LTD.
A35: or Deposit Cash/Cheque payment to bank as below: | J35: or Deposit Cash/Cheque payment to bank as below:
A36: KB BRASAC BANK PLC | J36: KB BRASAC BANK PLC
A37: A/NAME: GRATEFUL SOLUTIONS (CAMBODIA) CO.,LTD. | J37: A/NAME: GRATEFUL SOLUTIONS (CAMBODIA) CO.,LTD.
A38: AC/NO: 033 754 230 001 | J38: AC/NO: 033 754 230 001
A48: ________________________ | G48: _______________________________ | J48: ________________________ | P48: _______________________________
A49: ហត្ថលេខា និង ឈ្មោះអ្នកទិញ | G49: ​​​​​​​​​​​ ហត្ថលេខា និង ឈ្មោះអ្នកលក់ | J49: ហត្ថលេខា និង ឈ្មោះអ្នកទិញ | P49: ​​​​​​​​​​​ ហត្ថលេខា និង ឈ្មោះអ្នកលក់
A50: សម្គាល់ច្បាប់ដើមសំរាប់អ្នកទិញច្បាប់ចំលងសំរាប់អ្នកលក់ | J50: សម្គាល់ច្បាប់ដើមសំរាប់អ្នកទិញច្បាប់ចំលងសំរាប់អ្នកលក់
A51: Note ÷ Original invoice for customer , copies invoice for seller | J51: Note ÷ Original invoice for customer , copies invoice for seller

Sheet D003
A1: DEBIT NOTE
A4: CUSTOMER | B4: : | C4: JR APPAREL CO.,LTD | F4: DN NO | G4: JR2609003
A5: ADDRESS | B5: : | C5: KAOH KNOR VILLAGE PREAEK ROKA | F5: DATE | G5: ='370'!$I$13 -> 46279
C6: COMMUNE KANDALSTUENG DISTRICT,
C7: KANDAL STUENG, KANDAL, CAMBODIA
A9: HBL NO | B9: : | C9: ='370'!$B$19 -> COSU6464270310
A10: G.W | B10: : | C10: ='370'!$I$18 -> 12454 | F10: POL: | G10: ='370'!$I$19 -> PNH PORT
A11: VOLUME: | B11: : | C11: ='370'!$E$19 -> 1X40'HC | F11: POD: | G11: ='370'!$I$20 -> USA
A12: CTNR No: | B12: : | C12: ='370'!$E$20 -> CSNU6351548 | F12: PKGS: | G12: ='370'!$B$20 -> 729 CTNS
A13: Shipper | B13: : | C13: ='370'!$C$17 -> JR APPAREL CO., LTD.
A14: Consignee | B14: : | C14: ='370'!$C$18 -> CHAPTERONE SPORTSWEAR
A16: NO | C16: DESCRIPTION | D16: Q'TY | E16: U/M | F16: PRICE | G16: TOTAL | H16: ='370'!S12 -> E 275226
A17: 1 | C17: TRUCKING FEE | D17: 1 | E17: 45H | F17: 260 | G17: =ROUND(F17*D17,2) -> 260
A18: 2 | C18: HANDLING FEE | D18: 1 | E18: 45H | F18: 35 | G18: =ROUND(F18*D18,2) -> 35
A19: 3 | C19: INCREASE TRUCKING FEE(65%) | D19: 1 | E19: TRUCK | F19: 169 | G19: =ROUND(F19*D19,2) -> 169 | H19: =G17*65% -> 169
A20: 4 | C20: DOCUMENT FEE | D20: 1 | E20: SET | F20: 25 | G20: =ROUND(F20*D20,2) -> 25
A21: 5 | C21: SERVICE TAXATION | D21: 1 | E21: SHIP | F21: 20 | G21: =ROUND(F21*D21,2) -> 20
A22: 6 | C22: PETROLL ALLOWANCE FEE | D22: 1 | E22: TIME | F22: 69 | G22: =ROUND(F22*D22,2) -> 69
A23: 7 | C23: FUEL SURCHARGE | D23: 1 | E23: 45H | F23: 40 | G23: =ROUND(F23*D23,2) -> 40
A24: 8 | C24: APPLY CO FOR INV: JRA26054 | D24: 1 | E24: INV | F24: 40 | G24: =ROUND(F24*D24,2) -> 40
A25: 9 | C25: LOLO EMPTY CONTAINER | D25: 1 | E25: 45H | F25: 49.5 | G25: =ROUND(F25*D25,2) -> 49.5
D26: GRAND TOTAL: | F26: USD | G26: =SUM(G17:G25) -> 707.5
A51: Thank you for your supporting | E51: AUTHORIZED SIGNATURE

Sheet 375
A2: ក្រុមហ៊ុន ហ្រ្តេតហ្វ៊ូល សឹលូសិន (ខេមបូឌា) ឯ.ក | J2: ក្រុមហ៊ុន ហ្រ្តេតហ្វ៊ូល សឹលូសិន (ខេមបូឌា) ឯ.ក
A3: GRATEFUL SOLUTIONS (CAMBODIA) CO.,LTD. | J3: GRATEFUL SOLUTIONS (CAMBODIA) CO.,LTD.
C4: លេខអត្តសញ្ញាណកម្ម អតប ( VATTIN ) : K008-902404873 | L4: លេខអត្តសញ្ញាណកម្ម អតប ( VATTIN ) : K008-902404873
A5: អាស័យដ្ឋាន : # 7E0 ផ្លូវបេតុង ក្រុម 7 ភូមិទួលថ្ងាន់ សង្កាត់ទួលសង្កែទី2 ខណ្ឌឬស្សីកែវ រាជធានីភ្នំពេញ | J5: អាស័យដ្ឋាន : # 7E0 ផ្លូវបេតុង ក្រុម 7 ភូមិទួលថ្ងាន់ សង្កាត់ទួលសង្កែទី2 ខណ្ឌឬស្សីកែវ រាជធានីភ្នំពេញ
A6: លេខទូរស័ព្ទ:​098​ 484 ​414 | J6: លេខទូរស័ព្ទ:​098​ 484 ​414
A9: វិក្កយបត្រអាករ | J9: វិក្កយបត្របង់ជំនួស
A10: TAX INVOICE | J10: DISBURSEMENT
A12: ឈ្មោះអតិថិជន /Customer: ជេអ អឹភែរឹល ឯ.ក | F12: លេខវិក័យប័ត្រ: /Invoice No: | I12: GS26-375 | J12: =A12 -> ឈ្មោះអតិថិជន /Customer: ជេអ អឹភែរឹល ឯ.ក | O12: លេខវិក័យប័ត្រ: /DIS-No: | R12: DIS418 | S12: E 284067
A13: JR APPAREL CO.,LTD | E13: ការបរិច្ឆេទវិក្កយបត្រ/Invoice Date: | I13: 46286 | J13: =A13 -> JR APPAREL CO.,LTD | N13: ការបរិច្ឆេទវិក្កយបត្រ/DIS-Date: | R13: =I13 -> 46286
A14: អាស័យដ្ឋាន/Address: KAOH KNOR VILLAGE PREAEK ROKA COMMUNE KANDAL | J14: =A14 -> អាស័យដ្ឋាន/Address: KAOH KNOR VILLAGE PREAEK ROKA COMMUNE KANDAL
A15: STUENG DISTRICT, KANDAL STUENG, KANDAL, CAMBODIA | J15: =A15 -> STUENG DISTRICT, KANDAL STUENG, KANDAL, CAMBODIA
A16: លេខ អ ត ប (VATTIN) : L001-902501613 | J16: =A16 -> លេខ អ ត ប (VATTIN) : L001-902501613
A17: SHIPPER: | C17: JR APPAREL CO., LTD. | J17: =A17 -> SHIPPER: | L17: =C17 -> JR APPAREL CO., LTD.
A18: CONSIGNEE : | C18: CHAPTERONE SPORTSWEAR | G18: GROSS WEIGHT: | I18: 14952.5 | J18: =A18 -> CONSIGNEE : | L18: =C18 -> CHAPTERONE SPORTSWEAR | P18: =G18 -> GROSS WEIGHT: | R18: =I18 -> 14952.5
A19: HBL: | B19: COSU6464808450 | D19: VOLUME: | E19: 1X45'HQ | H19: POL: | I19: PNH PORT | J19: =A19 -> HBL: | K19: =B19 -> COSU6464808450 | M19: VOLUME: | N19: =E19 -> 1X45'HQ | Q19: POL: | R19: =I19 -> PNH PORT
A20: PKGS: | B20: 977 CTNS | D20: CTNR No: | E20: TEMU8045497 | H20: POD: | I20: USA | J20: =A20 -> PKGS: | K20: =B20 -> 977 CTNS | M20: CTNR No: | N20: =E20 -> TEMU8045497 | Q20: POD: | R20: =I20 -> USA
G21: 4054 | P21: =G21 -> 4054
A22: ល.រ | B22: បរិយាយមុខទំនិញ | D22: បរិមាណ | E22: ឯកតា | F22: ថ្លៃឯកតា | G22: សរុប | H22: អាករ10% | I22: ថ្លៃទំនិញ | J22: ល.រ | K22: បរិយាយមុខទំនិញ | M22: បរិមាណ | N22: ឯកតា | O22: ថ្លៃឯកតា | P22: សរុប | Q22: អាករ 0% | R22: ថ្លៃទំនិញ
A23: No | B23: Description | D23: Quatity | E23: Unit | F23: Unit Price | G23: Sub. Total | H23: VAT ( 10%) | I23: Amount | J23: No | K23: Description | M23: Quatity | N23: Unit | O23: Unit Price | P23: Sub. Total | Q23: VAT ( 0%) | R23: Amount
A25: 1 | B25: កំរៃសេវាបំពេញបែបបទនាំចេញ / EXPORT PROCESSING FEE | D25: 1 | E25: 45H | F25: 242 | G25: =ROUND(F25*D25,2) -> 242 | H25: =G25*10% -> 24.2 | I25: =H25+G25 -> 266.2 | J25: 1 | K25: LOLO AT PORT | M25: 1 | N25: 45H | O25: 77 | P25: =O25*M25 -> 77 | Q25: 0 | R25: =Q25+P25 -> 77
J26: 2 | K26: CUSTOM PROCESSING FEE | M26: 1 | N26: 45H | O26: 21.25 | P26: =O26*M26 -> 21.25 | Q26: 0 | R26: =Q26+P26 -> 21.25
J27: 3 | K27: STORAGE FEE | M27: 1 | N27: 45H | O27: 13.2 | P27: =O27*M27 -> 13.2 | Q27: 0 | R27: =Q27+P27 -> 13.2
J28: 4 | K28: HBL FEE | M28: 1 | N28: 45H | O28: 539 | P28: =O28*M28 -> 539 | Q28: 0 | R28: =Q28+P28 -> 539
C30: សរុប SUB TOTAL | E30: KHR | F30: =$I$30*G21 -> 981068 | H30: USD | I30: =SUM(G25:G29) -> 242 | L30: សរុប SUB TOTAL | Q30: USD | R30: =SUM(R24:R29) -> 650.45
C31: អារករលើតម្លៃបន្ថែម (VAT 10%) | E31: KHR | F31: =$I$31*$G$21 -> 98106.8 | H31: USD | I31: =ROUND(SUM(H25:H29),2) -> 24.2 | L31: អារករលើតម្លៃបន្ថែម (VAT 0%) | Q31: USD | R31: 0
C32: សរុបរួម GRAND TOTAL | E32: KHR | F32: =I32*$G$21 -> 1079174.8 | H32: USD | I32: =$I$30+$I$31 -> 266.2 | L32: សរុបរួម GRAND TOTAL | Q32: USD | R32: =SUM(R30:R31) -> 650.45 | S32: =SUM(I32,R32) -> 916.65
A34: Note: Can make payment by cross cheque to: | J34: Note: Can make payment by cross cheque to:
A35: GRATEFUL SOLUTIONS (CAMBODIA) CO.,LTD. | J35: GRATEFUL SOLUTIONS (CAMBODIA) CO.,LTD.
A36: or Deposit Cash/Cheque payment to bank as below: | J36: or Deposit Cash/Cheque payment to bank as below:
A37: KB BRASAC BANK PLC | J37: KB BRASAC BANK PLC
A38: A/NAME: GRATEFUL SOLUTIONS (CAMBODIA) CO.,LTD. | J38: A/NAME: GRATEFUL SOLUTIONS (CAMBODIA) CO.,LTD.
A39: AC/NO: 033 754 230 001 | J39: AC/NO: 033 754 230 001
A48: ________________________ | G48: _______________________________ | J48: ________________________ | P48: _______________________________
A49: ហត្ថលេខា និង ឈ្មោះអ្នកទិញ | G49: ​​​​​​​​​​​ ហត្ថលេខា និង ឈ្មោះអ្នកលក់ | J49: ហត្ថលេខា និង ឈ្មោះអ្នកទិញ | P49: ​​​​​​​​​​​ ហត្ថលេខា និង ឈ្មោះអ្នកលក់
A50: សម្គាល់ច្បាប់ដើមសំរាប់អ្នកទិញច្បាប់ចំលងសំរាប់អ្នកលក់ | J50: សម្គាល់ច្បាប់ដើមសំរាប់អ្នកទិញច្បាប់ចំលងសំរាប់អ្នកលក់
A51: Note ÷ Original invoice for customer , copies invoice for seller | J51: Note ÷ Original invoice for customer , copies invoice for seller

Sheet D004
A1: DEBIT NOTE
A4: CUSTOMER | B4: : | C4: JR APPAREL CO.,LTD | F4: DN NO | G4: JR2609004
A5: ADDRESS | B5: : | C5: KAOH KNOR VILLAGE PREAEK ROKA | F5: DATE | G5: ='375'!I13 -> 46286
C6: COMMUNE KANDALSTUENG DISTRICT,
C7: KANDAL STUENG, KANDAL, CAMBODIA
A9: HBL NO | B9: : | C9: ='375'!B19 -> COSU6464808450
A10: G.W | B10: : | C10: ='375'!I18 -> 14952.5 | F10: POL: | G10: ='375'!I19 -> PNH PORT
A11: VOLUME: | B11: : | C11: ='375'!E19 -> 1X45'HQ | F11: POD: | G11: ='375'!I20 -> USA
A12: CTNR No: | B12: : | C12: ='375'!E20 -> TEMU8045497 | F12: PKGS: | G12: ='375'!B20 -> 977 CTNS
A13: Shipper | B13: : | C13: ='375'!C17 -> JR APPAREL CO., LTD.
A14: Consignee | B14: : | C14: ='375'!C18 -> CHAPTERONE SPORTSWEAR
A16: NO | C16: DESCRIPTION | D16: Q'TY | E16: U/M | F16: PRICE | G16: TOTAL | H16: ='375'!S12 -> E 284067
A17: 1 | C17: TRUCKING FEE | D17: 1 | E17: 45H | F17: 260 | G17: =ROUND(F17*D17,2) -> 260
A18: 2 | C18: HANDLING FEE | D18: 1 | E18: 45H | F18: 35 | G18: =ROUND(F18*D18,2) -> 35
A19: 3 | C19: INCREASE TRUCKING FEE(65%) | D19: 1 | E19: TRUCK | F19: 169 | G19: =ROUND(F19*D19,2) -> 169 | H19: =G17*65% -> 169
A20: 4 | C20: INSPECTION AT DRYPORT | D20: 1 | E20: TIME | F20: 57.5 | G20: =ROUND(F20*D20,2) -> 57.5
A21: 5 | C21: DOCUMENT FEE | D21: 1 | E21: SET | F21: 25 | G21: =ROUND(F21*D21,2) -> 25
A22: 6 | C22: SERVICE TAXATION | D22: 1 | E22: SHIP | F22: 20 | G22: =ROUND(F22*D22,2) -> 20
A23: 7 | C23: FUEL SURCHARGE | D23: 1 | E23: 45H | F23: 40 | G23: =ROUND(F23*D23,2) -> 40
A24: 8 | C24: OT INSPECTION | D24: 1 | E24: 45H | F24: 80 | G24: =ROUND(F24*D24,2) -> 80
A25: 9 | C25: OT AT PORT | D25: 1 | E25: 45H | F25: 60 | G25: =ROUND(F25*D25,2) -> 60
A26: 10 | C26: LOLO EMPTY CONTAINER | D26: 1 | E26: 45H | F26: 49.5 | G26: =ROUND(F26*D26,2) -> 49.5
A27: 11 | C27: GATE FEE AT DRY PORT | D27: 1 | E27: 45H | F27: 15 | G27: =ROUND(F27*D27,2) -> 15
A28: 12 | C28: APPLY CO FOR INV: JRA26055 | D28: 1 | E28: INV | F28: 40 | G28: =ROUND(F28*D28,2) -> 40
D29: GRAND TOTAL: | F29: USD | G29: =SUM(G17:G28) -> 851
A51: Thank you for your supporting | E51: AUTHORIZED SIGNATURE

Sheet 377
A2: ក្រុមហ៊ុន ហ្រ្តេតហ្វ៊ូល សឹលូសិន (ខេមបូឌា) ឯ.ក | J2: ក្រុមហ៊ុន ហ្រ្តេតហ្វ៊ូល សឹលូសិន (ខេមបូឌា) ឯ.ក
A3: GRATEFUL SOLUTIONS (CAMBODIA) CO.,LTD. | J3: GRATEFUL SOLUTIONS (CAMBODIA) CO.,LTD.
C4: លេខអត្តសញ្ញាណកម្ម អតប ( VATTIN ) : K008-902404873 | L4: លេខអត្តសញ្ញាណកម្ម អតប ( VATTIN ) : K008-902404873
A5: អាស័យដ្ឋាន : # 7E0 ផ្លូវបេតុង ក្រុម 7 ភូមិទួលថ្ងាន់ សង្កាត់ទួលសង្កែទី2 ខណ្ឌឬស្សីកែវ រាជធានីភ្នំពេញ | J5: អាស័យដ្ឋាន : # 7E0 ផ្លូវបេតុង ក្រុម 7 ភូមិទួលថ្ងាន់ សង្កាត់ទួលសង្កែទី2 ខណ្ឌឬស្សីកែវ រាជធានីភ្នំពេញ
A6: លេខទូរស័ព្ទ:​098​ 484 ​414 | J6: លេខទូរស័ព្ទ:​098​ 484 ​414
A9: វិក្កយបត្រអាករ | J9: វិក្កយបត្របង់ជំនួស
A10: TAX INVOICE | J10: DISBURSEMENT
A12: ឈ្មោះអតិថិជន /Customer: ជេអ អឹភែរឹល ឯ.ក | F12: លេខវិក័យប័ត្រ: /Invoice No: | I12: GS26-377 | J12: =A12 -> ឈ្មោះអតិថិជន /Customer: ជេអ អឹភែរឹល ឯ.ក | O12: លេខវិក័យប័ត្រ: /DIS-No: | R12: DIS420 | S12: I 136252
A13: JR APPAREL CO.,LTD | E13: ការបរិច្ឆេទវិក្កយបត្រ/Invoice Date: | I13: 46286 | J13: =A13 -> JR APPAREL CO.,LTD | N13: ការបរិច្ឆេទវិក្កយបត្រ/DIS-Date: | R13: =I13 -> 46286
A14: អាស័យដ្ឋាន/Address: KAOH KNOR VILLAGE PREAEK ROKA COMMUNE KANDAL | J14: =A14 -> អាស័យដ្ឋាន/Address: KAOH KNOR VILLAGE PREAEK ROKA COMMUNE KANDAL
A15: STUENG DISTRICT, KANDAL STUENG, KANDAL, CAMBODIA | J15: =A15 -> STUENG DISTRICT, KANDAL STUENG, KANDAL, CAMBODIA
A16: លេខ អ ត ប (VATTIN) : L001-902501613 | J16: =A16 -> លេខ អ ត ប (VATTIN) : L001-902501613
A17: SHIPPER: | C17: SHANGHAI YONGYUE IMP. &EXP. TRADING CO., LTD. | J17: =A17 -> SHIPPER: | L17: =C17 -> SHANGHAI YONGYUE IMP. &EXP. TRADING CO., LTD.
A18: CONSIGNEE : | C18: JR APPAREL CO., LTD. | G18: GROSS WEIGHT: | I18: 24300 | J18: =A18 -> CONSIGNEE : | L18: =C18 -> JR APPAREL CO., LTD. | P18: =G18 -> GROSS WEIGHT: | R18: =I18 -> 24300
A19: HBL: | B19: SHSIN6090083 | D19: VOLUME: | E19: 1X40'HQ | H19: POL: | I19: CHINA | J19: =A19 -> HBL: | K19: =B19 -> SHSIN6090083 | M19: VOLUME: | N19: =E19 -> 1X40'HQ | Q19: POL: | R19: =I19 -> CHINA
A20: PKGS: | B20: 797 ROLLS | D20: CTNR No: | E20: OOCU7012318 | H20: POD: | I20: SHV PORT | J20: =A20 -> PKGS: | K20: =B20 -> 797 ROLLS | M20: CTNR No: | N20: =E20 -> OOCU7012318 | Q20: POD: | R20: =I20 -> SHV PORT
G21: 4054 | P21: =G21 -> 4054
A22: ល.រ | B22: បរិយាយមុខទំនិញ | D22: បរិមាណ | E22: ឯកតា | F22: ថ្លៃឯកតា | G22: សរុប | H22: អាករ10% | I22: ថ្លៃទំនិញ | J22: ល.រ | K22: បរិយាយមុខទំនិញ | M22: បរិមាណ | N22: ឯកតា | O22: ថ្លៃឯកតា | P22: សរុប | Q22: អាករ 0% | R22: ថ្លៃទំនិញ
A23: No | B23: Description | D23: Quatity | E23: Unit | F23: Unit Price | G23: Sub. Total | H23: VAT ( 10%) | I23: Amount | J23: No | K23: Description | M23: Quatity | N23: Unit | O23: Unit Price | P23: Sub. Total | Q23: VAT ( 0%) | R23: Amount
A25: 1 | B25: កំរៃសេវាបំពេញបែបបទនាំចូល / IMPORT PROCESSING FEE | D25: 1 | E25: 40H | F25: 200 | G25: =ROUND(F25*D25,2) -> 200 | H25: =G25*10% -> 20 | I25: =H25+G25 -> 220 | J25: 1 | K25: LOLO AT PORT | M25: 1 | N25: 40H | O25: 95.7 | P25: =O25*M25 -> 95.7 | Q25: 0 | R25: =Q25+P25 -> 95.7
J26: 2 | K26: CUSTOM PROCESSING FEE | M26: 1 | N26: 40H | O26: 18.75 | P26: =O26*M26 -> 18.75 | Q26: 0 | R26: =Q26+P26 -> 18.75
J27: 3 | K27: THC FEE | M27: 1 | N27: 40H | O27: 691.5 | P27: =O27*M27 -> 691.5 | Q27: 0 | R27: =Q27+P27 -> 691.5
C29: សរុប SUB TOTAL | E29: KHR | F29: =$I$29*G21 -> 810800 | H29: USD | I29: =SUM(G25:G28) -> 200 | L29: សរុប SUB TOTAL | Q29: USD | R29: =SUM(R25:R28) -> 805.95
C30: អារករលើតម្លៃបន្ថែម (VAT 10%) | E30: KHR | F30: =$I$30*$G$21 -> 81080 | H30: USD | I30: =ROUND(SUM(H25:H28),2) -> 20 | L30: អារករលើតម្លៃបន្ថែម (VAT 0%) | Q30: USD | R30: 0
C31: សរុបរួម GRAND TOTAL | E31: KHR | F31: =I31*$G$21 -> 891880 | H31: USD | I31: =$I$29+$I$30 -> 220 | L31: សរុបរួម GRAND TOTAL | Q31: USD | R31: =SUM(R29:R30) -> 805.95 | S31: =SUM(I31,R31) -> 1025.95
A33: Note: Can make payment by cross cheque to: | J33: Note: Can make payment by cross cheque to:
A34: GRATEFUL SOLUTIONS (CAMBODIA) CO.,LTD. | J34: GRATEFUL SOLUTIONS (CAMBODIA) CO.,LTD.
A35: or Deposit Cash/Cheque payment to bank as below: | J35: or Deposit Cash/Cheque payment to bank as below:
A36: KB BRASAC BANK PLC | J36: KB BRASAC BANK PLC
A37: A/NAME: GRATEFUL SOLUTIONS (CAMBODIA) CO.,LTD. | J37: A/NAME: GRATEFUL SOLUTIONS (CAMBODIA) CO.,LTD.
A38: AC/NO: 033 754 230 001 | J38: AC/NO: 033 754 230 001
A50: ________________________ | G50: _______________________________ | J50: ________________________ | P50: _______________________________
A51: ហត្ថលេខា និង ឈ្មោះអ្នកទិញ | G51: ​​​​​​​​​​​ ហត្ថលេខា និង ឈ្មោះអ្នកលក់ | J51: ហត្ថលេខា និង ឈ្មោះអ្នកទិញ | P51: ​​​​​​​​​​​ ហត្ថលេខា និង ឈ្មោះអ្នកលក់
A52: សម្គាល់ច្បាប់ដើមសំរាប់អ្នកទិញច្បាប់ចំលងសំរាប់អ្នកលក់ | J52: សម្គាល់ច្បាប់ដើមសំរាប់អ្នកទិញច្បាប់ចំលងសំរាប់អ្នកលក់
A53: Note ÷ Original invoice for customer , copies invoice for seller | J53: Note ÷ Original invoice for customer , copies invoice for seller

Sheet D005
A1: DEBIT NOTE
A4: CUSTOMER | B4: : | C4: JR APPAREL CO.,LTD | F4: DN NO | G4: JR2609005
A5: ADDRESS | B5: : | C5: KAOH KNOR VILLAGE PREAEK ROKA | F5: DATE | G5: ='377'!I13 -> 46286
C6: COMMUNE KANDALSTUENG DISTRICT,
C7: KANDAL STUENG, KANDAL, CAMBODIA
A9: HBL NO | B9: : | C9: ='377'!B19 -> SHSIN6090083
A10: G.W | B10: : | C10: ='377'!I18 -> 24300 | F10: POL: | G10: ='377'!I19 -> CHINA
A11: VOLUME: | B11: : | C11: ='377'!E19 -> 1X40'HQ | F11: POD: | G11: ='377'!I20 -> SHV PORT
A12: CTNR No: | B12: : | C12: ='377'!E20 -> OOCU7012318 | F12: PKGS: | G12: ='377'!B20 -> 797 ROLLS
A13: Shipper | B13: : | C13: ='377'!C17 -> SHANGHAI YONGYUE IMP. &EXP. TRADING CO., LTD.
A14: Consignee | B14: : | C14: ='377'!C18 -> JR APPAREL CO., LTD.
A16: NO | C16: DESCRIPTION | D16: Q'TY | E16: U/M | F16: PRICE | G16: TOTAL | H16: ='377'!S12 -> I 136252
A17: 1 | C17: TRUCKING FEE | D17: 1 | E17: 40H | F17: 360 | G17: =ROUND(F17*D17,2) -> 360
A18: 2 | C18: HANDLING FEE | D18: 1 | E18: 40H | F18: 35 | G18: =ROUND(F18*D18,2) -> 35
A19: 3 | C19: INCREASE TRUCKING FEE(65%) | D19: 1 | E19: TRUCK | F19: 234 | G19: =ROUND(F19*D19,2) -> 234 | H19: =F17*65% -> 234
A20: 4 | C20: MISSING INSURANCE | D20: 1 | E20: SET | F20: 20 | G20: =ROUND(F20*D20,2) -> 20
A21: 5 | C21: DOCUMENT FEE | D21: 1 | E21: SET | F21: 25 | G21: =ROUND(F21*D21,2) -> 25
A22: 6 | C22: SERVICE TAXATION | D22: 1 | E22: SHIP | F22: 20 | G22: =ROUND(F22*D22,2) -> 20
A23: 7 | C23: PERMIT FEE | D23: 1 | E23: SET | F23: 45 | G23: =ROUND(F23*D23,2) -> 45
A24: 8 | C24: FUEL SURCHARGE | D24: 1 | E24: 40H | F24: 50 | G24: =ROUND(F24*D24,2) -> 50
A25: 9 | C25: OVER WEIGHT | D25: 3.3 | E25: TON | F25: 50 | G25: =ROUND(F25*D25,2) -> 165
A26: 10 | C26: TRUCKING TO SECOND PLACE | D26: 1 | E26: 40H | F26: 60 | G26: =ROUND(F26*D26,2) -> 60
A27: 11 | C27: LOLO EMPTY DROP DOWN | D27: 1 | E27: 40H | F27: 24.75 | G27: =ROUND(F27*D27,2) -> 24.75
D28: GRAND TOTAL: | F28: USD | G28: =SUM(G17:G27) -> 1038.75
A51: Thank you for your supporting | E51: AUTHORIZED SIGNATURE

Sheet 379
A2: ក្រុមហ៊ុន ហ្រ្តេតហ្វ៊ូល សឹលូសិន (ខេមបូឌា) ឯ.ក | J2: ក្រុមហ៊ុន ហ្រ្តេតហ្វ៊ូល សឹលូសិន (ខេមបូឌា) ឯ.ក
A3: GRATEFUL SOLUTIONS (CAMBODIA) CO.,LTD. | J3: GRATEFUL SOLUTIONS (CAMBODIA) CO.,LTD.
C4: លេខអត្តសញ្ញាណកម្ម អតប ( VATTIN ) : K008-902404873 | L4: លេខអត្តសញ្ញាណកម្ម អតប ( VATTIN ) : K008-902404873
A5: អាស័យដ្ឋាន : # 7E0 ផ្លូវបេតុង ក្រុម 7 ភូមិទួលថ្ងាន់ សង្កាត់ទួលសង្កែទី2 ខណ្ឌឬស្សីកែវ រាជធានីភ្នំពេញ | J5: អាស័យដ្ឋាន : # 7E0 ផ្លូវបេតុង ក្រុម 7 ភូមិទួលថ្ងាន់ សង្កាត់ទួលសង្កែទី2 ខណ្ឌឬស្សីកែវ រាជធានីភ្នំពេញ
A6: លេខទូរស័ព្ទ:​098​ 484 ​414 | J6: លេខទូរស័ព្ទ:​098​ 484 ​414
A9: វិក្កយបត្រអាករ | J9: វិក្កយបត្របង់ជំនួស
A10: TAX INVOICE | J10: DISBURSEMENT
A12: ឈ្មោះអតិថិជន /Customer: ជេអ អឹភែរឹល ឯ.ក | F12: លេខវិក័យប័ត្រ: /Invoice No: | I12: GS26-379 | J12: =A12 -> ឈ្មោះអតិថិជន /Customer: ជេអ អឹភែរឹល ឯ.ក | O12: លេខវិក័យប័ត្រ: /DIS-No: | R12: DIS422 | S12: I 136243
A13: JR APPAREL CO.,LTD | E13: ការបរិច្ឆេទវិក្កយបត្រ/Invoice Date: | I13: 46286 | J13: =A13 -> JR APPAREL CO.,LTD | N13: ការបរិច្ឆេទវិក្កយបត្រ/DIS-Date: | R13: =I13 -> 46286
A14: អាស័យដ្ឋាន/Address: KAOH KNOR VILLAGE PREAEK ROKA COMMUNE KANDAL | J14: =A14 -> អាស័យដ្ឋាន/Address: KAOH KNOR VILLAGE PREAEK ROKA COMMUNE KANDAL
A15: STUENG DISTRICT, KANDAL STUENG, KANDAL, CAMBODIA | J15: =A15 -> STUENG DISTRICT, KANDAL STUENG, KANDAL, CAMBODIA
A16: លេខ អ ត ប (VATTIN) : L001-902501613 | J16: =A16 -> លេខ អ ត ប (VATTIN) : L001-902501613
A17: SHIPPER: | C17: SHANGHAI YONGYUE IMP. &EXP. TRADING CO., LTD. | J17: =A17 -> SHIPPER: | L17: =C17 -> SHANGHAI YONGYUE IMP. &EXP. TRADING CO., LTD.
A18: CONSIGNEE : | C18: JR APPAREL CO., LTD. | G18: GROSS WEIGHT: | I18: 24996.9 | J18: =A18 -> CONSIGNEE : | L18: =C18 -> JR APPAREL CO., LTD. | P18: =G18 -> GROSS WEIGHT: | R18: =I18 -> 24996.9
A19: HBL: | B19: SHSIN6090084 | D19: VOLUME: | E19: 1X40'HQ | H19: POL: | I19: CHINA | J19: =A19 -> HBL: | K19: =B19 -> SHSIN6090084 | M19: VOLUME: | N19: =E19 -> 1X40'HQ | Q19: POL: | R19: =I19 -> CHINA
A20: PKGS: | B20: 688 ROLLS | D20: CTNR No: | E20: CSNU6862609 | H20: POD: | I20: SHV PORT | J20: =A20 -> PKGS: | K20: =B20 -> 688 ROLLS | M20: CTNR No: | N20: =E20 -> CSNU6862609 | Q20: POD: | R20: =I20 -> SHV PORT
G21: 4054 | P21: =G21 -> 4054
A22: ល.រ | B22: បរិយាយមុខទំនិញ | D22: បរិមាណ | E22: ឯកតា | F22: ថ្លៃឯកតា | G22: សរុប | H22: អាករ10% | I22: ថ្លៃទំនិញ | J22: ល.រ | K22: បរិយាយមុខទំនិញ | M22: បរិមាណ | N22: ឯកតា | O22: ថ្លៃឯកតា | P22: សរុប | Q22: អាករ 0% | R22: ថ្លៃទំនិញ
A23: No | B23: Description | D23: Quatity | E23: Unit | F23: Unit Price | G23: Sub. Total | H23: VAT ( 10%) | I23: Amount | J23: No | K23: Description | M23: Quatity | N23: Unit | O23: Unit Price | P23: Sub. Total | Q23: VAT ( 0%) | R23: Amount
A25: 1 | B25: កំរៃសេវាបំពេញបែបបទនាំចូល / IMPORT PROCESSING FEE | D25: 1 | E25: 40H | F25: 200 | G25: =ROUND(F25*D25,2) -> 200 | H25: =G25*10% -> 20 | I25: =H25+G25 -> 220 | J25: 1 | K25: LOLO AT PORT | M25: 1 | N25: 40H | O25: 95.7 | P25: =O25*M25 -> 95.7 | Q25: 0 | R25: =Q25+P25 -> 95.7
J26: 2 | K26: CUSTOM PROCESSING FEE | M26: 1 | N26: 40H | O26: 18.75 | P26: =O26*M26 -> 18.75 | Q26: 0 | R26: =Q26+P26 -> 18.75
J27: 3 | K27: THC FEE | M27: 1 | N27: 40H | O27: 691.5 | P27: =O27*M27 -> 691.5 | Q27: 0 | R27: =Q27+P27 -> 691.5
C29: សរុប SUB TOTAL | E29: KHR | F29: =$I$29*G21 -> 810800 | H29: USD | I29: =SUM(G25:G28) -> 200 | L29: សរុប SUB TOTAL | Q29: USD | R29: =SUM(R25:R28) -> 805.95
C30: អារករលើតម្លៃបន្ថែម (VAT 10%) | E30: KHR | F30: =$I$30*$G$21 -> 81080 | H30: USD | I30: =ROUND(SUM(H25:H28),2) -> 20 | L30: អារករលើតម្លៃបន្ថែម (VAT 0%) | Q30: USD | R30: 0
C31: សរុបរួម GRAND TOTAL | E31: KHR | F31: =I31*$G$21 -> 891880 | H31: USD | I31: =$I$29+$I$30 -> 220 | L31: សរុបរួម GRAND TOTAL | Q31: USD | R31: =SUM(R29:R30) -> 805.95 | S31: =SUM(I31,R31) -> 1025.95
A33: Note: Can make payment by cross cheque to: | J33: Note: Can make payment by cross cheque to:
A34: GRATEFUL SOLUTIONS (CAMBODIA) CO.,LTD. | J34: GRATEFUL SOLUTIONS (CAMBODIA) CO.,LTD.
A35: or Deposit Cash/Cheque payment to bank as below: | J35: or Deposit Cash/Cheque payment to bank as below:
A36: KB BRASAC BANK PLC | J36: KB BRASAC BANK PLC
A37: A/NAME: GRATEFUL SOLUTIONS (CAMBODIA) CO.,LTD. | J37: A/NAME: GRATEFUL SOLUTIONS (CAMBODIA) CO.,LTD.
A38: AC/NO: 033 754 230 001 | J38: AC/NO: 033 754 230 001
A49: ________________________ | G49: _______________________________ | J49: ________________________ | P49: _______________________________
A50: ហត្ថលេខា និង ឈ្មោះអ្នកទិញ | G50: ​​​​​​​​​​​ ហត្ថលេខា និង ឈ្មោះអ្នកលក់ | J50: ហត្ថលេខា និង ឈ្មោះអ្នកទិញ | P50: ​​​​​​​​​​​ ហត្ថលេខា និង ឈ្មោះអ្នកលក់
A51: សម្គាល់ច្បាប់ដើមសំរាប់អ្នកទិញច្បាប់ចំលងសំរាប់អ្នកលក់ | J51: សម្គាល់ច្បាប់ដើមសំរាប់អ្នកទិញច្បាប់ចំលងសំរាប់អ្នកលក់
A52: Note ÷ Original invoice for customer , copies invoice for seller | J52: Note ÷ Original invoice for customer , copies invoice for seller

Sheet D006
A1: DEBIT NOTE
A4: CUSTOMER | B4: : | C4: JR APPAREL CO.,LTD | F4: DN NO | G4: JR2609006
A5: ADDRESS | B5: : | C5: KAOH KNOR VILLAGE PREAEK ROKA | F5: DATE | G5: ='379'!I13 -> 46286
C6: COMMUNE KANDALSTUENG DISTRICT,
C7: KANDAL STUENG, KANDAL, CAMBODIA
A9: HBL NO | B9: : | C9: ='379'!B19 -> SHSIN6090084
A10: G.W | B10: : | C10: ='379'!I18 -> 24996.9 | F10: POL: | G10: ='379'!I19 -> CHINA
A11: VOLUME: | B11: : | C11: ='379'!E19 -> 1X40'HQ | F11: POD: | G11: ='379'!I20 -> SHV PORT
A12: CTNR No: | B12: : | C12: ='379'!E20 -> CSNU6862609 | F12: PKGS: | G12: ='379'!B20 -> 688 ROLLS
A13: Shipper | B13: : | C13: ='379'!C17 -> SHANGHAI YONGYUE IMP. &EXP. TRADING CO., LTD.
A14: Consignee | B14: : | C14: ='379'!C18 -> JR APPAREL CO., LTD.
A16: NO | C16: DESCRIPTION | D16: Q'TY | E16: U/M | F16: PRICE | G16: TOTAL | H16: ='379'!S12 -> I 136243
A17: 1 | C17: TRUCKING FEE | D17: 1 | E17: 40H | F17: 360 | G17: =ROUND(F17*D17,2) -> 360
A18: 2 | C18: HANDLING FEE | D18: 1 | E18: 40H | F18: 35 | G18: =ROUND(F18*D18,2) -> 35
A19: 3 | C19: INCREASE TRUCKING FEE(65%) | D19: 1 | E19: TRUCK | F19: 234 | G19: =ROUND(F19*D19,2) -> 234 | H19: =F17*65% -> 234
A20: 4 | C20: EXTRA TRUCKING FEE (TO PREK LEAP) | D20: 1 | E20: 40H | F20: 50 | G20: =ROUND(F20*D20,2) -> 50
A21: 5 | C21: MISSING INSURANCE | D21: 1 | E21: SET | F21: 20 | G21: =ROUND(F21*D21,2) -> 20
A22: 6 | C22: DOCUMENT FEE | D22: 1 | E22: SET | F22: 25 | G22: =ROUND(F22*D22,2) -> 25
A23: 7 | C23: SERVICE TAXATION | D23: 1 | E23: SHIP | F23: 20 | G23: =ROUND(F23*D23,2) -> 20
A24: 8 | C24: PERMIT FEE | D24: 1 | E24: SET | F24: 45 | G24: =ROUND(F24*D24,2) -> 45
A25: 9 | C25: FUEL SURCHARE | D25: 1 | E25: 40H | F25: 50 | G25: =ROUND(F25*D25,2) -> 50
A26: 10 | C26: TRUCKING DETENTION CHARGE | D26: 1 | E26: NIGHT | F26: 70 | G26: =ROUND(F26*D26,2) -> 70
A27: 11 | C27: OVER WEIGHT | D27: 4.99 | E27: TON | F27: 50 | G27: =ROUND(F27*D27,2) -> 249.5
A28: 12 | C28: LOLO EMPTY DROP DOWN | D28: 1 | E28: 40H | F28: 24.75 | G28: =ROUND(F28*D28,2) -> 24.75
D29: GRAND TOTAL: | F29: USD | G29: =SUM(G17:G28) -> 1183.25
A51: Thank you for your supporting | E51: AUTHORIZED SIGNATURE

Sheet 387
A2: ក្រុមហ៊ុន ហ្រ្តេតហ្វ៊ូល សឹលូសិន (ខេមបូឌា) ឯ.ក | J2: ក្រុមហ៊ុន ហ្រ្តេតហ្វ៊ូល សឹលូសិន (ខេមបូឌា) ឯ.ក
A3: GRATEFUL SOLUTIONS (CAMBODIA) CO.,LTD. | J3: GRATEFUL SOLUTIONS (CAMBODIA) CO.,LTD.
C4: លេខអត្តសញ្ញាណកម្ម អតប ( VATTIN ) : K008-902404873 | L4: លេខអត្តសញ្ញាណកម្ម អតប ( VATTIN ) : K008-902404873
A5: អាស័យដ្ឋាន : # 7E0 ផ្លូវបេតុង ក្រុម 7 ភូមិទួលថ្ងាន់ សង្កាត់ទួលសង្កែទី2 ខណ្ឌឬស្សីកែវ រាជធានីភ្នំពេញ | J5: អាស័យដ្ឋាន : # 7E0 ផ្លូវបេតុង ក្រុម 7 ភូមិទួលថ្ងាន់ សង្កាត់ទួលសង្កែទី2 ខណ្ឌឬស្សីកែវ រាជធានីភ្នំពេញ
A6: លេខទូរស័ព្ទ:​098​ 484 ​414 | J6: លេខទូរស័ព្ទ:​098​ 484 ​414
A9: វិក្កយបត្រអាករ | J9: វិក្កយបត្របង់ជំនួស
A10: TAX INVOICE | J10: DISBURSEMENT
A12: ឈ្មោះអតិថិជន /Customer: ជេអ អឹភែរឹល ឯ.ក | F12: លេខវិក័យប័ត្រ: /Invoice No: | I12: GS26-387 | J12: =A12 -> ឈ្មោះអតិថិជន /Customer: ជេអ អឹភែរឹល ឯ.ក | O12: លេខវិក័យប័ត្រ: /DIS-No: | R12: DIS430 | S12: E 291340
A13: JR APPAREL CO.,LTD | E13: ការបរិច្ឆេទវិក្កយបត្រ/Invoice Date: | I13: 46293 | J13: =A13 -> JR APPAREL CO.,LTD | N13: ការបរិច្ឆេទវិក្កយបត្រ/DIS-Date: | R13: =I13 -> 46293
A14: អាស័យដ្ឋាន/Address: KAOH KNOR VILLAGE PREAEK ROKA COMMUNE KANDAL | J14: =A14 -> អាស័យដ្ឋាន/Address: KAOH KNOR VILLAGE PREAEK ROKA COMMUNE KANDAL
A15: STUENG DISTRICT, KANDAL STUENG, KANDAL, CAMBODIA | J15: =A15 -> STUENG DISTRICT, KANDAL STUENG, KANDAL, CAMBODIA
A16: លេខ អ ត ប (VATTIN) : L001-902501613 | J16: =A16 -> លេខ អ ត ប (VATTIN) : L001-902501613
A17: SHIPPER: | C17: JR APPAREL CO., LTD. | J17: =A17 -> SHIPPER: | L17: =C17 -> JR APPAREL CO., LTD.
A18: CONSIGNEE : | C18: CHAPTERONE SPORTSWEAR | G18: GROSS WEIGHT: | I18: 14112.8 | J18: =A18 -> CONSIGNEE : | L18: =C18 -> CHAPTERONE SPORTSWEAR | P18: =G18 -> GROSS WEIGHT: | R18: =I18 -> 14112.8
A19: HBL: | B19: COSU6464270740 | D19: VOLUME: | E19: 1X45'HQ | H19: POL: | I19: PNH PORT | J19: =A19 -> HBL: | K19: =B19 -> COSU6464270740 | M19: VOLUME: | N19: =E19 -> 1X45'HQ | Q19: POL: | R19: =I19 -> PNH PORT
A20: PKGS: | B20: 814 CTNS | D20: CTNR No: | E20: CSNU6327198 | H20: POD: | I20: USA | J20: =A20 -> PKGS: | K20: =B20 -> 814 CTNS | M20: CTNR No: | N20: =E20 -> CSNU6327198 | Q20: POD: | R20: =I20 -> USA
G21: 4057 | P21: =G21 -> 4057
A22: ល.រ | B22: បរិយាយមុខទំនិញ | D22: បរិមាណ | E22: ឯកតា | F22: ថ្លៃឯកតា | G22: សរុប | H22: អាករ10% | I22: ថ្លៃទំនិញ | J22: ល.រ | K22: បរិយាយមុខទំនិញ | M22: បរិមាណ | N22: ឯកតា | O22: ថ្លៃឯកតា | P22: សរុប | Q22: អាករ 0% | R22: ថ្លៃទំនិញ
A23: No | B23: Description | D23: Quatity | E23: Unit | F23: Unit Price | G23: Sub. Total | H23: VAT ( 10%) | I23: Amount | J23: No | K23: Description | M23: Quatity | N23: Unit | O23: Unit Price | P23: Sub. Total | Q23: VAT ( 0%) | R23: Amount
A25: 1 | B25: កំរៃសេវាបំពេញបែបបទនាំចេញ / EXPORT PROCESSING FEE | D25: 1 | E25: 45H | F25: 242 | G25: =ROUND(F25*D25,2) -> 242 | H25: =G25*10% -> 24.2 | I25: =H25+G25 -> 266.2 | J25: 1 | K25: LOLO AT PORT | M25: 1 | N25: 45H | O25: 77 | P25: =O25*M25 -> 77 | Q25: 0 | R25: =Q25+P25 -> 77
J26: 2 | K26: CUSTOM PROCESSING FEE | M26: 1 | N26: 45H | O26: 21.25 | P26: =O26*M26 -> 21.25 | Q26: 0 | R26: =Q26+P26 -> 21.25
J27: 3 | K27: HBL FEE | M27: 1 | N27: 45H | O27: 539 | P27: =O27*M27 -> 539 | Q27: 0 | R27: =Q27+P27 -> 539
C29: សរុប SUB TOTAL | E29: KHR | F29: =$I$29*G21 -> 981794 | H29: USD | I29: =SUM(G25:G28) -> 242 | L29: សរុប SUB TOTAL | Q29: USD | R29: =SUM(R25:R28) -> 637.25
C30: អារករលើតម្លៃបន្ថែម (VAT 10%) | E30: KHR | F30: =$I$30*$G$21 -> 98179.4 | H30: USD | I30: =ROUND(SUM(H25:H28),2) -> 24.2 | L30: អារករលើតម្លៃបន្ថែម (VAT 0%) | Q30: USD | R30: 0
C31: សរុបរួម GRAND TOTAL | E31: KHR | F31: =I31*$G$21 -> 1079973.4 | H31: USD | I31: =$I$29+$I$30 -> 266.2 | L31: សរុបរួម GRAND TOTAL | Q31: USD | R31: =SUM(R29:R30) -> 637.25 | S31: =SUM(I31,R31) -> 903.45
A33: Note: Can make payment by cross cheque to: | J33: Note: Can make payment by cross cheque to:
A34: GRATEFUL SOLUTIONS (CAMBODIA) CO.,LTD. | J34: GRATEFUL SOLUTIONS (CAMBODIA) CO.,LTD.
A35: or Deposit Cash/Cheque payment to bank as below: | J35: or Deposit Cash/Cheque payment to bank as below:
A36: KB BRASAC BANK PLC | J36: KB BRASAC BANK PLC
A37: A/NAME: GRATEFUL SOLUTIONS (CAMBODIA) CO.,LTD. | J37: A/NAME: GRATEFUL SOLUTIONS (CAMBODIA) CO.,LTD.
A38: AC/NO: 033 754 230 001 | J38: AC/NO: 033 754 230 001
A49: ________________________ | G49: _______________________________ | J49: ________________________ | P49: _______________________________
A50: ហត្ថលេខា និង ឈ្មោះអ្នកទិញ | G50: ​​​​​​​​​​​ ហត្ថលេខា និង ឈ្មោះអ្នកលក់ | J50: ហត្ថលេខា និង ឈ្មោះអ្នកទិញ | P50: ​​​​​​​​​​​ ហត្ថលេខា និង ឈ្មោះអ្នកលក់
A51: សម្គាល់ច្បាប់ដើមសំរាប់អ្នកទិញច្បាប់ចំលងសំរាប់អ្នកលក់ | J51: សម្គាល់ច្បាប់ដើមសំរាប់អ្នកទិញច្បាប់ចំលងសំរាប់អ្នកលក់
A52: Note ÷ Original invoice for customer , copies invoice for seller | J52: Note ÷ Original invoice for customer , copies invoice for seller

Sheet D007
A1: DEBIT NOTE
A4: CUSTOMER | B4: : | C4: JR APPAREL CO.,LTD | F4: DN NO | G4: JR2609007
A5: ADDRESS | B5: : | C5: KAOH KNOR VILLAGE PREAEK ROKA | F5: DATE | G5: ='387'!I13 -> 46293
C6: COMMUNE KANDALSTUENG DISTRICT,
C7: KANDAL STUENG, KANDAL, CAMBODIA
A9: HBL NO | B9: : | C9: ='387'!B19 -> COSU6464270740
A10: G.W | B10: : | C10: ='387'!I18 -> 14112.8 | F10: POL: | G10: ='387'!I19 -> PNH PORT
A11: VOLUME: | B11: : | C11: ='387'!E19 -> 1X45'HQ | F11: POD: | G11: ='387'!I20 -> USA
A12: CTNR No: | B12: : | C12: ='387'!E20 -> CSNU6327198 | F12: PKGS: | G12: ='387'!B20 -> 814 CTNS
A13: Shipper | B13: : | C13: ='387'!C17 -> JR APPAREL CO., LTD.
A14: Consignee | B14: : | C14: ='387'!C18 -> CHAPTERONE SPORTSWEAR
A16: NO | C16: DESCRIPTION | D16: Q'TY | E16: U/M | F16: PRICE | G16: TOTAL | H16: ='387'!S12 -> E 291340
A17: 1 | C17: TRUCKING FEE | D17: 1 | E17: 45H | F17: 260 | G17: =ROUND(F17*D17,2) -> 260
A18: 2 | C18: HANDLING FEE | D18: 1 | E18: 45H | F18: 35 | G18: =ROUND(F18*D18,2) -> 35
A19: 3 | C19: INCREASE TRUCKING FEE(65%) | D19: 1 | E19: TRUCK | F19: 169 | G19: =ROUND(F19*D19,2) -> 169
A20: 4 | C20: INSPECTION AT DRYPORT | D20: 1 | E20: TIME | F20: 57.5 | G20: =ROUND(F20*D20,2) -> 57.5
A21: 5 | C21: DOCUMENT FEE | D21: 1 | E21: SET | F21: 25 | G21: =ROUND(F21*D21,2) -> 25
A22: 6 | C22: SERVICE TAXATION | D22: 1 | E22: SHIP | F22: 20 | G22: =ROUND(F22*D22,2) -> 20
A23: 7 | C23: FUEL SURCHARGE | D23: 1 | E23: 45H | F23: 40 | G23: =ROUND(F23*D23,2) -> 40
A24: 8 | C24: TRUCKING TO SECOND PLACE | D24: 1 | E24: 45H | F24: 60 | G24: =ROUND(F24*D24,2) -> 60
A25: 9 | C25: LOLO EMPTY CONTAINER | D25: 1 | E25: 45H | F25: 49.5 | G25: =ROUND(F25*D25,2) -> 49.5
A26: 10 | C26: GATE FEE AT DRY PORT | D26: 1 | E26: 45H | F26: 15 | G26: =ROUND(F26*D26,2) -> 15
A27: 11 | C27: APPLY CO FOR INV: JRA26057 | D27: 1 | E27: INV | F27: 40 | G27: =ROUND(F27*D27,2) -> 40
D28: GRAND TOTAL: | F28: USD | G28: =SUM(G17:G27) -> 771
A51: Thank you for your supporting | E51: AUTHORIZED SIGNATURE

Sheet 388
A2: ក្រុមហ៊ុន ហ្រ្តេតហ្វ៊ូល សឹលូសិន (ខេមបូឌា) ឯ.ក | J2: ក្រុមហ៊ុន ហ្រ្តេតហ្វ៊ូល សឹលូសិន (ខេមបូឌា) ឯ.ក
A3: GRATEFUL SOLUTIONS (CAMBODIA) CO.,LTD. | J3: GRATEFUL SOLUTIONS (CAMBODIA) CO.,LTD.
C4: លេខអត្តសញ្ញាណកម្ម អតប ( VATTIN ) : K008-902404873 | L4: លេខអត្តសញ្ញាណកម្ម អតប ( VATTIN ) : K008-902404873
A5: អាស័យដ្ឋាន : # 7E0 ផ្លូវបេតុង ក្រុម 7 ភូមិទួលថ្ងាន់ សង្កាត់ទួលសង្កែទី2 ខណ្ឌឬស្សីកែវ រាជធានីភ្នំពេញ | J5: អាស័យដ្ឋាន : # 7E0 ផ្លូវបេតុង ក្រុម 7 ភូមិទួលថ្ងាន់ សង្កាត់ទួលសង្កែទី2 ខណ្ឌឬស្សីកែវ រាជធានីភ្នំពេញ
A6: លេខទូរស័ព្ទ:​098​ 484 ​414 | J6: លេខទូរស័ព្ទ:​098​ 484 ​414
A9: វិក្កយបត្រអាករ | J9: វិក្កយបត្របង់ជំនួស
A10: TAX INVOICE | J10: DISBURSEMENT
A12: ឈ្មោះអតិថិជន /Customer: ជេអ អឹភែរឹល ឯ.ក | F12: លេខវិក័យប័ត្រ: /Invoice No: | I12: GS26-388 | J12: =A12 -> ឈ្មោះអតិថិជន /Customer: ជេអ អឹភែរឹល ឯ.ក | O12: លេខវិក័យប័ត្រ: /DIS-No: | R12: DIS431 | S12: I 138725
A13: JR APPAREL CO.,LTD | E13: ការបរិច្ឆេទវិក្កយបត្រ/Invoice Date: | I13: 46293 | J13: =A13 -> JR APPAREL CO.,LTD | N13: ការបរិច្ឆេទវិក្កយបត្រ/DIS-Date: | R13: =I13 -> 46293
A14: អាស័យដ្ឋាន/Address: KAOH KNOR VILLAGE PREAEK ROKA COMMUNE KANDAL | J14: =A14 -> អាស័យដ្ឋាន/Address: KAOH KNOR VILLAGE PREAEK ROKA COMMUNE KANDAL
A15: STUENG DISTRICT, KANDAL STUENG, KANDAL, CAMBODIA | J15: =A15 -> STUENG DISTRICT, KANDAL STUENG, KANDAL, CAMBODIA
A16: លេខ អ ត ប (VATTIN) : L001-902501613 | J16: =A16 -> លេខ អ ត ប (VATTIN) : L001-902501613
A17: SHIPPER: | C17: SHANGHAI YONGYUE IMP. &EXP. TRADING CO., LTD. | J17: =A17 -> SHIPPER: | L17: =C17 -> SHANGHAI YONGYUE IMP. &EXP. TRADING CO., LTD.
A18: CONSIGNEE : | C18: JR APPAREL CO., LTD. | G18: GROSS WEIGHT: | I18: 11104.1 | J18: =A18 -> CONSIGNEE : | L18: =C18 -> JR APPAREL CO., LTD. | P18: =G18 -> GROSS WEIGHT: | R18: =I18 -> 11104.1
A19: HBL: | B19: SHSIN6090113 | D19: VOLUME: | E19: 1X20'GP | H19: POL: | I19: CHINA | J19: =A19 -> HBL: | K19: =B19 -> SHSIN6090113 | M19: VOLUME: | N19: =E19 -> 1X20'GP | Q19: POL: | R19: =I19 -> CHINA
A20: PKGS: | B20: 306 ROLLS | D20: CTNR No: | E20: SEKU1756681 | H20: POD: | I20: SHV PORT | J20: =A20 -> PKGS: | K20: =B20 -> 306 ROLLS | M20: CTNR No: | N20: =E20 -> SEKU1756681 | Q20: POD: | R20: =I20 -> SHV PORT
G21: 4057 | P21: =G21 -> 4057
A22: ល.រ | B22: បរិយាយមុខទំនិញ | D22: បរិមាណ | E22: ឯកតា | F22: ថ្លៃឯកតា | G22: សរុប | H22: អាករ10% | I22: ថ្លៃទំនិញ | J22: ល.រ | K22: បរិយាយមុខទំនិញ | M22: បរិមាណ | N22: ឯកតា | O22: ថ្លៃឯកតា | P22: សរុប | Q22: អាករ 0% | R22: ថ្លៃទំនិញ
A23: No | B23: Description | D23: Quatity | E23: Unit | F23: Unit Price | G23: Sub. Total | H23: VAT ( 10%) | I23: Amount | J23: No | K23: Description | M23: Quatity | N23: Unit | O23: Unit Price | P23: Sub. Total | Q23: VAT ( 0%) | R23: Amount
A25: 1 | B25: កំរៃសេវាបំពេញបែបបទនាំចូល / IMPORT PROCESSING FEE | D25: 1 | E25: 20G | F25: 180 | G25: =ROUND(F25*D25,2) -> 180 | H25: =G25*10% -> 18 | I25: =H25+G25 -> 198 | J25: 1 | K25: LOLO AT PORT | M25: 1 | N25: 20G | O25: 62.7 | P25: =O25*M25 -> 62.7 | Q25: 0 | R25: =Q25+P25 -> 62.7
J26: 2 | K26: CUSTOM PROCESSING FEE | M26: 1 | N26: 20G | O26: 18.75 | P26: =O26*M26 -> 18.75 | Q26: 0 | R26: =Q26+P26 -> 18.75
J27: 3 | K27: THC FEE | M27: 1 | N27: 20G | O27: 479.5 | P27: =O27*M27 -> 479.5 | Q27: 0 | R27: =Q27+P27 -> 479.5
C29: សរុប SUB TOTAL | E29: KHR | F29: =$I$29*G21 -> 730260 | H29: USD | I29: =SUM(G25:G28) -> 180 | L29: សរុប SUB TOTAL | Q29: USD | R29: =SUM(R24:R28) -> 560.95
C30: អារករលើតម្លៃបន្ថែម (VAT 10%) | E30: KHR | F30: =$I$30*$G$21 -> 73026 | H30: USD | I30: =ROUND(SUM(H25:H28),2) -> 18 | L30: អារករលើតម្លៃបន្ថែម (VAT 0%) | Q30: USD | R30: 0
C31: សរុបរួម GRAND TOTAL | E31: KHR | F31: =I31*$G$21 -> 803286 | H31: USD | I31: =$I$29+$I$30 -> 198 | L31: សរុបរួម GRAND TOTAL | Q31: USD | R31: =SUM(R29:R30) -> 560.95 | S31: =SUM(I31,R31) -> 758.95
A33: Note: Can make payment by cross cheque to: | J33: Note: Can make payment by cross cheque to:
A34: GRATEFUL SOLUTIONS (CAMBODIA) CO.,LTD. | J34: GRATEFUL SOLUTIONS (CAMBODIA) CO.,LTD.
A35: or Deposit Cash/Cheque payment to bank as below: | J35: or Deposit Cash/Cheque payment to bank as below:
A36: KB BRASAC BANK PLC | J36: KB BRASAC BANK PLC
A37: A/NAME: GRATEFUL SOLUTIONS (CAMBODIA) CO.,LTD. | J37: A/NAME: GRATEFUL SOLUTIONS (CAMBODIA) CO.,LTD.
A38: AC/NO: 033 754 230 001 | J38: AC/NO: 033 754 230 001
A48: ________________________ | G48: _______________________________ | J48: ________________________ | P48: _______________________________
A49: ហត្ថលេខា និង ឈ្មោះអ្នកទិញ | G49: ​​​​​​​​​​​ ហត្ថលេខា និង ឈ្មោះអ្នកលក់ | J49: ហត្ថលេខា និង ឈ្មោះអ្នកទិញ | P49: ​​​​​​​​​​​ ហត្ថលេខា និង ឈ្មោះអ្នកលក់
A50: សម្គាល់ច្បាប់ដើមសំរាប់អ្នកទិញច្បាប់ចំលងសំរាប់អ្នកលក់ | J50: សម្គាល់ច្បាប់ដើមសំរាប់អ្នកទិញច្បាប់ចំលងសំរាប់អ្នកលក់
A51: Note ÷ Original invoice for customer , copies invoice for seller | J51: Note ÷ Original invoice for customer , copies invoice for seller

Sheet D008
A1: DEBIT NOTE
A4: CUSTOMER | B4: : | C4: JR APPAREL CO.,LTD | F4: DN NO | G4: JR2609008
A5: ADDRESS | B5: : | C5: KAOH KNOR VILLAGE PREAEK ROKA | F5: DATE | G5: ='388'!R13 -> 46293
C6: COMMUNE KANDALSTUENG DISTRICT,
C7: KANDAL STUENG, KANDAL, CAMBODIA
A9: HBL NO | B9: : | C9: ='388'!B19 -> SHSIN6090113
A10: G.W | B10: : | C10: ='388'!I18 -> 11104.1 | F10: POL: | G10: ='388'!I19 -> CHINA
A11: VOLUME: | B11: : | C11: ='388'!E19 -> 1X20'GP | F11: POD: | G11: ='388'!I20 -> SHV PORT
A12: CTNR No: | B12: : | C12: ='388'!E20 -> SEKU1756681 | F12: PKGS: | G12: ='388'!B20 -> 306 ROLLS
A13: Shipper | B13: : | C13: ='388'!C17 -> SHANGHAI YONGYUE IMP. &EXP. TRADING CO., LTD.
A14: Consignee | B14: : | C14: ='388'!C18 -> JR APPAREL CO., LTD.
A16: NO | C16: DESCRIPTION | D16: Q'TY | E16: U/M | F16: PRICE | G16: TOTAL | H16: ='388'!S12 -> I 138725
A17: 1 | C17: TRUCKING FEE | D17: 1 | E17: 20G | F17: 280 | G17: =ROUND(F17*D17,2) -> 280
A18: 2 | C18: HANDLING FEE | D18: 1 | E18: 20G | F18: 35 | G18: =ROUND(F18*D18,2) -> 35
A19: 3 | C19: INCREASE TRUCKING FEE(65%) | D19: 1 | E19: TRUCK | F19: 182 | G19: =ROUND(F19*D19,2) -> 182 | H19: =F17*65% -> 182
A20: 4 | C20: EXTRA TRUCKING FEE (TO PREK LEAP) | D20: 1 | E20: 20G | F20: 50 | G20: =ROUND(F20*D20,2) -> 50
A21: 5 | C21: PERMIT FEE | D21: 1 | E21: SET | F21: 45 | G21: =ROUND(F21*D21,2) -> 45
A22: 4 | C22: DOCUMENT FEE | D22: 1 | E22: SET | F22: 25 | G22: =ROUND(F22*D22,2) -> 25
A23: 5 | C23: SERVICE TAXATION | D23: 1 | E23: SHIP | F23: 20 | G23: =ROUND(F23*D23,2) -> 20
A24: 6 | C24: MISSING INSURANCE | D24: 1 | E24: SET | F24: 20 | G24: =ROUND(F24*D24,2) -> 20
A25: 7 | C25: FUEL SURCHARGE | D25: 1 | E25: 20G | F25: 30 | G25: =ROUND(F25*D25,2) -> 30
A26: 9 | C26: LOLO EMPTY DROP DOWN | D26: 1 | E26: 20G | F26: 16.5 | G26: =ROUND(F26*D26,2) -> 16.5
D27: GRAND TOTAL: | F27: USD | G27: =SUM(G17:G26) -> 703.5
A51: Thank you for your supporting | E51: AUTHORIZED SIGNATURE

Sheet 389
A2: ក្រុមហ៊ុន ហ្រ្តេតហ្វ៊ូល សឹលូសិន (ខេមបូឌា) ឯ.ក | J2: ក្រុមហ៊ុន ហ្រ្តេតហ្វ៊ូល សឹលូសិន (ខេមបូឌា) ឯ.ក
A3: GRATEFUL SOLUTIONS (CAMBODIA) CO.,LTD. | J3: GRATEFUL SOLUTIONS (CAMBODIA) CO.,LTD.
C4: លេខអត្តសញ្ញាណកម្ម អតប ( VATTIN ) : K008-902404873 | L4: លេខអត្តសញ្ញាណកម្ម អតប ( VATTIN ) : K008-902404873
A5: អាស័យដ្ឋាន : # 7E0 ផ្លូវបេតុង ក្រុម 7 ភូមិទួលថ្ងាន់ សង្កាត់ទួលសង្កែទី2 ខណ្ឌឬស្សីកែវ រាជធានីភ្នំពេញ | J5: អាស័យដ្ឋាន : # 7E0 ផ្លូវបេតុង ក្រុម 7 ភូមិទួលថ្ងាន់ សង្កាត់ទួលសង្កែទី2 ខណ្ឌឬស្សីកែវ រាជធានីភ្នំពេញ
A6: លេខទូរស័ព្ទ:​098​ 484 ​414 | J6: លេខទូរស័ព្ទ:​098​ 484 ​414
A9: វិក្កយបត្រអាករ | J9: វិក្កយបត្របង់ជំនួស
A10: TAX INVOICE | J10: DISBURSEMENT
A12: ឈ្មោះអតិថិជន /Customer: ជេអ អឹភែរឹល ឯ.ក | F12: លេខវិក័យប័ត្រ: /Invoice No: | I12: GS26-389 | J12: =A12 -> ឈ្មោះអតិថិជន /Customer: ជេអ អឹភែរឹល ឯ.ក | O12: លេខវិក័យប័ត្រ: /DIS-No: | R12: DIS432 | S12: I 138735
A13: JR APPAREL CO.,LTD | E13: ការបរិច្ឆេទវិក្កយបត្រ/Invoice Date: | I13: 46293 | J13: =A13 -> JR APPAREL CO.,LTD | N13: ការបរិច្ឆេទវិក្កយបត្រ/DIS-Date: | R13: =I13 -> 46293
A14: អាស័យដ្ឋាន/Address: KAOH KNOR VILLAGE PREAEK ROKA COMMUNE KANDAL | J14: =A14 -> អាស័យដ្ឋាន/Address: KAOH KNOR VILLAGE PREAEK ROKA COMMUNE KANDAL
A15: STUENG DISTRICT, KANDAL STUENG, KANDAL, CAMBODIA | J15: =A15 -> STUENG DISTRICT, KANDAL STUENG, KANDAL, CAMBODIA
A16: លេខ អ ត ប (VATTIN) : L001-902501613 | J16: =A16 -> លេខ អ ត ប (VATTIN) : L001-902501613
A17: SHIPPER: | C17: SHANGHAI YONGYUE IMP. &EXP. TRADING CO., LTD. | J17: =A17 -> SHIPPER: | L17: =C17 -> SHANGHAI YONGYUE IMP. &EXP. TRADING CO., LTD.
A18: CONSIGNEE : | C18: JR APPAREL CO., LTD. | G18: GROSS WEIGHT: | I18: 18809.5 | J18: =A18 -> CONSIGNEE : | L18: =C18 -> JR APPAREL CO., LTD. | P18: =G18 -> GROSS WEIGHT: | R18: =I18 -> 18809.5
A19: HBL: | B19: SHSIN6090031 | D19: VOLUME: | E19: 1X40'HQ | H19: POL: | I19: CHINA | J19: =A19 -> HBL: | K19: =B19 -> SHSIN6090031 | M19: VOLUME: | N19: =E19 -> 1X40'HQ | O19: =F19 -> 0 | Q19: POL: | R19: =I19 -> CHINA
A20: PKGS: | B20: 635 ROLLS | D20: CTNR No: | E20: ZCSU7954124 | H20: POD: | I20: SHV PORT | J20: =A20 -> PKGS: | K20: =B20 -> 635 ROLLS | M20: CTNR No: | N20: =E20 -> ZCSU7954124 | Q20: POD: | R20: =I20 -> SHV PORT
G21: 4057 | P21: =G21 -> 4057
A22: ល.រ | B22: បរិយាយមុខទំនិញ | D22: បរិមាណ | E22: ឯកតា | F22: ថ្លៃឯកតា | G22: សរុប | H22: អាករ10% | I22: ថ្លៃទំនិញ | J22: ល.រ | K22: បរិយាយមុខទំនិញ | M22: បរិមាណ | N22: ឯកតា | O22: ថ្លៃឯកតា | P22: សរុប | Q22: អាករ 0% | R22: ថ្លៃទំនិញ
A23: No | B23: Description | D23: Quatity | E23: Unit | F23: Unit Price | G23: Sub. Total | H23: VAT ( 10%) | I23: Amount | J23: No | K23: Description | M23: Quatity | N23: Unit | O23: Unit Price | P23: Sub. Total | Q23: VAT ( 0%) | R23: Amount
A25: 1 | B25: កំរៃសេវាបំពេញបែបបទនាំចូល / IMPORT PROCESSING FEE | D25: 1 | E25: 40H | F25: 200 | G25: =ROUND(F25*D25,2) -> 200 | H25: =G25*10% -> 20 | I25: =H25+G25 -> 220 | J25: 1 | K25: LOLO AT PORT | M25: 1 | N25: 40H | O25: 95.7 | P25: =O25*M25 -> 95.7 | Q25: 0 | R25: =Q25+P25 -> 95.7
J26: 2 | K26: CUSTOM PROCESSING FEE | M26: 1 | N26: 40H | O26: 18.75 | P26: =O26*M26 -> 18.75 | Q26: 0 | R26: =Q26+P26 -> 18.75
J27: 3 | K27: THC FEE | M27: 1 | N27: 40H | O27: 599.5 | P27: =O27*M27 -> 599.5 | Q27: 0 | R27: =Q27+P27 -> 599.5
C29: សរុប SUB TOTAL | E29: KHR | F29: =$I$29*G21 -> 811400 | H29: USD | I29: =SUM(G25:G28) -> 200 | L29: សរុប SUB TOTAL | Q29: USD | R29: =SUM(R24:R28) -> 713.95
C30: អារករលើតម្លៃបន្ថែម (VAT 10%) | E30: KHR | F30: =$I$30*$G$21 -> 81140 | H30: USD | I30: =ROUND(SUM(H25:H28),2) -> 20 | L30: អារករលើតម្លៃបន្ថែម (VAT 0%) | Q30: USD | R30: 0
C31: សរុបរួម GRAND TOTAL | E31: KHR | F31: =I31*$G$21 -> 892540 | H31: USD | I31: =$I$29+$I$30 -> 220 | L31: សរុបរួម GRAND TOTAL | Q31: USD | R31: =SUM(R29:R30) -> 713.95 | S31: =SUM(I31,R31) -> 933.95
A33: Note: Can make payment by cross cheque to: | J33: Note: Can make payment by cross cheque to:
A34: GRATEFUL SOLUTIONS (CAMBODIA) CO.,LTD. | J34: GRATEFUL SOLUTIONS (CAMBODIA) CO.,LTD.
A35: or Deposit Cash/Cheque payment to bank as below: | J35: or Deposit Cash/Cheque payment to bank as below:
A36: KB BRASAC BANK PLC | J36: KB BRASAC BANK PLC
A37: A/NAME: GRATEFUL SOLUTIONS (CAMBODIA) CO.,LTD. | J37: A/NAME: GRATEFUL SOLUTIONS (CAMBODIA) CO.,LTD.
A38: AC/NO: 033 754 230 001 | J38: AC/NO: 033 754 230 001
A48: ________________________ | G48: _______________________________ | J48: ________________________ | P48: _______________________________
A49: ហត្ថលេខា និង ឈ្មោះអ្នកទិញ | G49: ​​​​​​​​​​​ ហត្ថលេខា និង ឈ្មោះអ្នកលក់ | J49: ហត្ថលេខា និង ឈ្មោះអ្នកទិញ | P49: ​​​​​​​​​​​ ហត្ថលេខា និង ឈ្មោះអ្នកលក់
A50: សម្គាល់ច្បាប់ដើមសំរាប់អ្នកទិញច្បាប់ចំលងសំរាប់អ្នកលក់ | J50: សម្គាល់ច្បាប់ដើមសំរាប់អ្នកទិញច្បាប់ចំលងសំរាប់អ្នកលក់
A51: Note ÷ Original invoice for customer , copies invoice for seller | J51: Note ÷ Original invoice for customer , copies invoice for seller

Sheet D009
A1: DEBIT NOTE
A4: CUSTOMER | B4: : | C4: JR APPAREL CO.,LTD | F4: DN NO | G4: JR2609009
A5: ADDRESS | B5: : | C5: KAOH KNOR VILLAGE PREAEK ROKA | F5: DATE | G5: ='389'!R13 -> 46293
C6: COMMUNE KANDALSTUENG DISTRICT,
C7: KANDAL STUENG, KANDAL, CAMBODIA
A9: HBL NO | B9: : | C9: ='389'!B19 -> SHSIN6090031
A10: G.W | B10: : | C10: ='389'!I18 -> 18809.5 | F10: POL: | G10: ='389'!I19 -> CHINA
A11: VOLUME: | B11: : | C11: ='389'!E19 -> 1X40'HQ | F11: POD: | G11: ='389'!I20 -> SHV PORT
A12: CTNR No: | B12: : | C12: ='389'!E20 -> ZCSU7954124 | F12: PKGS: | G12: ='389'!B20 -> 635 ROLLS
A13: Shipper | B13: : | C13: ='389'!C17 -> SHANGHAI YONGYUE IMP. &EXP. TRADING CO., LTD.
A14: Consignee | B14: : | C14: ='389'!C18 -> JR APPAREL CO., LTD.
A16: NO | C16: DESCRIPTION | D16: Q'TY | E16: U/M | F16: PRICE | G16: TOTAL | H16: ='389'!S12 -> I 138735
