Workbook

Sheet IMPORT
A1: ETA PORT | B1: ETA FTY | C1: F.W BROKER | D1: SHIPPER | E1: INV | F1: DATE | G1: QTY PKGS | H1: ORG / DEST | I1: MONTH | J1: MATERIAL | K1: ITEM | L1: CDC NO | M1: QUANTITY | N1: CDC UNIT | O1: NW.KGS | P1: GW.KGS | Q1: UNIT PRICE | R1: AMOUNT | S1: HBL | T1: MARK | U1: DECLARE | V1: DECLARE DATE | W1: THC FEE | X1: INVOICE DATE | Y1: INVOICE NUMBER | Z1: GS INVOICE | AA1: GS DIS | AB1: GS DN
A2: 45945 | B2: 45959 | C2: FWF GRATEFUL | D2: BRISK INDUSTRY | E2: JRCNQ25033 | F2: 45929 | G2: 388 | H2: CH-SHV | I2: 10-2025 | J2: I. MACHINERIES & EQUIPMENTS | K2: ONE NEEDLE SEWING MACHINE | L2: =VLOOKUP(K2,CDC!$B$6:$O$203,14,FALSE) -> I-7 | M2: 64 | N2: =VLOOKUP(K2,CDC!$B$6:$O$203,3,FALSE) -> SET | O2: 4268 | P2: 4656 | Q2: 320 | R2: 20480 | S2: NBSIN5100006 | T2: BSIU9352545 / 40HQ Driver H/P 096 792 6032 Stand by container 21day | U2: I 33843 | V2: 45947
A3: 45945 | B3: 45959 | H3: CH-SHV | I3: 10-2025 | J3: I. MACHINERIES & EQUIPMENTS | K3: TWO NEEDLE SEWING MACHINE | L3: =VLOOKUP(K3,CDC!$B$6:$O$203,14,FALSE) -> I-8 | M3: 2 | N3: =VLOOKUP(K3,CDC!$B$6:$O$203,3,FALSE) -> SET | O3: 138 | P3: 160 | Q3: 1500 | R3: 3000 | U3: I 33843 | V3: 45947
A4: 45945 | B4: 45959 | H4: CH-SHV | I4: 10-2025 | J4: I. MACHINERIES & EQUIPMENTS | K4: FOUR NEEDLE SIX THREAD SEWING MACHINE | L4: =VLOOKUP(K4,CDC!$B$6:$O$203,14,FALSE) -> I-10 | M4: 2 | N4: =VLOOKUP(K4,CDC!$B$6:$O$203,3,FALSE) -> SET | O4: 380 | P4: 500 | Q4: 3000 | R4: 6000 | U4: I 33843 | V4: 45947
A5: 45945 | B5: 45959 | H5: CH-SHV | I5: 10-2025 | J5: I. MACHINERIES & EQUIPMENTS | K5: FOUR THREAD OVERLOCK SEWING MACHINE | L5: =VLOOKUP(K5,CDC!$B$6:$O$203,14,FALSE) -> I-11 | M5: 24 | N5: =VLOOKUP(K5,CDC!$B$6:$O$203,3,FALSE) -> SET | O5: 1540 | P5: 1676 | Q5: 500 | R5: 12000 | U5: I 33843 | V5: 45947
A6: 45945 | B6: 45959 | H6: CH-SHV | I6: 10-2025 | J6: I. MACHINERIES & EQUIPMENTS | K6: FIVE THREAD OVERLOCK SEWING MACHINE | L6: =VLOOKUP(K6,CDC!$B$6:$O$203,14,FALSE) -> I-12 | M6: 46 | N6: =VLOOKUP(K6,CDC!$B$6:$O$203,3,FALSE) -> SET | O6: 3082 | P6: 3367.2 | Q6: 550 | R6: 25300 | U6: I 33843 | V6: 45947
A7: 45945 | B7: 45959 | H7: CH-SHV | I7: 10-2025 | J7: I. MACHINERIES & EQUIPMENTS | K7: SEWING MACHINE | L7: =VLOOKUP(K7,CDC!$B$6:$O$203,14,FALSE) -> I-14 | M7: 7 | N7: =VLOOKUP(K7,CDC!$B$6:$O$203,3,FALSE) -> SET | O7: 553 | P7: 581 | Q7: 1000 | R7: 7000 | U7: I 33843 | V7: 45947
A8: 45945 | B8: 45959 | H8: CH-SHV | I8: 10-2025 | J8: I. MACHINERIES & EQUIPMENTS | K8: BARTACKING MACHINE | L8: =VLOOKUP(K8,CDC!$B$6:$O$203,14,FALSE) -> I-16 | M8: 10 | N8: =VLOOKUP(K8,CDC!$B$6:$O$203,3,FALSE) -> SET | O8: 820 | P8: 890 | Q8: 1200 | R8: 12000 | U8: I 33843 | V8: 45947
A9: 45945 | B9: 45959 | H9: CH-SHV | I9: 10-2025 | J9: I. MACHINERIES & EQUIPMENTS | K9: AUTO POCKET MAKING MACHINE | L9: =VLOOKUP(K9,CDC!$B$6:$O$203,14,FALSE) -> I-20 | M9: 4 | N9: =VLOOKUP(K9,CDC!$B$6:$O$203,3,FALSE) -> SET | O9: 1040 | P9: 1440 | Q9: 3200 | R9: 12800 | U9: I 33843 | V9: 45947
A10: 45945 | B10: 45959 | H10: CH-SHV | I10: 10-2025 | J10: I. MACHINERIES & EQUIPMENTS | K10: BUTTON SEWING MACHINE | L10: =VLOOKUP(K10,CDC!$B$6:$O$203,14,FALSE) -> I-26 | M10: 5 | N10: =VLOOKUP(K10,CDC!$B$6:$O$203,3,FALSE) -> SET | O10: 370 | P10: 415 | Q10: 1500 | R10: 7500 | U10: I 33843 | V10: 45947
A11: 45945 | B11: 45959 | C11: FWF GRATEFUL | D11: BRISK INDUSTRY | E11: JRCNQ25032 | F11: 45929 | G11: 57 | H11: CH-SHV | I11: 10-2025 | J11: I. MACHINERIES & EQUIPMENTS | K11: FABRIC INSPECTION MACHINE | L11: =VLOOKUP(K11,CDC!$B$6:$O$203,14,FALSE) -> I-3 | M11: 2 | N11: =VLOOKUP(K11,CDC!$B$6:$O$203,3,FALSE) -> SET | O11: 1660 | P11: 1920 | Q11: 5500 | R11: 11000 | S11: SHSIN5100005 | T11: CSNU8516288 / 40HQ Driver H/P 096 6424288 21day--RED SIGNAL | U11: I 33840 | V11: 45947
A12: 45945 | B12: 45959 | H12: CH-SHV | I12: 10-2025 | J12: I. MACHINERIES & EQUIPMENTS | K12: FABRIC RELAXING MACHINE | L12: =VLOOKUP(K12,CDC!$B$6:$O$203,14,FALSE) -> I-38 | M12: 1 | N12: =VLOOKUP(K12,CDC!$B$6:$O$203,3,FALSE) -> SET | O12: 230 | P12: 320 | Q12: 2100 | R12: 2100 | U12: I 33840 | V12: 45947
A13: 45945 | B13: 45959 | H13: CH-SHV | I13: 10-2025 | J13: I. MACHINERIES & EQUIPMENTS | K13: FUSING MACHINE | L13: =VLOOKUP(K13,CDC!$B$6:$O$203,14,FALSE) -> I-43 | M13: 2 | N13: =VLOOKUP(K13,CDC!$B$6:$O$203,3,FALSE) -> SET | O13: 1160 | P13: 1340 | Q13: 3000 | R13: 6000 | U13: I 33840 | V13: 45947
A14: 45945 | B14: 45959 | H14: CH-SHV | I14: 10-2025 | J14: I. MACHINERIES & EQUIPMENTS | K14: IRON TABLE | L14: =VLOOKUP(K14,CDC!$B$6:$O$203,14,FALSE) -> I-70 | M14: 20 | N14: =VLOOKUP(K14,CDC!$B$6:$O$203,3,FALSE) -> SET | O14: 1180 | P14: 1262 | Q14: 200 | R14: 4000 | U14: I 33840 | V14: 45947
A15: 45945 | B15: 45959 | C15: COSCO GRATEFUL | D15: BRISK INDUSTRY | E15: JRCNQ25027 | F15: 45937 | G15: 93 | H15: CH-SHV | I15: 10-2025 | J15: I. MACHINERIES & EQUIPMENTS | K15: BUTTON PULL TEST MACHINE | L15: =VLOOKUP(K15,CDC!$B$6:$O$203,14,FALSE) -> I-58 | M15: 1 | N15: =VLOOKUP(K15,CDC!$B$6:$O$203,3,FALSE) -> SET | O15: 272.2 | P15: 26 | Q15: 600 | R15: 600 | S15: COAU7262776160 | T15: TIIU5355369 / 40HQ driver H/P 016 612 849 Retop-PP pay to customs for with wrong item 300$ | U15: I 139328 | V15: 45958
A16: 45945 | B16: 45959 | H16: CH-SHV | I16: 10-2025 | J16: I. MACHINERIES & EQUIPMENTS | K16: TEMPERATURE MEASURING DEVICE | L16: =VLOOKUP(K16,CDC!$B$6:$O$203,14,FALSE) -> I-86 | M16: 2 | N16: =VLOOKUP(K16,CDC!$B$6:$O$203,3,FALSE) -> SET | O16: 1 | P16: 0.6 | Q16: 60 | R16: 120 | U16: I 139328 | V16: 45958
A17: 45945 | B17: 45959 | H17: CH-SHV | I17: 10-2025 | J17: I. MACHINERIES & EQUIPMENTS | K17: SEWING SITTING CHAIRS | L17: =VLOOKUP(K17,CDC!$B$6:$O$203,14,FALSE) -> I-103 | M17: 212 | N17: =VLOOKUP(K17,CDC!$B$6:$O$203,3,FALSE) -> SET | O17: 172.8 | P17: 1048.8 | Q17: 10 | R17: 2120 | U17: I 139328 | V17: 45958
A18: 45945 | B18: 45959 | H18: CH-SHV | I18: 10-2025 | J18: I. MACHINERIES & EQUIPMENTS | K18: TROLLEY | L18: =VLOOKUP(K18,CDC!$B$6:$O$203,14,FALSE) -> I-98 | M18: 18 | N18: =VLOOKUP(K18,CDC!$B$6:$O$203,3,FALSE) -> SET | O18: 580 | P18: 906 | Q18: 110 | R18: 1980 | U18: I 139328 | V18: 45958
A19: 45945 | B19: 45959 | H19: CH-SHV | I19: 10-2025 | J19: I. MACHINERIES & EQUIPMENTS | K19: PLASTIC FRAME | L19: =VLOOKUP(K19,CDC!$B$6:$O$203,14,FALSE) -> I-122 | M19: 20 | N19: =VLOOKUP(K19,CDC!$B$6:$O$203,3,FALSE) -> SET | O19: 25 | P19: 200 | Q19: 20 | R19: 400 | U19: I 139328 | V19: 45958
A20: 45945 | B20: 45959 | H20: CH-SHV | I20: 10-2025 | J20: I. MACHINERIES & EQUIPMENTS | K20: SNAP FIXING MACHINE | L20: =VLOOKUP(K20,CDC!$B$6:$O$203,14,FALSE) -> I-27 | M20: 6 | N20: =VLOOKUP(K20,CDC!$B$6:$O$203,3,FALSE) -> SET | O20: 40.4 | P20: 180 | Q20: 300 | R20: 1800 | U20: I 139328 | V20: 45958
A21: 45945 | B21: 45959 | H21: CH-SHV | I21: 10-2025 | J21: I. MACHINERIES & EQUIPMENTS | K21: INSPECTION TABLE | L21: =VLOOKUP(K21,CDC!$B$6:$O$203,14,FALSE) -> I-96 | M21: 40 | N21: =VLOOKUP(K21,CDC!$B$6:$O$203,3,FALSE) -> SET | O21: 1973.7 | P21: 3363 | Q21: 80 | R21: 3200 | U21: I 139328 | V21: 45958
A22: 45945 | B22: 45959 | H22: CH-SHV | I22: 10-2025 | J22: I. MACHINERIES & EQUIPMENTS | K22: LOOSE CLOTH RACK | L22: =VLOOKUP(K22,CDC!$B$6:$O$203,14,FALSE) -> I-100 | M22: 5 | N22: =VLOOKUP(K22,CDC!$B$6:$O$203,3,FALSE) -> SET | O22: 0.57 | P22: 477 | Q22: 240 | R22: 1200 | U22: I 139328 | V22: 45958
A23: 45945 | B23: 45959 | H23: CH-SHV | I23: 10-2025 | J23: I. MACHINERIES & EQUIPMENTS | K23: BOILER | L23: =VLOOKUP(K23,CDC!$B$6:$O$203,14,FALSE) -> I-68 | M23: 1 | N23: =VLOOKUP(K23,CDC!$B$6:$O$203,3,FALSE) -> SET | O23: 3360.6 | P23: 1983.3 | Q23: 8000 | R23: 8000 | U23: I 139328 | V23: 45958
A24: 45945 | B24: 45959 | H24: CH-SHV | I24: 10-2025 | J24: I. MACHINERIES & EQUIPMENTS | K24: VERY NARROW AISLE FORKLIFT (VNA) | L24: =VLOOKUP(K24,CDC!$B$6:$O$203,14,FALSE) -> I-50 | M24: 1 | N24: =VLOOKUP(K24,CDC!$B$6:$O$203,3,FALSE) -> SET | O24: 903 | P24: 700 | Q24: 6000 | R24: 6000 | U24: I 139328 | V24: 45958
A25: 45945 | B25: 45959 | H25: CH-SHV | I25: 10-2025 | J25: I. MACHINERIES & EQUIPMENTS | K25: LIGHT BOX | L25: =VLOOKUP(K25,CDC!$B$6:$O$203,14,FALSE) -> I-63 | M25: 1 | N25: =VLOOKUP(K25,CDC!$B$6:$O$203,3,FALSE) -> SET | O25: 476.2 | P25: 41 | Q25: 700 | R25: 700 | U25: I 139328 | V25: 45958
A26: 45945 | B26: 45959 | H26: CH-SHV | I26: 10-2025 | J26: I. MACHINERIES & EQUIPMENTS | K26: METAL DETECTOR MACHINE | L26: =VLOOKUP(K26,CDC!$B$6:$O$203,14,FALSE) -> I-1 | M26: 1 | N26: =VLOOKUP(K26,CDC!$B$6:$O$203,3,FALSE) -> SET | O26: 1014.6 | P26: 273 | Q26: 4500 | R26: 4500 | U26: I 139328 | V26: 45958
A27: 45945 | B27: 45959 | H27: CH-SHV | I27: 10-2025 | J27: I. MACHINERIES & EQUIPMENTS | K27: HANDHELD SCANNER | L27: =VLOOKUP(K27,CDC!$B$6:$O$203,14,FALSE) -> I-2 | M27: 2 | N27: =VLOOKUP(K27,CDC!$B$6:$O$203,3,FALSE) -> SET | O27: 197 | P27: 2 | Q27: 130 | R27: 260 | U27: I 139328 | V27: 45958
A28: 45967 | B28: 45938 | C28: FWF GRATEFUL | D28: BRISK INDUSTRY | E28: JRCNQ25038 | F28: 45947 | G28: 5 | H28: CH-SHV | I28: 10-2025 | J28: I. MACHINERIES & EQUIPMENTS | K28: FABRIC SPREADING MACHINE | L28: =VLOOKUP(K28,CDC!$B$6:$O$203,14,FALSE) -> I-36 | M28: 1 | N28: =VLOOKUP(K28,CDC!$B$6:$O$203,3,FALSE) -> SET | O28: 4785.07 | P28: 4985.95 | Q28: =R28/M28 -> 19000 | R28: 19000 | S28: QDSIN5100137 | T28: EGSU3278049/ 20GP | U28: I 154789 | V28: 45988
A30: 46048 | B30: 46051 | C30: FWF GRATEFUL | D30: SHANGHAI YOUNGYUE | E30: CNQ126001 | F30: 46041 | G30: 912 | H30: CH-SHV | I30: 01-2026 | J30: II. RAW MATERIAL | K30: KNITTED FABRIC | L30: =VLOOKUP(K30,CDC!$B$6:$O$203,14,FALSE) -> II-125 | M30: 17262 | N30: MTR | O30: 6298.9 | P30: 6379 | Q30: 1 | R30: 17262 | S30: SHSIN6010077 | U30: I 14254 | V30: 46050
A31: 46048 | B31: 46051 | H31: CH-SHV | I31: 01-2026 | J31: II. RAW MATERIAL | K31: WOVEN FABRIC | L31: =VLOOKUP(K31,CDC!$B$6:$O$203,14,FALSE) -> II-124 | M31: 50625.4 | N31: MTR | O31: 12927.4 | P31: 13172.5 | Q31: 1.8 | R31: 91125.72 | U31: I 14254 | V31: 46050
A32: 46048 | B32: 46051 | H32: CH-SHV | I32: 01-2026 | J32: II. RAW MATERIAL | K32: HANGER | L32: =VLOOKUP(K32,CDC!$B$6:$O$203,14,FALSE) -> III-182 | M32: 380 | N32: DZN | O32: 375.4 | P32: 402.6 | Q32: 1 | R32: 380 | U32: I 14254 | V32: 46050
A33: 46051 | B33: 46055 | C33: FWF GRATEFUL | D33: SHANGHAI YOUNGYUE | E33: CNQ126003 | F33: 46043 | G33: 362 | H33: CH-SHV | I33: 01-2026 | J33: III. ACCESSORY | K33: WOVEN FABRIC | L33: =VLOOKUP(K33,CDC!$B$6:$O$203,14,FALSE) -> II-124 | M33: 28887.4 | N33: MTR | O33: 7934.8 | P33: 8022.1 | Q33: 1.8 | R33: 51997.32 | S33: SHSIN6010126 | U33: I 15940 | V33: 46052
A35: 46061 | B35: 46063 | C35: FWF GRATEFUL | D35: SHANGHAI YOUNGYUE | E35: CNQ26004 | F35: 46045 | G35: 743 | H35: CH-SHV | I35: 02-2026 | J35: II. RAW MATERIAL | K35: KNITTED FABRIC | L35: =VLOOKUP(K35,CDC!$B$6:$O$203,14,FALSE) -> II-125 | M35: 41469.8 | N35: MTR | O35: 19220.9 | P35: 19367.3 | Q35: 1 | R35: 41469.8 | S35: SHSIN6010122 | T35: CSLU6002087 / 40'HQ SEAL NO: CW842373 HAVE CHINA CO | U35: I 21065 | V35: 46062
A36: 46061 | B36: 46063 | I36: 02-2026 | J36: III. ACCESSORY | K36: WOVEN TAPE | L36: =VLOOKUP(K36,CDC!$B$6:$O$203,14,FALSE) -> III-152 | M36: 2977 | N36: MTR | O36: 94.3 | P36: 99.8 | Q36: 0.02 | R36: 59.54 | U36: I 21065 | V36: 46062
A37: 46070 | B37: 46076 | C37: FWF GRATEFUL | D37: HANGZHOU | E37: CNQ26006 | F37: 46059 | G37: 843 | H37: CH-SHV | I37: 02-2026 | J37: II. RAW MATERIAL | K37: KNITTED FABRIC | L37: =VLOOKUP(K37,CDC!$B$6:$O$203,14,FALSE) -> II-125 | M37: 39717.9 | N37: MTR | O37: 23936 | P37: 24105 | Q37: 1 | R37: 39717.9 | S37: SHSIN6020045 | T37: CSGU6893215 / 40'HQ SEAL NO: CU422890 HAVE CHINA CO | U37: I 27779 | V37: 46076
A39: 46083 | B39: 46084 | C39: FWF GRATEFUL | D39: SHANGHAI YOUNGYUE | E39: CNQ126007 | F39: 46064 | G39: 369 | H39: CH-SHV | I39: 03-2026 | J39: II. RAW MATERIAL | K39: KNITTED FABRIC | L39: =VLOOKUP(K39,CDC!$B$6:$O$203,14,FALSE) -> II-125 | M39: 29217.8 | N39: MTR | O39: 8594.9 | P39: 86999.9 | Q39: 1 | R39: =ROUND(M39*Q39,2) -> 29217.8 | S39: SHSIN6020168 | T39: OOCU1196250 (20'GP) Delayed 1d (01-March - 02-March) unavailable for berthing | U39: I 32429 | V39: 46083
A40: 46083 | B40: 46084 | H40: CH-SHV | I40: 03-2026 | J40: II. RAW MATERIAL | K40: WOVEN FABRIC | L40: =VLOOKUP(K40,CDC!$B$6:$O$203,14,FALSE) -> II-124 | M40: 282.5 | N40: MTR | O40: 97.9 | P40: 99.1 | Q40: 1.8 | R40: =ROUND(M40*Q40,2) -> 508.5 | U40: I 32429 | V40: 46083
A41: 46083 | B41: 46084 | H41: CH-SHV | I41: 03-2026 | J41: II. RAW MATERIAL | K41: WOVEN TAPE | L41: =VLOOKUP(K41,CDC!$B$6:$O$203,14,FALSE) -> III-152 | M41: 4013 | N41: MTR | O41: 110.4 | P41: 114.4 | Q41: 0.02 | R41: =ROUND(M41*Q41,2) -> 80.26 | U41: I 32429 | V41: 46083
A42: 46083 | B42: 46084 | H42: CH-SHV | I42: 03-2026 | J42: II. RAW MATERIAL | K42: HANGER | L42: =VLOOKUP(K42,CDC!$B$6:$O$203,14,FALSE) -> III-182 | M42: 234 | N42: DZN | O42: 161.1 | P42: 173.4 | Q42: 1 | R42: =ROUND(M42*Q42,2) -> 234 | U42: I 32429 | V42: 46083
A43: 46083 | B43: 46084 | C43: FWF GRATEFUL | D43: SHANGHAI YOUNGYUE | E43: CNQ126008 | F43: 46064 | G43: 1000 | H43: CH-SHV | I43: 03-2026 | J43: II. RAW MATERIAL | K43: WOVEN FABRIC | L43: =VLOOKUP(K43,CDC!$B$6:$O$203,14,FALSE) -> II-124 | M43: 13511.9 | N43: MTR | O43: 2147.8 | P43: 2198.7 | Q43: 1.8 | R43: 24321.42 | S43: SHSIN6020169 | T43: TRHU52554521 (40'HQ) Delayed 1d (01-March - 02-March) unavailable for berthing. Standby (one night) $70 + Trucking Fee (6A FTY to JR FTY) $150 | U43: I 32408 | V43: 46083
...

Sheet CDC
I4: IMPORTED
A5: I. MACHINERIES & EQUIPMENTS | C5: New/ Used | D5: Unit | E5: Quantity | F5: Unit Price USD | G5: Total Price USD | H5: Remarks | I5: Q'TY | J5: PRICE | K5: N.W | L5: BALANCE | M5: <50% | N5: Condition | O5: Declare
A6: 1 | B6: METAL DETECTOR MACHINE | C6: New | D6: SET | E6: 3 | F6: 4500 | G6: =F6*E6 -> 13500 | H6: N/A | I6: =SUMIFS(IMPORT!$M$2:$M$94,IMPORT!$K$2:$K$94,CDC!B6) -> 1 | J6: =SUMIFS(IMPORT!$R$2:$R$94,IMPORT!$K$2:$K$94,CDC!B6) -> 4500 | K6: =SUMIFS(IMPORT!$O$2:$O$94,IMPORT!$K$2:$K$94,CDC!B6) -> 1014.6 | L6: =E6-I6 -> 2 | M6: =L6/E6 -> 0.66666667 | N6: =IF(M6<50%,"CHECK","OK") -> OK | O6: I-1 | P6: FABRIC INSPECTION MACHINE | Q6: =VLOOKUP(P6,$B$6:$O$203,3,FALSE) -> SET
A7: =A6+1 -> 2 | B7: HANDHELD SCANNER | C7: New | D7: SET | E7: 8 | F7: 130 | G7: =F7*E7 -> 1040 | H7: N/A | I7: =SUMIFS(IMPORT!$M$2:$M$94,IMPORT!$K$2:$K$94,CDC!B7) -> 2 | J7: =SUMIFS(IMPORT!$R$2:$R$94,IMPORT!$K$2:$K$94,CDC!B7) -> 260 | K7: =SUMIFS(IMPORT!$O$2:$O$94,IMPORT!$K$2:$K$94,CDC!B7) -> 197 | L7: =E7-I7 -> 6 | M7: =L7/E7 -> 0.75 | N7: =IF(M7<50%,"CHECK","OK") -> OK | O7: I-2 | P7: Fabric relaxing machine | Q7: =VLOOKUP(P7,$B$6:$O$203,3,FALSE) -> SET
A8: =A7+1 -> 3 | B8: FABRIC INSPECTION MACHINE | C8: New | D8: SET | E8: 3 | F8: 5500 | G8: =F8*E8 -> 16500 | H8: N/A | I8: =SUMIFS(IMPORT!$M$2:$M$94,IMPORT!$K$2:$K$94,CDC!B8) -> 2 | J8: =SUMIFS(IMPORT!$R$2:$R$94,IMPORT!$K$2:$K$94,CDC!B8) -> 11000 | K8: =SUMIFS(IMPORT!$O$2:$O$94,IMPORT!$K$2:$K$94,CDC!B8) -> 1660 | L8: =E8-I8 -> 1 | M8: =L8/E8 -> 0.33333333 | N8: =IF(M8<50%,"CHECK","OK") -> CHECK | O8: I-3 | P8: FUSING MACHINE | Q8: =VLOOKUP(P8,$B$6:$O$203,3,FALSE) -> SET
A9: =A8+1 -> 4 | B9: ELECTRONIC SCALE-30KG | C9: New | D9: SET | E9: 10 | F9: 50 | G9: =F9*E9 -> 500 | H9: N/A | I9: =SUMIFS(IMPORT!$M$2:$M$94,IMPORT!$K$2:$K$94,CDC!B9) -> 0 | J9: =SUMIFS(IMPORT!$R$2:$R$94,IMPORT!$K$2:$K$94,CDC!B9) -> 0 | K9: =SUMIFS(IMPORT!$O$2:$O$94,IMPORT!$K$2:$K$94,CDC!B9) -> 0 | L9: =E9-I9 -> 10 | M9: =L9/E9 -> 1 | N9: =IF(M9<50%,"CHECK","OK") -> OK | O9: I-4 | P9: IRON TABLE | Q9: =VLOOKUP(P9,$B$6:$O$203,3,FALSE) -> SET
A10: =A9+1 -> 5 | B10: GRAM SCALE-500G | C10: New | D10: SET | E10: 5 | F10: 50 | G10: =F10*E10 -> 250 | H10: N/A | I10: =SUMIFS(IMPORT!$M$2:$M$94,IMPORT!$K$2:$K$94,CDC!B10) -> 0 | J10: =SUMIFS(IMPORT!$R$2:$R$94,IMPORT!$K$2:$K$94,CDC!B10) -> 0 | K10: =SUMIFS(IMPORT!$O$2:$O$94,IMPORT!$K$2:$K$94,CDC!B10) -> 0 | L10: =E10-I10 -> 5 | M10: =L10/E10 -> 1 | N10: =IF(M10<50%,"CHECK","OK") -> OK | O10: I-5
A11: =A10+1 -> 6 | B11: HANGING SYSTEM | C11: New | D11: SET | E11: 8 | F11: 35000 | G11: =F11*E11 -> 280000 | H11: N/A | I11: =SUMIFS(IMPORT!$M$2:$M$94,IMPORT!$K$2:$K$94,CDC!B11) -> 0 | J11: =SUMIFS(IMPORT!$R$2:$R$94,IMPORT!$K$2:$K$94,CDC!B11) -> 0 | K11: =SUMIFS(IMPORT!$O$2:$O$94,IMPORT!$K$2:$K$94,CDC!B11) -> 0 | L11: =E11-I11 -> 8 | M11: =L11/E11 -> 1 | N11: =IF(M11<50%,"CHECK","OK") -> OK | O11: I-6
A12: =A11+1 -> 7 | B12: ONE NEEDLE SEWING MACHINE | C12: New | D12: SET | E12: 300 | F12: 320 | G12: =F12*E12 -> 96000 | H12: N/A | I12: =SUMIFS(IMPORT!$M$2:$M$94,IMPORT!$K$2:$K$94,CDC!B12) -> 64 | J12: =SUMIFS(IMPORT!$R$2:$R$94,IMPORT!$K$2:$K$94,CDC!B12) -> 20480 | K12: =SUMIFS(IMPORT!$O$2:$O$94,IMPORT!$K$2:$K$94,CDC!B12) -> 4268 | L12: =E12-I12 -> 236 | M12: =L12/E12 -> 0.78666667 | N12: =IF(M12<50%,"CHECK","OK") -> OK | O12: I-7
A13: =A12+1 -> 8 | B13: TWO NEEDLE SEWING MACHINE | C13: New | D13: SET | E13: 50 | F13: 1500 | G13: =F13*E13 -> 75000 | H13: N/A | I13: =SUMIFS(IMPORT!$M$2:$M$94,IMPORT!$K$2:$K$94,CDC!B13) -> 2 | J13: =SUMIFS(IMPORT!$R$2:$R$94,IMPORT!$K$2:$K$94,CDC!B13) -> 3000 | K13: =SUMIFS(IMPORT!$O$2:$O$94,IMPORT!$K$2:$K$94,CDC!B13) -> 138 | L13: =E13-I13 -> 48 | M13: =L13/E13 -> 0.96 | N13: =IF(M13<50%,"CHECK","OK") -> OK | O13: I-8
A14: =A13+1 -> 9 | B14: THREE NEEDLE FIVE THREAD SEWING MACHINE | C14: New | D14: SET | E14: 50 | F14: 1500 | G14: =F14*E14 -> 75000 | H14: N/A | I14: =SUMIFS(IMPORT!$M$2:$M$94,IMPORT!$K$2:$K$94,CDC!B14) -> 0 | J14: =SUMIFS(IMPORT!$R$2:$R$94,IMPORT!$K$2:$K$94,CDC!B14) -> 0 | K14: =SUMIFS(IMPORT!$O$2:$O$94,IMPORT!$K$2:$K$94,CDC!B14) -> 0 | L14: =E14-I14 -> 50 | M14: =L14/E14 -> 1 | N14: =IF(M14<50%,"CHECK","OK") -> OK | O14: I-9
A15: =A14+1 -> 10 | B15: FOUR NEEDLE SIX THREAD SEWING MACHINE | C15: New | D15: SET | E15: 40 | F15: 3000 | G15: =F15*E15 -> 120000 | H15: N/A | I15: =SUMIFS(IMPORT!$M$2:$M$94,IMPORT!$K$2:$K$94,CDC!B15) -> 2 | J15: =SUMIFS(IMPORT!$R$2:$R$94,IMPORT!$K$2:$K$94,CDC!B15) -> 6000 | K15: =SUMIFS(IMPORT!$O$2:$O$94,IMPORT!$K$2:$K$94,CDC!B15) -> 380 | L15: =E15-I15 -> 38 | M15: =L15/E15 -> 0.95 | N15: =IF(M15<50%,"CHECK","OK") -> OK | O15: I-10
A16: =A15+1 -> 11 | B16: FOUR THREAD OVERLOCK SEWING MACHINE | C16: New | D16: SET | E16: 300 | F16: 500 | G16: =F16*E16 -> 150000 | H16: N/A | I16: =SUMIFS(IMPORT!$M$2:$M$94,IMPORT!$K$2:$K$94,CDC!B16) -> 24 | J16: =SUMIFS(IMPORT!$R$2:$R$94,IMPORT!$K$2:$K$94,CDC!B16) -> 12000 | K16: =SUMIFS(IMPORT!$O$2:$O$94,IMPORT!$K$2:$K$94,CDC!B16) -> 1540 | L16: =E16-I16 -> 276 | M16: =L16/E16 -> 0.92 | N16: =IF(M16<50%,"CHECK","OK") -> OK | O16: I-11
A17: =A16+1 -> 12 | B17: FIVE THREAD OVERLOCK SEWING MACHINE | C17: New | D17: SET | E17: 50 | F17: 550 | G17: =F17*E17 -> 27500 | H17: N/A | I17: =SUMIFS(IMPORT!$M$2:$M$94,IMPORT!$K$2:$K$94,CDC!B17) -> 46 | J17: =SUMIFS(IMPORT!$R$2:$R$94,IMPORT!$K$2:$K$94,CDC!B17) -> 25300 | K17: =SUMIFS(IMPORT!$O$2:$O$94,IMPORT!$K$2:$K$94,CDC!B17) -> 3082 | L17: =E17-I17 -> 4 | M17: =L17/E17 -> 0.08 | N17: =IF(M17<50%,"CHECK","OK") -> CHECK | O17: I-12
A18: =A17+1 -> 13 | B18: COVER STITCHING MACHINE | C18: New | D18: SET | E18: 30 | F18: 600 | G18: =F18*E18 -> 18000 | H18: N/A | I18: =SUMIFS(IMPORT!$M$2:$M$94,IMPORT!$K$2:$K$94,CDC!B18) -> 0 | J18: =SUMIFS(IMPORT!$R$2:$R$94,IMPORT!$K$2:$K$94,CDC!B18) -> 0 | K18: =SUMIFS(IMPORT!$O$2:$O$94,IMPORT!$K$2:$K$94,CDC!B18) -> 0 | L18: =E18-I18 -> 30 | M18: =L18/E18 -> 1 | N18: =IF(M18<50%,"CHECK","OK") -> OK | O18: I-13
A19: =A18+1 -> 14 | B19: SEWING MACHINE | C19: New | D19: SET | E19: 100 | F19: 1000 | G19: =F19*E19 -> 100000 | H19: N/A | I19: =SUMIFS(IMPORT!$M$2:$M$94,IMPORT!$K$2:$K$94,CDC!B19) -> 7 | J19: =SUMIFS(IMPORT!$R$2:$R$94,IMPORT!$K$2:$K$94,CDC!B19) -> 7000 | K19: =SUMIFS(IMPORT!$O$2:$O$94,IMPORT!$K$2:$K$94,CDC!B19) -> 553 | L19: =E19-I19 -> 93 | M19: =L19/E19 -> 0.93 | N19: =IF(M19<50%,"CHECK","OK") -> OK | O19: I-14
A20: =A19+1 -> 15 | B20: LONG ARM SEWING MACHINE | C20: New | D20: SET | E20: 10 | F20: 800 | G20: =F20*E20 -> 8000 | H20: N/A | I20: =SUMIFS(IMPORT!$M$2:$M$94,IMPORT!$K$2:$K$94,CDC!B20) -> 0 | J20: =SUMIFS(IMPORT!$R$2:$R$94,IMPORT!$K$2:$K$94,CDC!B20) -> 0 | K20: =SUMIFS(IMPORT!$O$2:$O$94,IMPORT!$K$2:$K$94,CDC!B20) -> 0 | L20: =E20-I20 -> 10 | M20: =L20/E20 -> 1 | N20: =IF(M20<50%,"CHECK","OK") -> OK | O20: I-15
A21: =A20+1 -> 16 | B21: BARTACKING MACHINE | C21: New | D21: SET | E21: 20 | F21: 1200 | G21: =F21*E21 -> 24000 | H21: N/A | I21: =SUMIFS(IMPORT!$M$2:$M$94,IMPORT!$K$2:$K$94,CDC!B21) -> 10 | J21: =SUMIFS(IMPORT!$R$2:$R$94,IMPORT!$K$2:$K$94,CDC!B21) -> 12000 | K21: =SUMIFS(IMPORT!$O$2:$O$94,IMPORT!$K$2:$K$94,CDC!B21) -> 820 | L21: =E21-I21 -> 10 | M21: =L21/E21 -> 0.5 | N21: =IF(M21<50%,"CHECK","OK") -> OK | O21: I-16
... A78: =A77+1 -> 73 | B78: DEHUMIDIFIER MACHINE | C78: New | D78: SET | E78: 5 | F78: 3500 | G78: =F78*E78 -> 17500 | H78: N/A | I78: =SUMIFS(IMPORT!$M$2:$M$94,IMPORT!$K$2:$K$94,CDC!B78) -> 0 | J78: =SUMIFS(IMPORT!$R$2:$R$94,IMPORT!$K$2:$K$94,CDC!B78) -> 0 | K78: =SUMIFS(IMPORT!$O$2:$O$94,IMPORT!$K$2:$K$94,CDC!B78) -> 0 | L78: =E78-I78 -> 5 | M78: =L78/E78 -> 1 | N78: =IF(M78<50%,"CHECK","OK") -> OK | O78: I-73
A79: =A78+1 -> 74 | B79: LAMP (USE IN WORKSHOP) | C79: New | D79: SET | E79: 0 | F79: 10 | G79: =F79*E79 -> 0 | H79: N/A | I79: =SUMIFS(IMPORT!$M$2:$M$94,IMPORT!$K$2:$K$94,CDC!B79) -> 0 | J79: =SUMIFS(IMPORT!$R$2:$R$94,IMPORT!$K$2:$K$94,CDC!B79) -> 0 | K79: =SUMIFS(IMPORT!$O$2:$O$94,IMPORT!$K$2:$K$94,CDC!B79) -> 0 | L79: =E79-I79 -> 0 | M79: 0 | N79: =IF(M79<50%,"CHECK","OK") -> CHECK | O79: I-74
A80: =A79+1 -> 75 | B80: EXPLOSION-PROOF LAMP | C80: New | D80: SET | E80: 0 | F80: 35 | G80: =F80*E80 -> 0 | H80: N/A | I80: =SUMIFS(IMPORT!$M$2:$M$94,IMPORT!$K$2:$K$94,CDC!B80) -> 0 | J80: =SUMIFS(IMPORT!$R$2:$R$94,IMPORT!$K$2:$K$94,CDC!B80) -> 0 | K80: =SUMIFS(IMPORT!$O$2:$O$94,IMPORT!$K$2:$K$94,CDC!B80) -> 0 | L80: =E80-I80 -> 0 | M80: 0 | N80: =IF(M80<50%,"CHECK","OK") -> CHECK | O80: I-75
A81: =A80+1 -> 76 | B81: ELECTRIC WIRE (10-25MM) * 100M/ROLL | C81: New | D81: NRL | E81: 0 | F81: 180 | G81: =F81*E81 -> 0 | H81: N/A | I81: =SUMIFS(IMPORT!$M$2:$M$94,IMPORT!$K$2:$K$94,CDC!B81) -> 0 | J81: =SUMIFS(IMPORT!$R$2:$R$94,IMPORT!$K$2:$K$94,CDC!B81) -> 0 | K81: =SUMIFS(IMPORT!$O$2:$O$94,IMPORT!$K$2:$K$94,CDC!B81) -> 0 | L81: =E81-I81 -> 0 | M81: 0 | N81: =IF(M81<50%,"CHECK","OK") -> CHECK | O81: I-76
A82: =A81+1 -> 77 | B82: ELECTRIC WIRE (1.5-6MM) * 100M / ROLL | C82: New | D82: NRL | E82: 0 | F82: 60 | G82: =F82*E82 -> 0 | H82: N/A | I82: =SUMIFS(IMPORT!$M$2:$M$94,IMPORT!$K$2:$K$94,CDC!B82) -> 0 | J82: =SUMIFS(IMPORT!$R$2:$R$94,IMPORT!$K$2:$K$94,CDC!B82) -> 0 | K82: =SUMIFS(IMPORT!$O$2:$O$94,IMPORT!$K$2:$K$94,CDC!B82) -> 0 | L82: =E82-I82 -> 0 | M82: 0 | N82: =IF(M82<50%,"CHECK","OK") -> CHECK | O82: I-77
A83: =A82+1 -> 78 | B83: CABLE (30 - 70MM) | C83: New | D83: MTR | E83: 0 | F83: 20 | G83: =F83*E83 -> 0 | H83: N/A | I83: =SUMIFS(IMPORT!$M$2:$M$94,IMPORT!$K$2:$K$94,CDC!B83) -> 0 | J83: =SUMIFS(IMPORT!$R$2:$R$94,IMPORT!$K$2:$K$94,CDC!B83) -> 0 | K83: =SUMIFS(IMPORT!$O$2:$O$94,IMPORT!$K$2:$K$94,CDC!B83) -> 0 | L83: =E83-I83 -> 0 | M83: 0 | N83: =IF(M83<50%,"CHECK","OK") -> CHECK | O83: I-78
A84: =A83+1 -> 79 | B84: CABLE (120-300MM) | C84: New | D84: MTR | E84: 0 | F84: 65 | G84: =F84*E84 -> 0 | H84: N/A | I84: =SUMIFS(IMPORT!$M$2:$M$94,IMPORT!$K$2:$K$94,CDC!B84) -> 0 | J84: =SUMIFS(IMPORT!$R$2:$R$94,IMPORT!$K$2:$K$94,CDC!B84) -> 0 | K84: =SUMIFS(IMPORT!$O$2:$O$94,IMPORT!$K$2:$K$94,CDC!B84) -> 0 | L84: =E84-I84 -> 0 | M84: 0 | N84: =IF(M84<50%,"CHECK","OK") -> CHECK | O84: I-79
A85: =A84+1 -> 80 | B85: BREAKERS | C85: New | D85: SET | E85: 0 | F85: 3 | G85: =F85*E85 -> 0 | H85: N/A | I85: =SUMIFS(IMPORT!$M$2:$M$94,IMPORT!$K$2:$K$94,CDC!B85) -> 0 | J85: =SUMIFS(IMPORT!$R$2:$R$94,IMPORT!$K$2:$K$94,CDC!B85) -> 0 | K85: =SUMIFS(IMPORT!$O$2:$O$94,IMPORT!$K$2:$K$94,CDC!B85) -> 0 | L85: =E85-I85 -> 0 | M85: 0 | N85: =IF(M85<50%,"CHECK","OK") -> CHECK | O85: I-80
A86: =A85+1 -> 81 | B86: FAN | C86: New | D86: SET | E86: 0 | F86: 200 | G86: =F86*E86 -> 0 | H86: N/A | I86: =SUMIFS(IMPORT!$M$2:$M$94,IMPORT!$K$2:$K$94,CDC!B86) -> 0 | J86: =SUMIFS(IMPORT!$R$2:$R$94,IMPORT!$K$2:$K$94,CDC!B86) -> 0 | K86: =SUMIFS(IMPORT!$O$2:$O$94,IMPORT!$K$2:$K$94,CDC!B86) -> 0 | L86: =E86-I86 -> 0 | M86: 0 | N86: =IF(M86<50%,"CHECK","OK") -> CHECK | O86: I-81
A87: =A86+1 -> 82 | B87: WATER DRINKING MACHINE | C87: New | D87: SET | E87: 10 | F87: 800 | G87: =F87*E87 -> 8000 | H87: N/A | I87: =SUMIFS(IMPORT!$M$2:$M$94,IMPORT!$K$2:$K$94,CDC!B87) -> 0 | J87: =SUMIFS(IMPORT!$R$2:$R$94,IMPORT!$K$2:$K$94,CDC!B87) -> 0 | K87: =SUMIFS(IMPORT!$O$2:$O$94,IMPORT!$K$2:$K$94,CDC!B87) -> 0 | L87: =E87-I87 -> 10 | M87: =L87/E87 -> 1 | N87: =IF(M87<50%,"CHECK","OK") -> OK | O87: I-82
A88: =A87+1 -> 83 | B88: WATER SOFTENER SYSTEM (RO) | C88: New | D88: SET | E88: 5 | F88: 8000 | G88: =F88*E88 -> 40000 | H88: N/A | I88: =SUMIFS(IMPORT!$M$2:$M$94,IMPORT!$K$2:$K$94,CDC!B88) -> 0 | J88: =SUMIFS(IMPORT!$R$2:$R$94,IMPORT!$K$2:$K$94,CDC!B88) -> 0 | K88: =SUMIFS(IMPORT!$O$2:$O$94,IMPORT!$K$2:$K$94,CDC!B88) -> 0 | L88: =E88-I88 -> 5 | M88: =L88/E88 -> 1 | N88: =IF(M88<50%,"CHECK","OK") -> OK | O88: I-83
A89: =A88+1 -> 84 | B89: BARCODE PRINTER | C89: New | D89: SET | E89: 10 | F89: 1400 | G89: =F89*E89 -> 14000 | H89: N/A | I89: =SUMIFS(IMPORT!$M$2:$M$94,IMPORT!$K$2:$K$94,CDC!B89) -> 0 | J89: =SUMIFS(IMPORT!$R$2:$R$94,IMPORT!$K$2:$K$94,CDC!B89) -> 0 | K89: =SUMIFS(IMPORT!$O$2:$O$94,IMPORT!$K$2:$K$94,CDC!B89) -> 0 | L89: =E89-I89 -> 10 | M89: =L89/E89 -> 1 | N89: =IF(M89<50%,"CHECK","OK") -> OK | O89: I-84
A90: =A89+1 -> 85 | B90: INFRARED THERMOMETER | C90: New | D90: SET | E90: 10 | F90: 300 | G90: =F90*E90 -> 3000 | H90: N/A | I90: =SUMIFS(IMPORT!$M$2:$M$94,IMPORT!$K$2:$K$94,CDC!B90) -> 0 | J90: =SUMIFS(IMPORT!$R$2:$R$94,IMPORT!$K$2:$K$94,CDC!B90) -> 0 | K90: =SUMIFS(IMPORT!$O$2:$O$94,IMPORT!$K$2:$K$94,CDC!B90) -> 0 | L90: =E90-I90 -> 10 | M90: =L90/E90 -> 1 | N90: =IF(M90<50%,"CHECK","OK") -> OK | O90: I-85
A91: =A90+1 -> 86 | B91: TEMPERATURE MEASURING DEVICE | C91: New | D91: SET | E91: 35 | F91: 60 | G91: =F91*E91 -> 2100 | H91: N/A | I91: =SUMIFS(IMPORT!$M$2:$M$94,IMPORT!$K$2:$K$94,CDC!B91) -> 2 | J91: =SUMIFS(IMPORT!$R$2:$R$94,IMPORT!$K$2:$K$94,CDC!B91) -> 120 | K91: =SUMIFS(IMPORT!$O$2:$O$94,IMPORT!$K$2:$K$94,CDC!B91) -> 1 | L91: =E91-I91 -> 33 | M91: =L91/E91 -> 0.94285714 | N91: =IF(M91<50%,"CHECK","OK") -> OK | O91: I-86
A92: =A91+1 -> 87 | B92: PUSH BAR | C92: New | D92: SET | E92: 0 | F92: 50 | G92: =F92*E92 -> 0 | H92: N/A | I92: =SUMIFS(IMPORT!$M$2:$M$94,IMPORT!$K$2:$K$94,CDC!B92) -> 0 | J92: =SUMIFS(IMPORT!$R$2:$R$94,IMPORT!$K$2:$K$94,CDC!B92) -> 0 | K92: =SUMIFS(IMPORT!$O$2:$O$94,IMPORT!$K$2:$K$94,CDC!B92) -> 0 | L92: =E92-I92 -> 0 | M92: 0 | N92: =IF(M92<50%,"CHECK","OK") -> CHECK | O92: I-87
A93: =A92+1 -> 88 | B93: PUSH BAR LOCK | C93: New | D93: SET | E93: 0 | F93: 40 | G93: =F93*E93 -> 0 | H93: N/A | I93: =SUMIFS(IMPORT!$M$2:$M$94,IMPORT!$K$2:$K$94,CDC!B93) -> 0 | J93: =SUMIFS(IMPORT!$R$2:$R$94,IMPORT!$K$2:$K$94,CDC!B93) -> 0 | K93: =SUMIFS(IMPORT!$O$2:$O$94,IMPORT!$K$2:$K$94,CDC!B93) -> 0 | L93: =E93-I93 -> 0 | M93: 0 | N93: =IF(M93<50%,"CHECK","OK") -> CHECK | O93: I-88
A94: =A93+1 -> 89 | B94: DOOR CLOSURE | C94: New | D94: SET | E94: 0 | F94: 15 | G94: =F94*E94 -> 0 | H94: N/A | I94: =SUMIFS(IMPORT!$M$2:$M$94,IMPORT!$K$2:$K$94,CDC!B94) -> 0 | J94: =SUMIFS(IMPORT!$R$2:$R$94,IMPORT!$K$2:$K$94,CDC!B94) -> 0 | K94: =SUMIFS(IMPORT!$O$2:$O$94,IMPORT!$K$2:$K$94,CDC!B94) -> 0 | L94: =E94-I94 -> 0 | M94: 0 | N94: =IF(M94<50%,"CHECK","OK") -> CHECK | O94: I-89
A95: =A94+1 -> 90 | B95: MOSQUITO KILLER TUBE | C95: New | D95: SET | E95: 70 | F95: 3 | G95: =F95*E95 -> 210 | H95: N/A | I95: =SUMIFS(IMPORT!$M$2:$M$94,IMPORT!$K$2:$K$94,CDC!B95) -> 0 | J95: =SUMIFS(IMPORT!$R$2:$R$94,IMPORT!$K$2:$K$94,CDC!B95) -> 0 | K95: =SUMIFS(IMPORT!$O$2:$O$94,IMPORT!$K$2:$K$94,CDC!B95) -> 0 | L95: =E95-I95 -> 70 | M95: =L95/E95 -> 1 | N95: =IF(M95<50%,"CHECK","OK") -> OK | O95: I-90
A96: =A95+1 -> 91 | B96: MOSQUITO KILLER LAMP STARTER | C96: New | D96: SET | E96: 50 | F96: 1 | G96: =F96*E96 -> 50 | H96: N/A | I96: =SUMIFS(IMPORT!$M$2:$M$94,IMPORT!$K$2:$K$94,CDC!B96) -> 0 | J96: =SUMIFS(IMPORT!$R$2:$R$94,IMPORT!$K$2:$K$94,CDC!B96) -> 0 | K96: =SUMIFS(IMPORT!$O$2:$O$94,IMPORT!$K$2:$K$94,CDC!B96) -> 0 | L96: =E96-I96 -> 50 | M96: =L96/E96 -> 1 | N96: =IF(M96<50%,"CHECK","OK") -> OK | O96: I-91
A97: =A96+1 -> 92 | B97: FAUCET | C97: New | D97: SET | E97: 0 | F97: 5 | G97: =F97*E97 -> 0 | H97: N/A | I97: =SUMIFS(IMPORT!$M$2:$M$94,IMPORT!$K$2:$K$94,CDC!B97) -> 0 | J97: =SUMIFS(IMPORT!$R$2:$R$94,IMPORT!$K$2:$K$94,CDC!B97) -> 0 | K97: =SUMIFS(IMPORT!$O$2:$O$94,IMPORT!$K$2:$K$94,CDC!B97) -> 0 | L97: =E97-I97 -> 0 | M97: 0 | N97: =IF(M97<50%,"CHECK","OK") -> CHECK | O97: I-92
A98: =A97+1 -> 93 | B98: ELECTRICAL TAPE | C98: New | D98: SET | E98: 0 | F98: 0.5 | G98: =F98*E98 -> 0 | H98: N/A | I98: =SUMIFS(IMPORT!$M$2:$M$94,IMPORT!$K$2:$K$94,CDC!B98) -> 0 | J98: =SUMIFS(IMPORT!$R$2:$R$94,IMPORT!$K$2:$K$94,CDC!B98) -> 0 | K98: =SUMIFS(IMPORT!$O$2:$O$94,IMPORT!$K$2:$K$94,CDC!B98) -> 0 | L98: =E98-I98 -> 0 | M98: 0 | N98: =IF(M98<50%,"CHECK","OK") -> CHECK | O98: I-93
A99: =A98+1 -> 94 | B99: CABLE TIE | C99: New | D99: SET | E99: 0 | F99: 1 | G99: =F99*E99 -> 0 | H99: N/A | I99: =SUMIFS(IMPORT!$M$2:$M$94,IMPORT!$K$2:$K$94,CDC!B99) -> 0 | J99: =SUMIFS(IMPORT!$R$2:$R$94,IMPORT!$K$2:$K$94,CDC!B99) -> 0 | K99: =SUMIFS(IMPORT!$O$2:$O$94,IMPORT!$K$2:$K$94,CDC!B99) -> 0 | L99: =E99-I99 -> 0 | M99: 0 | N99: =IF(M99<50%,"CHECK","OK") -> CHECK | O99: I-94
...
