Workbook

Sheet 1-JAN
B1: ព្រះរាជាណាចក្រកម្ពុជា
B2: ជាត​ សានា ព្រះមហាក្សត្រ
G3: 
B4: របាយការណ៍ជូនក្រសួងឧស្សាហកម្ម វិទ្យាសាស្ត្រ បច្ចេកវិទ្យា និងនវានុវត្តន៍
B5: Report for Ministry of Industry, Science, Technology & Innovation
G6: ទិន្នន័យប្រចាំខែ | I6: មករា | J6: ឆ្នាំ 2026
G7: Monthly Data In ........... 202…
A9: ឈ្មោះរោងចក្រ:​​​​​​​​​​ ជេអ អឹភែរឹល ឯ.ក អាស័យដ្ឋានរោងចក្រៈ # ផ្លូវលំ ភូមិ កោះខ្នុរ ឃុំ ព្រែករកា ស្រុក កណ្ដាលស្ទឹង ខេត្ត កណ្ដាល ប្រកាសលេខៈ៤១៧ ឧស.កឧ.ប្រក១២ ចុះថ្ងៃទី ២៤​​ ខែ ធ្នូ ឆ្នាំ ២០១៨
A10: Name of Factory: JR APPAREL CO., LTD Factory Address: #LOM ROAD,KAOH KNOR PREAEK ROKA KANDAL STUENG​ KANDAL PROVINCE Prakas Number : 417
A11: ឈ្មោះអ្នកគ្រប់គ្រងរោងចក្រ NI, CUNLAN ទូរស័ព្ទៈ 855-85 441 621 ទូរសារ:.............................. អ៊ីម៉ែលៈ sanashipping8@gmail.com
A12: Manager Name: NI, CUNLAN Tel: 855-85 441 621 Fax:……………………… E-mail: sanashipping8@gmail.com
A13: ចំនួនពលកម្មសរុបៈ​​​ | C13: 168 | E13: ក្នុងនោះមានស្រីៈ | F13: 111 | H13: បៀរវត្សសរុបប្រចាំខែៈ | J13: 45784.38 | L13: USD
A14: Total Number of Employees: Persons Number of Females: Persons Total Salary & Wage of Monthly USD
A15: ទុនសរុបមិនគិតដីធ្លី Total Asset(Land exclude) | D15: 1000000 | F15: ទុនអចលនទ្រព្យមិនគិតដីធ្លី Total Fixed Asset (Land exclude) | J15: 1000000
A16: មុខផលិតផល Products | C16: ឯកតាUnit | D16: បរិមាណ និងតម្លៃផលិតផល Total Output
D17: ឆ្នាំមុន (Data Last Year) | H17: ទិន្នន័យប្រចាំខែ (Monthly Data) | L17: សរុបពីដើមឆ្នាំ (From beginning of the Year )
D18: ​ បរិមាណ Quantity | F18: តម្លៃ Value(USD) | H18: បរិមាណផលិតផល Product Quantity | J18: តម្លៃផលិតផល Product Value(USD) | L18: បរិមាណផលិតផល Product Quantity | N18: តម្លៃផលិតផល Product Value(USD)
D19: ក្នុងស្រុក Domestic | E19: នាំចេញ Export | F19: ក្នុងស្រុក Domestic | G19: នាំចេញ Export | H19: ក្នុងស្រុក Domestic | I19: នាំចេញ Export | J19: ក្នុងស្រុក Domestic | K19: នាំចេញ Export | L19: ក្នុងស្រុក Domestic | M19: នាំចេញ Export | N19: ក្នុងស្រុក Domestic | O19: នាំចេញ Export
A20: LADIES | B20: PAJAMAS | C20: PCS | I20: 25768 | K20: 27190 | M20: =I20 -> 25768 | O20: =K20 -> 27190 | Q20: =M20+I20 -> 51536 | S20: =O20+K20 -> 54380
A21: LADIES | B21: PANTS | C21: PCS | I21: 60216 | K21: 53155.36 | M21: =I21 -> 60216 | O21: =K21 -> 53155.36 | Q21: =M21+I21 -> 120432 | S21: =O21+K21 -> 106310.72
A22: LADIES | B22: NIGHT GOWN | C22: PCS | I22: 2080 | K22: 155240 | M22: =I22 -> 2080 | O22: =K22 -> 155240 | Q22: =M22+I22 -> 4160 | S22: =O22+K22 -> 310480
A23: LADIES | B23: TANK | C23: PCS | O23: =K23 -> 0
A24: LADIES | B24: SKIRT | C24: PCS | O24: =K24 -> 0
A25: LADIES | B25: SHORT | C25: PCS | M25: 0 | O25: =K25 -> 0 | Q25: =M25+I25 -> 0 | S25: =O25+K25 -> 0
A26: LADIES | B26: DRESS | C26: PCS | M26: 0 | O26: =K26 -> 0 | Q26: =M26+I26 -> 0 | S26: =O26+K26 -> 0
A27: Total | E27: =SUM(E20:E26) -> 0 | G27: =SUM(G20:G26) -> 0 | I27: =SUM(I20:I26) -> 88064 | K27: =SUM(K20:K26) -> 235585.36 | M27: =SUM(M20:M26) -> 88064 | O27: =SUM(O20:O26) -> 235585.36
A28: សំគាល់ :​ ទិន្នន័យនៃរបាយការណ៍នេះត្រូវបានប្រើប្រាស់តែក្នុងគោលបំណង ស្ថិតិឧស្សាហកម្មតែប៉ុណ្ណោះ មិនត្រូវបានយកទៅចែកចាយដើម្បីប្រើប្រាស់
A29: ក្នុងគោលបំណងពាណិជ្ជកម្ម ឬក្នុងការគណនាបង់ពន្ធដារទេ។ | K29: ថ្ងៃទី 15 ខែ មករា ឆ្នាំ2026 | N29: =K29 -> ថ្ងៃទី 15 ខែ មករា ឆ្នាំ2026
A30: Remark: This report is used for industrial statistic only,​ not for commercial or tax purpose | J30: ​​​​​​​​​​​​​​​​​​​ | K30: Date:……./……../…… | N30: Date:……./……../……
A31: ទុនអចលនទ្រព្យមិនគិតដីធ្លី រួមមាន៖ អគារ និងឧបករណ៍បរិក្ខារដែលភ្ជាប់នឹងអគារ | K31: នាយក | N31: អ្នកធ្វើរបាយការណ៍
A32: Total asset excluding land comprises of : building & material attached.
A33: ទុនសរុបមិនគិតដីធ្លី រួមមាន៖ ទុនអចលនទ្រព្យមិនគិតដីធ្លី, មធ្យោបាយដឹកជញ្ជូន, គ្រឿងចក្រ-ម៉ាស៊ីន និងឧបករណ៍សម្ភារប្រើប្រាស់ក្នុងផលិតកម្ម, សង្ហារឹម និងសម្ភារការិយាល័យ | K33: Director | N33: Reportor
A34: Total fixed asset excluding land comprises of : real estate capital excluding land, transportation, machinery, and instrument utilised in the production line,
A35: furniture and office equiment.
A36: ទំនាក់ទំនង : Tel 077 330 279/090 922 237 E-mail : industryaffair.mih@gmail.com : TELEGRAM :077 330 279
K40: NI, CUNLAN | N40: THNIN
B41: ឈ្មោះរោងចក្រ ជេអ​ អឹភែរឹល ឯ.ក
A42: ទីផ្សារលក់ផលិតផលប្រចាំខែ | J42: =I6 -> មករា | K42: ឆ្នាំ២០២៦ (USD)
A43: ល.រ | B43: ឈ្មោះផលិតផល | D43: ឯកតា (Unit) | E43: ឈ្មោះប្រទេសនាំចេញផលិតផល | O43: សរុបពីដើមឆ្នាំ
E44: USA | G44: CANADA | I44: CHINA | K44: EU GROUP | M44: ផ្សេងៗ
...

Sheet 2-FEB
B1: ព្រះរាជាណាចក្រកម្ពុជា
B2: ជាត​ សានា ព្រះមហាក្សត្រ
G3: 
B4: របាយការណ៍ជូនក្រសួងឧស្សាហកម្ម វិទ្យាសាស្ត្រ បច្ចេកវិទ្យា និងនវានុវត្តន៍
B5: Report for Ministry of Industry, Science, Technology & Innovation
G6: ទិន្នន័យប្រចាំខែ | I6: កុម្ភៈ | J6: ឆ្នាំ 2026
G7: Monthly Data In ........... 202…
A9: ឈ្មោះរោងចក្រ:​​​​​​​​​​ ជេអ អឹភែរឹល ឯ.ក អាស័យដ្ឋានរោងចក្រៈ # ផ្លូវលំ ភូមិ កោះខ្នុរ ឃុំ ព្រែករកា ស្រុក កណ្ដាលស្ទឹង ខេត្ត កណ្ដាល ប្រកាសលេខៈ៤១៧ ឧស.កឧ.ប្រក១២ ចុះថ្ងៃទី ២៤​​ ខែ ធ្នូ ឆ្នាំ ២០១៨
A10: Name of Factory: JR APPAREL CO., LTD Factory Address: #LOM ROAD,KAOH KNOR PREAEK ROKA KANDAL STUENG​ KANDAL PROVINCE Prakas Number : 417
A11: ឈ្មោះអ្នកគ្រប់គ្រងរោងចក្រ NI, CUNLAN ទូរស័ព្ទៈ 855-85 441 621 ទូរសារ:.............................. អ៊ីម៉ែលៈ sanashipping8@gmail.com
A12: Manager Name: NI, CUNLAN Tel: 855-85 441 621 Fax:……………………… E-mail: sanashipping8@gmail.com
A13: ចំនួនពលកម្មសរុបៈ​​​ | C13: 175 | E13: ក្នុងនោះមានស្រីៈ | F13: 117 | H13: បៀរវត្សសរុបប្រចាំខែៈ | J13: 58602.51 | L13: USD
A14: Total Number of Employees: Persons Number of Females: Persons Total Salary & Wage of Monthly USD
A15: ទុនសរុបមិនគិតដីធ្លី Total Asset(Land exclude) | D15: 1000000 | F15: ទុនអចលនទ្រព្យមិនគិតដីធ្លី Total Fixed Asset (Land exclude) | J15: 1000000
A16: មុខផលិតផល Products | C16: ឯកតាUnit | D16: បរិមាណ និងតម្លៃផលិតផល Total Output
D17: ឆ្នាំមុន (Data Last Year) | H17: ទិន្នន័យប្រចាំខែ (Monthly Data) | L17: សរុបពីដើមឆ្នាំ (From beginning of the Year )
D18: ​ បរិមាណ Quantity | F18: តម្លៃ Value(USD) | H18: បរិមាណផលិតផល Product Quantity | J18: តម្លៃផលិតផល Product Value(USD) | L18: បរិមាណផលិតផល Product Quantity | N18: តម្លៃផលិតផល Product Value(USD)
D19: ក្នុងស្រុក Domestic | E19: នាំចេញ Export | F19: ក្នុងស្រុក Domestic | G19: នាំចេញ Export | H19: ក្នុងស្រុក Domestic | I19: នាំចេញ Export | J19: ក្នុងស្រុក Domestic | K19: នាំចេញ Export | L19: ក្នុងស្រុក Domestic | M19: នាំចេញ Export | N19: ក្នុងស្រុក Domestic | O19: នាំចេញ Export
A20: LADIES | B20: PANTS | C20: PCS | I20: 22549 | K20: =ROUND(I20*2.03594837908555,2) -> 45908.6 | M20: =I20+'1-JAN'!M21 -> 82765 | O20: ='2-FEB'!K20+'1-JAN'!O21 -> 99063.96 | Q20: =M20+I20 -> 105314 | S20: =O20+K20 -> 144972.56
A21: LADIES | B21: TANK | C21: PCS | I21: 3396 | K21: =ROUND(I21*0.669257950530035,2) -> 2272.8 | M21: =I21 -> 3396 | O21: =K21 -> 2272.8 | Q21: =M21+I21 -> 6792 | S21: =O21+K21 -> 4545.6
A22: LADIES | B22: SKIRT | C22: PCS | I22: 1635 | K22: =ROUND(I22*1.5,2) -> 2452.5 | M22: =I22 -> 1635 | O22: =K22 -> 2452.5
A23: LADIES | B23: SHORT | C23: PCS | I23: 1848 | K23: =ROUND(I23*1.41,2) -> 2605.68 | M23: =I23 -> 1848 | O23: =K23 -> 2605.68 | Q23: =M23+I23 -> 3696 | S23: =O23+K23 -> 5211.36
A24: LADIES | B24: PAJAMAS | C24: PCS | I24: 4026 | K24: =ROUND(I24*2.04,2) -> 8213.04 | M24: ='1-JAN'!M20 -> 25768 | O24: =K24+'1-JAN'!O22 -> 163453.04
A25: LADIES | B25: NIGHT GOWN | C25: PCS | M25: ='1-JAN'!M22 -> 2080 | O25: ='1-JAN'!O22 -> 155240
A26: LADIES | B26: DRESS | C26: PCS | M26: 0 | O26: 0 | Q26: =M26+I26 -> 0 | S26: =O26+K26 -> 0
A27: Total | E27: =SUM(E20:E26) -> 0 | G27: =SUM(G20:G26) -> 0 | I27: =SUM(I20:I26) -> 33454 | K27: =SUM(K20:K26) -> 61452.62 | M27: =SUM(M20:M26) -> 117492 | O27: =SUM(O20:O26) -> 425087.98
A28: សំគាល់ :​ ទិន្នន័យនៃរបាយការណ៍នេះត្រូវបានប្រើប្រាស់តែក្នុងគោលបំណង ស្ថិតិឧស្សាហកម្មតែប៉ុណ្ណោះ មិនត្រូវបានយកទៅចែកចាយដើម្បីប្រើប្រាស់
A29: ក្នុងគោលបំណងពាណិជ្ជកម្ម ឬក្នុងការគណនាបង់ពន្ធដារទេ។ | K29: ថ្ងៃទី 15 ខែ កុម្ភៈ ឆ្នាំ2026 | N29: =K29 -> ថ្ងៃទី 15 ខែ កុម្ភៈ ឆ្នាំ2026
A30: Remark: This report is used for industrial statistic only,​ not for commercial or tax purpose | J30: ​​​​​​​​​​​​​​​​​​​ | K30: Date:……./……../…… | N30: Date:……./……../……
A31: ទុនអចលនទ្រព្យមិនគិតដីធ្លី រួមមាន៖ អគារ និងឧបករណ៍បរិក្ខារដែលភ្ជាប់នឹងអគារ | K31: នាយក | N31: អ្នកធ្វើរបាយការណ៍
A32: Total asset excluding land comprises of : building & material attached.
A33: ទុនសរុបមិនគិតដីធ្លី រួមមាន៖ ទុនអចលនទ្រព្យមិនគិតដីធ្លី, មធ្យោបាយដឹកជញ្ជូន, គ្រឿងចក្រ-ម៉ាស៊ីន និងឧបករណ៍សម្ភារប្រើប្រាស់ក្នុងផលិតកម្ម, សង្ហារឹម និងសម្ភារការិយាល័យ | K33: Director | N33: Reportor
A34: Total fixed asset excluding land comprises of : real estate capital excluding land, transportation, machinery, and instrument utilised in the production line,
A35: furniture and office equiment.
A36: ទំនាក់ទំនង : Tel 077 330 279/090 922 237 E-mail : industryaffair.mih@gmail.com : TELEGRAM :077 330 279
K40: NI, CUNLAN | N40: THNIN
B41: ឈ្មោះរោងចក្រ ជេអ​ អឹភែរឹល ឯ.ក
A42: ទីផ្សារលក់ផលិតផលប្រចាំខែ | J42: =I6 -> កុម្ភៈ | K42: ឆ្នាំ២០២៦ (USD)
A43: ល.រ | B43: ឈ្មោះផលិតផល | D43: ឯកតា (Unit) | E43: ឈ្មោះប្រទេសនាំចេញផលិតផល | O43: សរុបពីដើមឆ្នាំ
E44: USA | G44: CANADA | I44: CHINA | K44: EU GROUP | M44: ផ្សេងៗ
...

Sheet 3-MAR
B1: ព្រះរាជាណាចក្រកម្ពុជា
B2: ជាត​ សានា ព្រះមហាក្សត្រ
G3: 
B4: របាយការណ៍ជូនក្រសួងឧស្សាហកម្ម វិទ្យាសាស្ត្រ បច្ចេកវិទ្យា និងនវានុវត្តន៍
B5: Report for Ministry of Industry, Science, Technology & Innovation
G6: ទិន្នន័យប្រចាំខែ | I6: មីនា | J6: ឆ្នាំ 2026
G7: Monthly Data In ........... 202…
A9: ឈ្មោះរោងចក្រ:​​​​​​​​​​ ជេអ អឹភែរឹល ឯ.ក អាស័យដ្ឋានរោងចក្រៈ # ផ្លូវលំ ភូមិ កោះខ្នុរ ឃុំ ព្រែករកា ស្រុក កណ្ដាលស្ទឹង ខេត្ត កណ្ដាល ប្រកាសលេខៈ៤១៧ ឧស.កឧ.ប្រក១២ ចុះថ្ងៃទី ២៤​​ ខែ ធ្នូ ឆ្នាំ ២០១៨
A10: Name of Factory: JR APPAREL CO., LTD Factory Address: #LOM ROAD,KAOH KNOR PREAEK ROKA KANDAL STUENG​ KANDAL PROVINCE Prakas Number : 417
A11: ឈ្មោះអ្នកគ្រប់គ្រងរោងចក្រ NI, CUNLAN ទូរស័ព្ទៈ 855-85 441 621 ទូរសារ:.............................. អ៊ីម៉ែលៈ sanashipping8@gmail.com
A12: Manager Name: NI, CUNLAN Tel: 855-85 441 621 Fax:……………………… E-mail: sanashipping8@gmail.com
A13: ចំនួនពលកម្មសរុបៈ​​​ | C13: 179 | E13: ក្នុងនោះមានស្រីៈ | F13: 122 | H13: បៀរវត្សសរុបប្រចាំខែៈ | J13: 63192.24 | L13: USD
A14: Total Number of Employees: Persons Number of Females: Persons Total Salary & Wage of Monthly USD
A15: ទុនសរុបមិនគិតដីធ្លី Total Asset(Land exclude) | D15: 1000000 | F15: ទុនអចលនទ្រព្យមិនគិតដីធ្លី Total Fixed Asset (Land exclude) | J15: 1000000
A16: មុខផលិតផល Products | C16: ឯកតាUnit | D16: បរិមាណ និងតម្លៃផលិតផល Total Output
D17: ឆ្នាំមុន (Data Last Year) | H17: ទិន្នន័យប្រចាំខែ (Monthly Data) | L17: សរុបពីដើមឆ្នាំ (From beginning of the Year )
D18: ​ បរិមាណ Quantity | F18: តម្លៃ Value(USD) | H18: បរិមាណផលិតផល Product Quantity | J18: តម្លៃផលិតផល Product Value(USD) | L18: បរិមាណផលិតផល Product Quantity | N18: តម្លៃផលិតផល Product Value(USD)
D19: ក្នុងស្រុក Domestic | E19: នាំចេញ Export | F19: ក្នុងស្រុក Domestic | G19: នាំចេញ Export | H19: ក្នុងស្រុក Domestic | I19: នាំចេញ Export | J19: ក្នុងស្រុក Domestic | K19: នាំចេញ Export | L19: ក្នុងស្រុក Domestic | M19: នាំចេញ Export | N19: ក្នុងស្រុក Domestic | O19: នាំចេញ Export
A20: LADIES | B20: PANTS | C20: PCS | I20: 60139 | K20: =ROUND(I20*1.9865772626748,2) -> 119470.77 | M20: =I20+'2-FEB'!M20 -> 142904 | O20: =K20+'2-FEB'!O20 -> 218534.73 | Q20: =M20+I20 -> 203043 | S20: =O20+K20 -> 338005.5
A21: LADIES | B21: NIGHT GOWN | C21: PCS | I21: 2004 | K21: =ROUND(I21*2.04,2) -> 4088.16 | M21: =I21+'2-FEB'!M25 -> 4084 | O21: =K21+'1-JAN'!O22 -> 159328.16 | Q21: =M21+I21 -> 6088 | S21: =O21+K21 -> 163416.32
A22: LADIES | B22: PAJAMAS | C22: PCS | I22: 19680 | K22: =ROUND(I22*2.13887804878049,2) -> 42093.12 | M22: =I22+'2-FEB'!M24 -> 45448 | O22: =K22+'2-FEB'!O24 -> 205546.16
A23: LADIES | B23: TANK | C23: PCS | M23: ='2-FEB'!M21 -> 3396 | O23: ='2-FEB'!O21 -> 2272.8
A24: LADIES | B24: SKIRT | C24: PCS | M24: ='2-FEB'!M22 -> 1635 | O24: ='2-FEB'!O22 -> 2452.5 | Q24: =M24+I24 -> 1635 | S24: =O24+K24 -> 2452.5
A25: LADIES | B25: SHORT | C25: PCS | M25: ='2-FEB'!M23 -> 1848 | O25: ='2-FEB'!O23 -> 2605.68 | Q25: =M25+I25 -> 1848 | S25: =O25+K25 -> 2605.68
A26: LADIES | B26: DRESS | C26: PCS | M26: 0 | O26: 0 | Q26: =M26+I26 -> 0 | S26: =O26+K26 -> 0
A27: Total | E27: =SUM(E20:E26) -> 0 | G27: =SUM(G20:G26) -> 0 | I27: =SUM(I20:I26) -> 81823 | K27: =SUM(K20:K26) -> 165652.05 | M27: =SUM(M20:M26) -> 199315 | O27: =SUM(O20:O26) -> 590740.03
A28: សំគាល់ :​ ទិន្នន័យនៃរបាយការណ៍នេះត្រូវបានប្រើប្រាស់តែក្នុងគោលបំណង ស្ថិតិឧស្សាហកម្មតែប៉ុណ្ណោះ មិនត្រូវបានយកទៅចែកចាយដើម្បីប្រើប្រាស់
A29: ក្នុងគោលបំណងពាណិជ្ជកម្ម ឬក្នុងការគណនាបង់ពន្ធដារទេ។ | K29: ថ្ងៃទី 15 ខែ មីនា ឆ្នាំ2026 | N29: =K29 -> ថ្ងៃទី 15 ខែ មីនា ឆ្នាំ2026
A30: Remark: This report is used for industrial statistic only,​ not for commercial or tax purpose | J30: ​​​​​​​​​​​​​​​​​​​ | K30: Date:……./……../…… | N30: Date:……./……../……
A31: ទុនអចលនទ្រព្យមិនគិតដីធ្លី រួមមាន៖ អគារ និងឧបករណ៍បរិក្ខារដែលភ្ជាប់នឹងអគារ | K31: នាយក | N31: អ្នកធ្វើរបាយការណ៍
A32: Total asset excluding land comprises of : building & material attached.
A33: ទុនសរុបមិនគិតដីធ្លី រួមមាន៖ ទុនអចលនទ្រព្យមិនគិតដីធ្លី, មធ្យោបាយដឹកជញ្ជូន, គ្រឿងចក្រ-ម៉ាស៊ីន និងឧបករណ៍សម្ភារប្រើប្រាស់ក្នុងផលិតកម្ម, សង្ហារឹម និងសម្ភារការិយាល័យ | K33: Director | N33: Reportor
A34: Total fixed asset excluding land comprises of : real estate capital excluding land, transportation, machinery, and instrument utilised in the production line,
A35: furniture and office equiment.
A36: ទំនាក់ទំនង : Tel 077 330 279/090 922 237 E-mail : industryaffair.mih@gmail.com : TELEGRAM :077 330 279
K40: NI, CUNLAN | N40: THNIN
B41: ឈ្មោះរោងចក្រ ជេអ​ អឹភែរឹល ឯ.ក
A42: ទីផ្សារលក់ផលិតផលប្រចាំខែ | J42: =I6 -> មីនា | K42: ឆ្នាំ២០២៦ (USD)
A43: ល.រ | B43: ឈ្មោះផលិតផល | D43: ឯកតា (Unit) | E43: ឈ្មោះប្រទេសនាំចេញផលិតផល | O43: សរុបពីដើមឆ្នាំ
E44: USA | G44: CANADA | I44: CHINA | K44: EU GROUP | M44: ផ្សេងៗ
...

Sheet 4-APR
B1: ព្រះរាជាណាចក្រកម្ពុជា
B2: ជាត​ សានា ព្រះមហាក្សត្រ
G3: 
B4: របាយការណ៍ជូនក្រសួងឧស្សាហកម្ម វិទ្យាសាស្ត្រ បច្ចេកវិទ្យា និងនវានុវត្តន៍
B5: Report for Ministry of Industry, Science, Technology & Innovation
G6: ទិន្នន័យប្រចាំខែ | I6: មេសា | J6: ឆ្នាំ 2026
G7: Monthly Data In ........... 202…
A9: ឈ្មោះរោងចក្រ:​​​​​​​​​​ ជេអ អឹភែរឹល ឯ.ក អាស័យដ្ឋានរោងចក្រៈ # ផ្លូវលំ ភូមិ កោះខ្នុរ ឃុំ ព្រែករកា ស្រុក កណ្ដាលស្ទឹង ខេត្ត កណ្ដាល ប្រកាសលេខៈ៤១៧ ឧស.កឧ.ប្រក១២ ចុះថ្ងៃទី ២៤​​ ខែ ធ្នូ ឆ្នាំ ២០១៨
A10: Name of Factory: JR APPAREL CO., LTD Factory Address: #LOM ROAD,KAOH KNOR PREAEK ROKA KANDAL STUENG​ KANDAL PROVINCE Prakas Number : 417
A11: ឈ្មោះអ្នកគ្រប់គ្រងរោងចក្រ NI, CUNLAN ទូរស័ព្ទៈ 855-85 441 621 ទូរសារ:.............................. អ៊ីម៉ែលៈ sanashipping8@gmail.com
A12: Manager Name: NI, CUNLAN Tel: 855-85 441 621 Fax:……………………… E-mail: sanashipping8@gmail.com
A13: ចំនួនពលកម្មសរុបៈ​​​ | C13: 169 | E13: ក្នុងនោះមានស្រីៈ | F13: 116 | H13: បៀរវត្សសរុបប្រចាំខែៈ | J13: 56704.61 | L13: USD
A14: Total Number of Employees: Persons Number of Females: Persons Total Salary & Wage of Monthly USD
A15: ទុនសរុបមិនគិតដីធ្លី Total Asset(Land exclude) | D15: 1000000 | F15: ទុនអចលនទ្រព្យមិនគិតដីធ្លី Total Fixed Asset (Land exclude) | J15: 1000000
A16: មុខផលិតផល Products | C16: ឯកតាUnit | D16: បរិមាណ និងតម្លៃផលិតផល Total Output
D17: ឆ្នាំមុន (Data Last Year) | H17: ទិន្នន័យប្រចាំខែ (Monthly Data) | L17: សរុបពីដើមឆ្នាំ (From beginning of the Year )
D18: ​ បរិមាណ Quantity | F18: តម្លៃ Value(USD) | H18: បរិមាណផលិតផល Product Quantity | J18: តម្លៃផលិតផល Product Value(USD) | L18: បរិមាណផលិតផល Product Quantity | N18: តម្លៃផលិតផល Product Value(USD)
D19: ក្នុងស្រុក Domestic | E19: នាំចេញ Export | F19: ក្នុងស្រុក Domestic | G19: នាំចេញ Export | H19: ក្នុងស្រុក Domestic | I19: នាំចេញ Export | J19: ក្នុងស្រុក Domestic | K19: នាំចេញ Export | L19: ក្នុងស្រុក Domestic | M19: នាំចេញ Export | N19: ក្នុងស្រុក Domestic | O19: នាំចេញ Export
A20: LADIES | B20: PANTS | C20: PCS | I20: 26583 | K20: =ROUND(I20*1.96772561411428,2) -> 52308.05 | M20: =I20+'3-MAR'!M20 -> 169487 | O20: =K20+'3-MAR'!O20 -> 270842.78 | Q20: =M20+I20 -> 196070 | S20: =O20+K20 -> 323150.83
A21: LADIES | B21: DRESS | C21: PCS | I21: 576 | K21: =ROUND(I21*2.66,2) -> 1532.16 | M21: =I21 -> 576 | O21: =K21 -> 1532.16 | Q21: =M21+I21 -> 1152 | S21: =O21+K21 -> 3064.32
A22: LADIES | B22: PAJAMAS | C22: PCS | I22: 35832 | K22: =ROUND(I22*1.73571667782987,2) -> 62194.2 | M22: =I22+'3-MAR'!M22 -> 81280 | O22: =K22+'3-MAR'!O22 -> 267740.36
A23: LADIES | B23: NIGHT GOWN | C23: PCS | M23: ='3-MAR'!M21 -> 4084 | O23: ='3-MAR'!O21 -> 159328.16
A24: LADIES | B24: TANK | C24: PCS | M24: ='3-MAR'!M23 -> 3396 | O24: ='3-MAR'!O23 -> 2272.8 | Q24: =M24+I24 -> 3396 | S24: =O24+K24 -> 2272.8
A25: LADIES | B25: SKIRT | C25: PCS | M25: ='3-MAR'!M24 -> 1635 | O25: ='3-MAR'!O24 -> 2452.5 | Q25: =M25+I25 -> 1635 | S25: =O25+K25 -> 2452.5
A26: LADIES | B26: SHORT | C26: PCS | M26: ='3-MAR'!M25 -> 1848 | O26: ='3-MAR'!O25 -> 2605.68 | Q26: =M26+I26 -> 1848 | S26: =O26+K26 -> 2605.68
A27: Total | E27: =SUM(E20:E26) -> 0 | G27: =SUM(G20:G26) -> 0 | I27: =SUM(I20:I26) -> 62991 | K27: =SUM(K20:K26) -> 116034.41 | M27: =SUM(M20:M26) -> 262306 | O27: =SUM(O20:O26) -> 706774.44
A28: សំគាល់ :​ ទិន្នន័យនៃរបាយការណ៍នេះត្រូវបានប្រើប្រាស់តែក្នុងគោលបំណង ស្ថិតិឧស្សាហកម្មតែប៉ុណ្ណោះ មិនត្រូវបានយកទៅចែកចាយដើម្បីប្រើប្រាស់
A29: ក្នុងគោលបំណងពាណិជ្ជកម្ម ឬក្នុងការគណនាបង់ពន្ធដារទេ។ | K29: ថ្ងៃទី 15 ខែ មេសា ឆ្នាំ2026 | N29: =K29 -> ថ្ងៃទី 15 ខែ មេសា ឆ្នាំ2026
A30: Remark: This report is used for industrial statistic only,​ not for commercial or tax purpose | J30: ​​​​​​​​​​​​​​​​​​​ | K30: Date:……./……../…… | N30: Date:……./……../……
A31: ទុនអចលនទ្រព្យមិនគិតដីធ្លី រួមមាន៖ អគារ និងឧបករណ៍បរិក្ខារដែលភ្ជាប់នឹងអគារ | K31: នាយក | N31: អ្នកធ្វើរបាយការណ៍
A32: Total asset excluding land comprises of : building & material attached.
A33: ទុនសរុបមិនគិតដីធ្លី រួមមាន៖ ទុនអចលនទ្រព្យមិនគិតដីធ្លី, មធ្យោបាយដឹកជញ្ជូន, គ្រឿងចក្រ-ម៉ាស៊ីន និងឧបករណ៍សម្ភារប្រើប្រាស់ក្នុងផលិតកម្ម, សង្ហារឹម និងសម្ភារការិយាល័យ | K33: Director | N33: Reportor
A34: Total fixed asset excluding land comprises of : real estate capital excluding land, transportation, machinery, and instrument utilised in the production line,
A35: furniture and office equiment.
A36: ទំនាក់ទំនង : Tel 077 330 279/090 922 237 E-mail : industryaffair.mih@gmail.com : TELEGRAM :077 330 279
K40: NI, CUNLAN | N40: THNIN
B41: ឈ្មោះរោងចក្រ ជេអ​ អឹភែរឹល ឯ.ក
A42: ទីផ្សារលក់ផលិតផលប្រចាំខែ | J42: =I6 -> មេសា | K42: ឆ្នាំ២០២៦ (USD)
A43: ល.រ | B43: ឈ្មោះផលិតផល | D43: ឯកតា (Unit) | E43: ឈ្មោះប្រទេសនាំចេញផលិតផល | O43: សរុបពីដើមឆ្នាំ
E44: USA | G44: CANADA | I44: CHINA | K44: EU GROUP | M44: ផ្សេងៗ
...

Sheet 5-MAY
B1: ព្រះរាជាណាចក្រកម្ពុជា
B2: ជាត​ សានា ព្រះមហាក្សត្រ
G3: 
B4: របាយការណ៍ជូនក្រសួងឧស្សាហកម្ម វិទ្យាសាស្ត្រ បច្ចេកវិទ្យា និងនវានុវត្តន៍
B5: Report for Ministry of Industry, Science, Technology & Innovation
G6: ទិន្នន័យប្រចាំខែ | I6: ឧសភា | J6: ឆ្នាំ 2026
G7: Monthly Data In ........... 202…
A9: ឈ្មោះរោងចក្រ:​​​​​​​​​​ ជេអ អឹភែរឹល ឯ.ក អាស័យដ្ឋានរោងចក្រៈ # ផ្លូវលំ ភូមិ កោះខ្នុរ ឃុំ ព្រែករកា ស្រុក កណ្ដាលស្ទឹង ខេត្ត កណ្ដាល ប្រកាសលេខៈ៤១៧ ឧស.កឧ.ប្រក១២ ចុះថ្ងៃទី ២៤​​ ខែ ធ្នូ ឆ្នាំ ២០១៨
A10: Name of Factory: JR APPAREL CO., LTD Factory Address: #LOM ROAD,KAOH KNOR PREAEK ROKA KANDAL STUENG​ KANDAL PROVINCE Prakas Number : 417
A11: ឈ្មោះអ្នកគ្រប់គ្រងរោងចក្រ NI, CUNLAN ទូរស័ព្ទៈ 855-85 441 621 ទូរសារ:.............................. អ៊ីម៉ែលៈ sanashipping8@gmail.com
A12: Manager Name: NI, CUNLAN Tel: 855-85 441 621 Fax:……………………… E-mail: sanashipping8@gmail.com
A13: ចំនួនពលកម្មសរុបៈ​​​ | C13: 151 | E13: ក្នុងនោះមានស្រីៈ | F13: 105 | H13: បៀរវត្សសរុបប្រចាំខែៈ | J13: 55620.7 | L13: USD
A14: Total Number of Employees: Persons Number of Females: Persons Total Salary & Wage of Monthly USD
A15: ទុនសរុបមិនគិតដីធ្លី Total Asset(Land exclude) | D15: 1000000 | F15: ទុនអចលនទ្រព្យមិនគិតដីធ្លី Total Fixed Asset (Land exclude) | J15: 1000000
A16: មុខផលិតផល Products | C16: ឯកតាUnit | D16: បរិមាណ និងតម្លៃផលិតផល Total Output
D17: ឆ្នាំមុន (Data Last Year) | H17: ទិន្នន័យប្រចាំខែ (Monthly Data) | L17: សរុបពីដើមឆ្នាំ (From beginning of the Year )
D18: ​ បរិមាណ Quantity | F18: តម្លៃ Value(USD) | H18: បរិមាណផលិតផល Product Quantity | J18: តម្លៃផលិតផល Product Value(USD) | L18: បរិមាណផលិតផល Product Quantity | N18: តម្លៃផលិតផល Product Value(USD)
D19: ក្នុងស្រុក Domestic | E19: នាំចេញ Export | F19: ក្នុងស្រុក Domestic | G19: នាំចេញ Export | H19: ក្នុងស្រុក Domestic | I19: នាំចេញ Export | J19: ក្នុងស្រុក Domestic | K19: នាំចេញ Export | L19: ក្នុងស្រុក Domestic | M19: នាំចេញ Export | N19: ក្នុងស្រុក Domestic | O19: នាំចេញ Export
A20: LADIES | B20: PANTS | C20: PCS | I20: 45756 | K20: =ROUND(I20*2.13575268817204,2) -> 97723.5 | M20: =I20+'4-APR'!M20 -> 215243 | O20: =K20+'4-APR'!O20 -> 368566.28 | Q20: =M20+I20 -> 260999 | S20: =O20+K20 -> 466289.78
A21: LADIES | B21: SKIRT | C21: PCS | I21: 175 | K21: =ROUND(I21*2.3,2) -> 402.5 | M21: =I21+'2-FEB'!M22 -> 1810 | O21: =K21+'2-FEB'!O22 -> 2855 | Q21: =M21+I21 -> 1985 | S21: =O21+K21 -> 3257.5
A22: LADIES | B22: PAJAMAS | C22: PCS | I22: 38268 | K22: =ROUND(I22*1.34513954217623,2) -> 51475.8 | M22: =I22+'4-APR'!M22 -> 119548 | O22: =K22+'4-APR'!O22 -> 319216.16
A23: LADIES | B23: DRESS | C23: PCS | M23: ='4-APR'!M22 -> 81280 | O23: ='4-APR'!O22 -> 267740.36
A24: LADIES | B24: NIGHT GOWN | C24: PCS | M24: ='4-APR'!M21 -> 576 | O24: ='4-APR'!O21 -> 1532.16 | Q24: =M24+I24 -> 576 | S24: =O24+K24 -> 1532.16
A25: LADIES | B25: TANK | C25: PCS | M25: ='4-APR'!M24 -> 3396 | O25: ='4-APR'!O24 -> 2272.8 | Q25: =M25+I25 -> 3396 | S25: =O25+K25 -> 2272.8
A26: LADIES | B26: SHORT | C26: PCS | M26: ='4-APR'!M26 -> 1848 | O26: ='4-APR'!O26 -> 2605.68 | Q26: =M26+I26 -> 1848 | S26: =O26+K26 -> 2605.68
A27: Total | E27: =SUM(E20:E26) -> 0 | G27: =SUM(G20:G26) -> 0 | I27: =SUM(I20:I26) -> 84199 | K27: =SUM(K20:K26) -> 149601.8 | M27: =SUM(M20:M26) -> 423701 | O27: =SUM(O20:O26) -> 964788.44
A28: សំគាល់ :​ ទិន្នន័យនៃរបាយការណ៍នេះត្រូវបានប្រើប្រាស់តែក្នុងគោលបំណង ស្ថិតិឧស្សាហកម្មតែប៉ុណ្ណោះ មិនត្រូវបានយកទៅចែកចាយដើម្បីប្រើប្រាស់
A29: ក្នុងគោលបំណងពាណិជ្ជកម្ម ឬក្នុងការគណនាបង់ពន្ធដារទេ។ | K29: ថ្ងៃទី 15 ខែ ឧសភា ឆ្នាំ2026 | N29: =K29 -> ថ្ងៃទី 15 ខែ ឧសភា ឆ្នាំ2026
A30: Remark: This report is used for industrial statistic only,​ not for commercial or tax purpose | J30: ​​​​​​​​​​​​​​​​​​​ | K30: Date:……./……../…… | N30: Date:……./……../……
A31: ទុនអចលនទ្រព្យមិនគិតដីធ្លី រួមមាន៖ អគារ និងឧបករណ៍បរិក្ខារដែលភ្ជាប់នឹងអគារ | K31: នាយក | N31: អ្នកធ្វើរបាយការណ៍
A32: Total asset excluding land comprises of : building & material attached.
A33: ទុនសរុបមិនគិតដីធ្លី រួមមាន៖ ទុនអចលនទ្រព្យមិនគិតដីធ្លី, មធ្យោបាយដឹកជញ្ជូន, គ្រឿងចក្រ-ម៉ាស៊ីន និងឧបករណ៍សម្ភារប្រើប្រាស់ក្នុងផលិតកម្ម, សង្ហារឹម និងសម្ភារការិយាល័យ | K33: Director | N33: Reportor
A34: Total fixed asset excluding land comprises of : real estate capital excluding land, transportation, machinery, and instrument utilised in the production line,
A35: furniture and office equiment.
A36: ទំនាក់ទំនង : Tel 077 330 279/090 922 237 E-mail : industryaffair.mih@gmail.com : TELEGRAM :077 330 279
K40: NI, CUNALN | N40: THNIN
B41: ឈ្មោះរោងចក្រ ជេអ​ អឹភែរឹល ឯ.ក
A42: ទីផ្សារលក់ផលិតផលប្រចាំខែ | J42: =I6 -> ឧសភា | K42: ឆ្នាំ២០២៦ (USD)
A43: ល.រ | B43: ឈ្មោះផលិតផល | D43: ឯកតា (Unit) | E43: ឈ្មោះប្រទេសនាំចេញផលិតផល | O43: សរុបពីដើមឆ្នាំ
E44: USA | G44: CANADA | I44: CHINA | K44: EU GROUP | M44: ផ្សេងៗ
...

Sheet 6-JUN
B1: ព្រះរាជាណាចក្រកម្ពុជា
B2: ជាត​ សានា ព្រះមហាក្សត្រ
G3: 
B4: របាយការណ៍ជូនក្រសួងឧស្សាហកម្ម វិទ្យាសាស្ត្រ បច្ចេកវិទ្យា និងនវានុវត្តន៍
B5: Report for Ministry of Industry, Science, Technology & Innovation
G6: ទិន្នន័យប្រចាំខែ | I6: មិថុនា | J6: ឆ្នាំ 2026
G7: Monthly Data In ........... 202…
A9: ឈ្មោះរោងចក្រ:​​​​​​​​​​ ជេអ អឹភែរឹល ឯ.ក អាស័យដ្ឋានរោងចក្រៈ # ផ្លូវលំ ភូមិ កោះខ្នុរ ឃុំ ព្រែករកា ស្រុក កណ្ដាលស្ទឹង ខេត្ត កណ្ដាល ប្រកាសលេខៈ៤១៧ ឧស.កឧ.ប្រក១២ ចុះថ្ងៃទី ២៤​​ ខែ ធ្នូ ឆ្នាំ ២០១៨
A10: Name of Factory: JR APPAREL CO., LTD Factory Address: #LOM ROAD,KAOH KNOR PREAEK ROKA KANDAL STUENG​ KANDAL PROVINCE Prakas Number : 417
A11: ឈ្មោះអ្នកគ្រប់គ្រងរោងចក្រ NI, CUNLAN ទូរស័ព្ទៈ 855-85 441 621 ទូរសារ:.............................. អ៊ីម៉ែលៈ sanashipping8@gmail.com
A12: Manager Name: NI, CUNLAN Tel: 855-85 441 621 Fax:……………………… E-mail: sanashipping8@gmail.com
A13: ចំនួនពលកម្មសរុបៈ​​​ | C13: 186 | E13: ក្នុងនោះមានស្រីៈ | F13: 125 | H13: បៀរវត្សសរុបប្រចាំខែៈ | J13: 65896.2 | L13: USD
A14: Total Number of Employees: Persons Number of Females: Persons Total Salary & Wage of Monthly USD
A15: ទុនសរុបមិនគិតដីធ្លី Total Asset(Land exclude) | D15: 1000000 | F15: ទុនអចលនទ្រព្យមិនគិតដីធ្លី Total Fixed Asset (Land exclude) | J15: 1000000
A16: មុខផលិតផល Products | C16: ឯកតាUnit | D16: បរិមាណ និងតម្លៃផលិតផល Total Output
D17: ឆ្នាំមុន (Data Last Year) | H17: ទិន្នន័យប្រចាំខែ (Monthly Data) | L17: សរុបពីដើមឆ្នាំ (From beginning of the Year )
D18: ​ បរិមាណ Quantity | F18: តម្លៃ Value(USD) | H18: បរិមាណផលិតផល Product Quantity | J18: តម្លៃផលិតផល Product Value(USD) | L18: បរិមាណផលិតផល Product Quantity | N18: តម្លៃផលិតផល Product Value(USD)
D19: ក្នុងស្រុក Domestic | E19: នាំចេញ Export | F19: ក្នុងស្រុក Domestic | G19: នាំចេញ Export | H19: ក្នុងស្រុក Domestic | I19: នាំចេញ Export | J19: ក្នុងស្រុក Domestic | K19: នាំចេញ Export | L19: ក្នុងស្រុក Domestic | M19: នាំចេញ Export | N19: ក្នុងស្រុក Domestic | O19: នាំចេញ Export
A20: LADIES | B20: PANTS | C20: PCS | I20: 136526 | K20: =ROUND(I20*2.05938099702621,2) -> 281159.05 | M20: =I20+'5-MAY'!M20 -> 351769 | O20: =K20+'5-MAY'!O20 -> 649725.33 | Q20: =M20+I20 -> 488295 | S20: =O20+K20 -> 930884.38
A21: LADIES | B21: PAJAMAS | C21: PCS | I21: 5424 | K21: =ROUND(I21*1.325,2) -> 7186.8 | M21: =I21+'5-MAY'!M22 -> 124972 | O21: =K21+'5-MAY'!O22 -> 326402.96
A22: LADIES | B22: SKIRT | C22: PCS | M22: ='5-MAY'!M21 -> 1810 | O22: ='5-MAY'!O21 -> 2855
A23: LADIES | B23: DRESS | C23: PCS | M23: ='5-MAY'!M23 -> 81280 | O23: ='5-MAY'!O23 -> 267740.36 | Q23: =M23+I23 -> 81280 | S23: =O23+K23 -> 267740.36
A24: LADIES | B24: NIGHT GOWN | C24: PCS | M24: ='5-MAY'!M24 -> 576 | O24: ='5-MAY'!O24 -> 1532.16 | Q24: =M24+I24 -> 576 | S24: =O24+K24 -> 1532.16
A25: LADIES | B25: TANK | C25: PCS | M25: ='5-MAY'!M25 -> 3396 | O25: ='5-MAY'!O25 -> 2272.8 | Q25: =M25+I25 -> 3396 | S25: =O25+K25 -> 2272.8
A26: LADIES | B26: SHORT | C26: PCS | M26: ='5-MAY'!M26 -> 1848 | O26: ='5-MAY'!O26 -> 2605.68 | Q26: =M26+I26 -> 1848 | S26: =O26+K26 -> 2605.68
A27: Total | E27: =SUM(E20:E26) -> 0 | G27: =SUM(G20:G26) -> 0 | I27: =SUM(I20:I26) -> 141950 | K27: =SUM(K20:K26) -> 288345.85 | M27: =SUM(M20:M26) -> 565651 | O27: =SUM(O20:O26) -> 1253134.3
A28: សំគាល់ :​ ទិន្នន័យនៃរបាយការណ៍នេះត្រូវបានប្រើប្រាស់តែក្នុងគោលបំណង ស្ថិតិឧស្សាហកម្មតែប៉ុណ្ណោះ មិនត្រូវបានយកទៅចែកចាយដើម្បីប្រើប្រាស់
A29: ក្នុងគោលបំណងពាណិជ្ជកម្ម ឬក្នុងការគណនាបង់ពន្ធដារទេ។ | K29: ថ្ងៃទី 15 ខែ មិថុនា ឆ្នាំ2026 | N29: =K29 -> ថ្ងៃទី 15 ខែ មិថុនា ឆ្នាំ2026
A30: Remark: This report is used for industrial statistic only,​ not for commercial or tax purpose | J30: ​​​​​​​​​​​​​​​​​​​ | K30: Date:……./……../…… | N30: Date:……./……../……
A31: ទុនអចលនទ្រព្យមិនគិតដីធ្លី រួមមាន៖ អគារ និងឧបករណ៍បរិក្ខារដែលភ្ជាប់នឹងអគារ | K31: នាយក | N31: អ្នកធ្វើរបាយការណ៍
A32: Total asset excluding land comprises of : building & material attached.
A33: ទុនសរុបមិនគិតដីធ្លី រួមមាន៖ ទុនអចលនទ្រព្យមិនគិតដីធ្លី, មធ្យោបាយដឹកជញ្ជូន, គ្រឿងចក្រ-ម៉ាស៊ីន និងឧបករណ៍សម្ភារប្រើប្រាស់ក្នុងផលិតកម្ម, សង្ហារឹម និងសម្ភារការិយាល័យ | K33: Director | N33: Reportor
A34: Total fixed asset excluding land comprises of : real estate capital excluding land, transportation, machinery, and instrument utilised in the production line,
A35: furniture and office equiment.
A36: ទំនាក់ទំនង : Tel 077 330 279/090 922 237 E-mail : industryaffair.mih@gmail.com : TELEGRAM :077 330 279
K40: NI, CUNLAN | N40: THNIN
B41: ឈ្មោះរោងចក្រ ជេអ​ អឹភែរឹល ឯ.ក
A42: ទីផ្សារលក់ផលិតផលប្រចាំខែ | J42: =I6 -> មិថុនា | K42: ឆ្នាំ២០២៦ (USD)
A43: ល.រ | B43: ឈ្មោះផលិតផល | D43: ឯកតា (Unit) | E43: ឈ្មោះប្រទេសនាំចេញផលិតផល | O43: សរុបពីដើមឆ្នាំ
E44: USA | G44: CANADA | I44: CHINA | K44: EU GROUP | M44: ផ្សេងៗ
...

Sheet 7-JUL
B1: ព្រះរាជាណាចក្រកម្ពុជា
B2: ជាត​ សានា ព្រះមហាក្សត្រ
G3: 
B4: របាយការណ៍ជូនក្រសួងឧស្សាហកម្ម វិទ្យាសាស្ត្រ បច្ចេកវិទ្យា និងនវានុវត្តន៍
B5: Report for Ministry of Industry, Science, Technology & Innovation
G6: ទិន្នន័យប្រចាំខែ | I6: កក្កដា | J6: ឆ្នាំ 2026
G7: Monthly Data In ........... 202…
A9: ឈ្មោះរោងចក្រ:​​​​​​​​​​ ជេអ អឹភែរឹល ឯ.ក អាស័យដ្ឋានរោងចក្រៈ # ផ្លូវលំ ភូមិ កោះខ្នុរ ឃុំ ព្រែករកា ស្រុក កណ្ដាលស្ទឹង ខេត្ត កណ្ដាល ប្រកាសលេខៈ៤១៧ ឧស.កឧ.ប្រក១២ ចុះថ្ងៃទី ២៤​​ ខែ ធ្នូ ឆ្នាំ ២០១៨
A10: Name of Factory: JR APPAREL CO., LTD Factory Address: #LOM ROAD,KAOH KNOR PREAEK ROKA KANDAL STUENG​ KANDAL PROVINCE Prakas Number : 417
A11: ឈ្មោះអ្នកគ្រប់គ្រងរោងចក្រ NI, CUNLAN ទូរស័ព្ទៈ 855-85 441 621 ទូរសារ:.............................. អ៊ីម៉ែលៈ sanashipping8@gmail.com
A12: Manager Name: NI, CUNLAN Tel: 855-85 441 621 Fax:……………………… E-mail: sanashipping8@gmail.com
A13: ចំនួនពលកម្មសរុបៈ​​​ | C13: 169 | E13: ក្នុងនោះមានស្រីៈ | F13: 113 | H13: បៀរវត្សសរុបប្រចាំខែៈ | J13: 59031.34 | L13: USD
A14: Total Number of Employees: Persons Number of Females: Persons Total Salary & Wage of Monthly USD
A15: ទុនសរុបមិនគិតដីធ្លី Total Asset(Land exclude) | D15: 1000000 | F15: ទុនអចលនទ្រព្យមិនគិតដីធ្លី Total Fixed Asset (Land exclude) | J15: 1000000
A16: មុខផលិតផល Products | C16: ឯកតាUnit | D16: បរិមាណ និងតម្លៃផលិតផល Total Output
D17: ឆ្នាំមុន (Data Last Year) | H17: ទិន្នន័យប្រចាំខែ (Monthly Data) | L17: សរុបពីដើមឆ្នាំ (From beginning of the Year )
D18: ​ បរិមាណ Quantity | F18: តម្លៃ Value(USD) | H18: បរិមាណផលិតផល Product Quantity | J18: តម្លៃផលិតផល Product Value(USD) | L18: បរិមាណផលិតផល Product Quantity | N18: តម្លៃផលិតផល Product Value(USD)
D19: ក្នុងស្រុក Domestic | E19: នាំចេញ Export | F19: ក្នុងស្រុក Domestic | G19: នាំចេញ Export | H19: ក្នុងស្រុក Domestic | I19: នាំចេញ Export | J19: ក្នុងស្រុក Domestic | K19: នាំចេញ Export | L19: ក្នុងស្រុក Domestic | M19: នាំចេញ Export | N19: ក្នុងស្រុក Domestic | O19: នាំចេញ Export
A20: LADIES | B20: PANTS | C20: PCS | I20: 22486 | K20: 56774.5 | M20: 374255 | O20: =K20+'6-JUN'!O20 -> 706499.83 | Q20: =M20+I20 -> 396741 | S20: =O20+K20 -> 763274.33
A21: LADIES | B21: PAJAMAS | C21: PCS | I21: 8484 | K21: 10918.8 | M21: 10294 | O21: =K21+'6-JUN'!O21 -> 337321.76
A22: LADIES | B22: SKIRT | C22: PCS | M22: 81280 | O22: =K22+'6-JUN'!O22 -> 2855
A23: LADIES | B23: DRESS | C23: PCS | M23: 576 | O23: =K23+'6-JUN'!O23 -> 267740.36 | Q23: =M23+I23 -> 576 | S23: =O23+K23 -> 267740.36
A24: LADIES | B24: NIGHT GOWN | C24: PCS | M24: 3396 | O24: =K24+'6-JUN'!O24 -> 1532.16 | Q24: =M24+I24 -> 3396 | S24: =O24+K24 -> 1532.16
A25: LADIES | B25: TANK | C25: PCS | M25: 1848 | O25: =K25+'6-JUN'!O25 -> 2272.8 | Q25: =M25+I25 -> 1848 | S25: =O25+K25 -> 2272.8
A26: LADIES | B26: SHORT | C26: PCS | M26: 565651 | O26: =K26+'6-JUN'!O26 -> 2605.68 | Q26: =M26+I26 -> 565651 | S26: =O26+K26 -> 2605.68
A27: LADIES | B27: SKORT | C27: PCS | I27: 1000 | K27: 1950 | M27: 1000 | O27: =K27 -> 1950
A28: Total | E28: =SUM(E20:E26) -> 0 | G28: =SUM(G20:G26) -> 0 | I28: =SUM(I20:I27) -> 31970 | K28: =SUM(K20:K27) -> 69643.3 | M28: =SUM(M20:M27) -> 1038300 | O28: =SUM(O20:O27) -> 1322777.6
A29: សំគាល់ :​ ទិន្នន័យនៃរបាយការណ៍នេះត្រូវបានប្រើប្រាស់តែក្នុងគោលបំណង ស្ថិតិឧស្សាហកម្មតែប៉ុណ្ណោះ មិនត្រូវបានយកទៅចែកចាយដើម្បីប្រើប្រាស់
A30: ក្នុងគោលបំណងពាណិជ្ជកម្ម ឬក្នុងការគណនាបង់ពន្ធដារទេ។ | K30: ថ្ងៃទី 15 ខែ កក្កដា ឆ្នាំ2026 | N30: =K30 -> ថ្ងៃទី 15 ខែ កក្កដា ឆ្នាំ2026
A31: Remark: This report is used for industrial statistic only,​ not for commercial or tax purpose | J31: ​​​​​​​​​​​​​​​​​​​ | K31: Date:……./……../…… | N31: Date:……./……../……
A32: ទុនអចលនទ្រព្យមិនគិតដីធ្លី រួមមាន៖ អគារ និងឧបករណ៍បរិក្ខារដែលភ្ជាប់នឹងអគារ | K32: នាយក | N32: អ្នកធ្វើរបាយការណ៍
A33: Total asset excluding land comprises of : building & material attached.
A34: ទុនសរុបមិនគិតដីធ្លី រួមមាន៖ ទុនអចលនទ្រព្យមិនគិតដីធ្លី, មធ្យោបាយដឹកជញ្ជូន, គ្រឿងចក្រ-ម៉ាស៊ីន និងឧបករណ៍សម្ភារប្រើប្រាស់ក្នុងផលិតកម្ម, សង្ហារឹម និងសម្ភារការិយាល័យ | K34: Director | N34: Reportor
A35: Total fixed asset excluding land comprises of : real estate capital excluding land, transportation, machinery, and instrument utilised in the production line,
A36: furniture and office equiment.
A37: ទំនាក់ទំនង : Tel 077 330 279/090 922 237 E-mail : industryaffair.mih@gmail.com : TELEGRAM :077 330 279
K41: NI, CUNLAN | N41: THNIN
B42: ឈ្មោះរោងចក្រ ជេអ​ អឹភែរឹល ឯ.ក
A43: ទីផ្សារលក់ផលិតផលប្រចាំខែ | J43: =I6 -> កក្កដា | K43: ឆ្នាំ២០២៦ (USD)
A44: ល.រ | B44: ឈ្មោះផលិតផល | D44: ឯកតា (Unit) | E44: ឈ្មោះប្រទេសនាំចេញផលិតផល | O44: សរុបពីដើមឆ្នាំ
...

Sheet 8-AUG
B1: ព្រះរាជាណាចក្រកម្ពុជា
B2: ជាត​ សានា ព្រះមហាក្សត្រ
G3: 
B4: របាយការណ៍ជូនក្រសួងឧស្សាហកម្ម វិទ្យាសាស្ត្រ បច្ចេកវិទ្យា និងនវានុវត្តន៍
B5: Report for Ministry of Industry, Science, Technology & Innovation
G6: ទិន្នន័យប្រចាំខែ | I6: សីហា | J6: ឆ្នាំ 2026
G7: Monthly Data In August 2026
A9: ឈ្មោះរោងចក្រ:​​​​​​​​​​ ជេអ អឹភែរឹល ឯ.ក អាស័យដ្ឋានរោងចក្រៈ # ផ្លូវលំ ភូមិ កោះខ្នុរ ឃុំ ព្រែករកា ស្រុក កណ្ដាលស្ទឹង ខេត្ត កណ្ដាល ប្រកាសលេខៈ៤១៧ ឧស.កឧ.ប្រក១២ ចុះថ្ងៃទី ២៤​​ ខែ ធ្នូ ឆ្នាំ ២០១៨
A10: Name of Factory: JR APPAREL CO., LTD Factory Address: #LOM ROAD,KAOH KNOR PREAEK ROKA KANDAL STUENG​ KANDAL PROVINCE Prakas Number : 417
A11: ឈ្មោះអ្នកគ្រប់គ្រងរោងចក្រ NI, CUNLAN ទូរស័ព្ទៈ 855-85 441 621 ទូរសារ:.............................. អ៊ីម៉ែលៈ sanashipping8@gmail.com
A12: Manager Name: NI, CUNLAN Tel: 855-85 441 621 Fax:……………………… E-mail: sanashipping8@gmail.com
A13: ចំនួនពលកម្មសរុបៈ​​​ | C13: 168 | D13: ក្នុងនោះមានស្រីៈ | F13: 113 | H13: បៀរវត្សសរុបប្រចាំខែៈ | J13: 61010.34 | L13: USD
A14: Total Number of Employees: Persons Number of Females: Persons Total Salary & Wage of Monthly USD
A15: ទុនសរុបមិនគិតដីធ្លី Total Asset(Land exclude) | D15: 1000000 | F15: ទុនអចលនទ្រព្យមិនគិតដីធ្លី Total Fixed Asset (Land exclude) | J15: 1000000
A16: មុខផលិតផល Products | C16: ឯកតាUnit | D16: បរិមាណ និងតម្លៃផលិតផល Total Output
D17: ឆ្នាំមុន (Data Last Year) | H17: ទិន្នន័យប្រចាំខែ (Monthly Data) | L17: សរុបពីដើមឆ្នាំ (From beginning of the Year )
D18: ​ បរិមាណ Quantity | F18: តម្លៃ Value(USD) | H18: បរិមាណផលិតផល Product Quantity | J18: តម្លៃផលិតផល Product Value(USD) | L18: បរិមាណផលិតផល Product Quantity | N18: តម្លៃផលិតផល Product Value(USD)
D19: ក្នុងស្រុក Domestic | E19: នាំចេញ Export | F19: ក្នុងស្រុក Domestic | G19: នាំចេញ Export | H19: ក្នុងស្រុក Domestic | I19: នាំចេញ Export | J19: ក្នុងស្រុក Domestic | K19: នាំចេញ Export | L19: ក្នុងស្រុក Domestic | M19: នាំចេញ Export | N19: ក្នុងស្រុក Domestic | O19: នាំចេញ Export
A20: LADIES | B20: PANTS | C20: PCS | I20: 41078 | K20: =ROUND(I20*2.25345562101368,2) -> 92567.45 | M20: =I20+'7-JUL'!M20 -> 415333 | O20: =K20+'7-JUL'!O20 -> 799067.28 | Q20: =M20+I20 -> 456411 | S20: =O20+K20 -> 891634.73
A21: LADIES | B21: PAJAMAS | C21: PCS | I21: 13404 | K21: =ROUND(I21*1.38028200537153,2) -> 18501.3 | M21: =I21+'7-JUL'!M21 -> 23698 | O21: =K21+'6-JUN'!O21 -> 344904.26
A22: LADIES | B22: SKIRT | C22: PCS | M22: 81280 | O22: =K22+'6-JUN'!O22 -> 2855
A23: LADIES | B23: DRESS | C23: PCS | M23: 576 | O23: =K23+'6-JUN'!O23 -> 267740.36 | Q23: =M23+I23 -> 576 | S23: =O23+K23 -> 267740.36
A24: LADIES | B24: NIGHT GOWN | C24: PCS | M24: 3396 | O24: =K24+'6-JUN'!O24 -> 1532.16 | Q24: =M24+I24 -> 3396 | S24: =O24+K24 -> 1532.16
A25: LADIES | B25: TANK | C25: PCS | M25: 1848 | O25: =K25+'6-JUN'!O25 -> 2272.8 | Q25: =M25+I25 -> 1848 | S25: =O25+K25 -> 2272.8
A26: LADIES | B26: SHORT | C26: PCS | M26: 565651 | O26: =K26+'6-JUN'!O26 -> 2605.68 | Q26: =M26+I26 -> 565651 | S26: =O26+K26 -> 2605.68
A27: LADIES | B27: SKORT | C27: PCS | M27: ='7-JUL'!M27 -> 1000 | O27: ='7-JUL'!O27 -> 1950
A28: Total | E28: =SUM(E20:E26) -> 0 | G28: =SUM(G20:G26) -> 0 | I28: =SUM(I20:I27) -> 54482 | K28: =SUM(K20:K27) -> 111068.75 | M28: =SUM(M20:M27) -> 1092782 | O28: =SUM(O20:O27) -> 1422927.5
A29: សំគាល់ :​ ទិន្នន័យនៃរបាយការណ៍នេះត្រូវបានប្រើប្រាស់តែក្នុងគោលបំណង ស្ថិតិឧស្សាហកម្មតែប៉ុណ្ណោះ មិនត្រូវបានយកទៅចែកចាយដើម្បីប្រើប្រាស់
A30: ក្នុងគោលបំណងពាណិជ្ជកម្ម ឬក្នុងការគណនាបង់ពន្ធដារទេ។ | K30: ថ្ងៃទី 15 ខែ សីហា ឆ្នាំ2026 | N30: =K30 -> ថ្ងៃទី 15 ខែ សីហា ឆ្នាំ2026
A31: Remark: This report is used for industrial statistic only,​ not for commercial or tax purpose | J31: ​​​​​​​​​​​​​​​​​​​ | K31: Date:……./……../…… | N31: Date:……./……../……
A32: ទុនអចលនទ្រព្យមិនគិតដីធ្លី រួមមាន៖ អគារ និងឧបករណ៍បរិក្ខារដែលភ្ជាប់នឹងអគារ | K32: នាយក | N32: អ្នកធ្វើរបាយការណ៍
A33: Total asset excluding land comprises of : building & material attached.
A34: ទុនសរុបមិនគិតដីធ្លី រួមមាន៖ ទុនអចលនទ្រព្យមិនគិតដីធ្លី, មធ្យោបាយដឹកជញ្ជូន, គ្រឿងចក្រ-ម៉ាស៊ីន និងឧបករណ៍សម្ភារប្រើប្រាស់ក្នុងផលិតកម្ម, សង្ហារឹម និងសម្ភារការិយាល័យ | K34: Director | N34: Reportor
A35: Total fixed asset excluding land comprises of : real estate capital excluding land, transportation, machinery, and instrument utilised in the production line,
A36: furniture and office equiment.
A37: ទំនាក់ទំនង : Tel 077 330 279/090 922 237 E-mail : industryaffair.mih@gmail.com : TELEGRAM :077 330 279
K41: NI, CUNLAN | N41: THNIN
B42: ឈ្មោះរោងចក្រ ជេអ​ អឹភែរឹល ឯ.ក
A43: ទីផ្សារលក់ផលិតផលប្រចាំខែ | J43: =I6 -> សីហា | K43: ឆ្នាំ២០២៦ (USD)
A44: ល.រ | B44: ឈ្មោះផលិតផល | D44: ឯកតា (Unit) | E44: ឈ្មោះប្រទេសនាំចេញផលិតផល | O44: សរុបពីដើមឆ្នាំ
...

Sheet 9-SEP
B1: ព្រះរាជាណាចក្រកម្ពុជា
B2: ជាត​ សានា ព្រះមហាក្សត្រ
G3: 
B4: របាយការណ៍ជូនក្រសួងឧស្សាហកម្ម វិទ្យាសាស្ត្រ បច្ចេកវិទ្យា និងនវានុវត្តន៍
B5: Report for Ministry of Industry, Science, Technology & Innovation
G6: ទិន្នន័យប្រចាំខែ | I6: កញ្ញា | J6: ឆ្នាំ 2026
G7: Monthly Data In September 2026
A9: ឈ្មោះរោងចក្រ:​​​​​​​​​​ ជេអ អឹភែរឹល ឯ.ក អាស័យដ្ឋានរោងចក្រៈ # ផ្លូវលំ ភូមិ កោះខ្នុរ ឃុំ ព្រែករកា ស្រុក កណ្ដាលស្ទឹង ខេត្ត កណ្ដាល ប្រកាសលេខៈ៤១៧ ឧស.កឧ.ប្រក១២ ចុះថ្ងៃទី ២៤​​ ខែ ធ្នូ ឆ្នាំ ២០១៨
A10: Name of Factory: JR APPAREL CO., LTD Factory Address: #LOM ROAD,KAOH KNOR PREAEK ROKA KANDAL STUENG​ KANDAL PROVINCE Prakas Number : 417
A11: ឈ្មោះអ្នកគ្រប់គ្រងរោងចក្រ NI, CUNLAN ទូរស័ព្ទៈ 855-85 441 621 ទូរសារ:.............................. អ៊ីម៉ែលៈ sanashipping8@gmail.com
A12: Manager Name: NI, CUNLAN Tel: 855-85 441 621 Fax:……………………… E-mail: sanashipping8@gmail.com
A13: ចំនួនពលកម្មសរុបៈ​​​ | C13: 148 | D13: ក្នុងនោះមានស្រីៈ | F13: 101 | H13: បៀរវត្សសរុបប្រចាំខែៈ | J13: 50419.75 | L13: USD
A14: Total Number of Employees: Persons Number of Females: Persons Total Salary & Wage of Monthly USD
A15: ទុនសរុបមិនគិតដីធ្លី Total Asset(Land exclude) | D15: 1000000 | F15: ទុនអចលនទ្រព្យមិនគិតដីធ្លី Total Fixed Asset (Land exclude) | J15: 1000000
A16: មុខផលិតផល Products | C16: ឯកតាUnit | D16: បរិមាណ និងតម្លៃផលិតផល Total Output
D17: ឆ្នាំមុន (Data Last Year) | H17: ទិន្នន័យប្រចាំខែ (Monthly Data) | L17: សរុបពីដើមឆ្នាំ (From beginning of the Year )
D18: ​ បរិមាណ Quantity | F18: តម្លៃ Value(USD) | H18: បរិមាណផលិតផល Product Quantity | J18: តម្លៃផលិតផល Product Value(USD) | L18: បរិមាណផលិតផល Product Quantity | N18: តម្លៃផលិតផល Product Value(USD)
D19: ក្នុងស្រុក Domestic | E19: នាំចេញ Export | F19: ក្នុងស្រុក Domestic | G19: នាំចេញ Export | H19: ក្នុងស្រុក Domestic | I19: នាំចេញ Export | J19: ក្នុងស្រុក Domestic | K19: នាំចេញ Export | L19: ក្នុងស្រុក Domestic | M19: នាំចេញ Export | N19: ក្នុងស្រុក Domestic | O19: នាំចេញ Export
A20: LADIES | B20: PANTS | C20: PCS | I20: 147962 | K20: =ROUND(I20*2.02726659547722,2) -> 299958.42 | M20: =I20+'8-AUG'!M20 -> 563295 | O20: =K20+'8-AUG'!O20 -> 1099025.7 | Q20: =M20+I20 -> 711257 | S20: =O20+K20 -> 1398984.1
A21: LADIES | B21: PAJAMAS | C21: PCS | M21: =I21+'8-AUG'!M21 -> 23698 | O21: =K21+'8-AUG'!O21 -> 344904.26
A22: LADIES | B22: SKIRT | C22: PCS | M22: =I22+'8-AUG'!M22 -> 81280 | O22: =K22+'8-AUG'!O22 -> 2855
A23: LADIES | B23: DRESS | C23: PCS | M23: =I23+'8-AUG'!M23 -> 576 | O23: =K23+'8-AUG'!O23 -> 267740.36 | Q23: =M23+I23 -> 576 | S23: =O23+K23 -> 267740.36
A24: LADIES | B24: NIGHT GOWN | C24: PCS | M24: =I24+'8-AUG'!M24 -> 3396 | O24: =K24+'8-AUG'!O24 -> 1532.16 | Q24: =M24+I24 -> 3396 | S24: =O24+K24 -> 1532.16
A25: LADIES | B25: TANK | C25: PCS | M25: =I25+'8-AUG'!M25 -> 1848 | O25: =K25+'8-AUG'!O25 -> 2272.8 | Q25: =M25+I25 -> 1848 | S25: =O25+K25 -> 2272.8
A26: LADIES | B26: SHORT | C26: PCS | M26: =I26+'8-AUG'!M26 -> 565651 | O26: =K26+'8-AUG'!O26 -> 2605.68 | Q26: =M26+I26 -> 565651 | S26: =O26+K26 -> 2605.68
A27: LADIES | B27: SKORT | C27: PCS | M27: =I27+'8-AUG'!M27 -> 1000 | O27: =K27+'8-AUG'!O27 -> 1950
A28: Total | E28: =SUM(E20:E26) -> 0 | G28: =SUM(G20:G26) -> 0 | I28: =SUM(I20:I27) -> 147962 | K28: =SUM(K20:K27) -> 299958.42 | M28: =SUM(M20:M27) -> 1240744 | O28: =SUM(O20:O27) -> 1722886
A29: សំគាល់ :​ ទិន្នន័យនៃរបាយការណ៍នេះត្រូវបានប្រើប្រាស់តែក្នុងគោលបំណង ស្ថិតិឧស្សាហកម្មតែប៉ុណ្ណោះ មិនត្រូវបានយកទៅចែកចាយដើម្បីប្រើប្រាស់
A30: ក្នុងគោលបំណងពាណិជ្ជកម្ម ឬក្នុងការគណនាបង់ពន្ធដារទេ។ | K30: ថ្ងៃទី 15 ខែ កញ្ញា ឆ្នាំ2026 | N30: =K30 -> ថ្ងៃទី 15 ខែ កញ្ញា ឆ្នាំ2026 | Q30: ថ្ងៃទី 15 ខែ កញ្ញា ឆ្នាំ2026
A31: Remark: This report is used for industrial statistic only,​ not for commercial or tax purpose | J31: ​​​​​​​​​​​​​​​​​​​ | K31: Date:……./……../…… | N31: Date:……./……../……
A32: ទុនអចលនទ្រព្យមិនគិតដីធ្លី រួមមាន៖ អគារ និងឧបករណ៍បរិក្ខារដែលភ្ជាប់នឹងអគារ | K32: នាយក | N32: អ្នកធ្វើរបាយការណ៍
A33: Total asset excluding land comprises of : building & material attached.
A34: ទុនសរុបមិនគិតដីធ្លី រួមមាន៖ ទុនអចលនទ្រព្យមិនគិតដីធ្លី, មធ្យោបាយដឹកជញ្ជូន, គ្រឿងចក្រ-ម៉ាស៊ីន និងឧបករណ៍សម្ភារប្រើប្រាស់ក្នុងផលិតកម្ម, សង្ហារឹម និងសម្ភារការិយាល័យ | K34: Director | N34: Reportor
A35: Total fixed asset excluding land comprises of : real estate capital excluding land, transportation, machinery, and instrument utilised in the production line,
A36: furniture and office equiment.
A37: ទំនាក់ទំនង : Tel 077 330 279/090 922 237 E-mail : industryaffair.mih@gmail.com : TELEGRAM :077 330 279
K41: NI, CUNLAN | N41: THNIN
B42: ឈ្មោះរោងចក្រ ជេអ​ អឹភែរឹល ឯ.ក
A43: ទីផ្សារលក់ផលិតផលប្រចាំខែ | J43: =I6 -> កញ្ញា | K43: ឆ្នាំ២០២៦ (USD)
A44: ល.រ | B44: ឈ្មោះផលិតផល | D44: ឯកតា (Unit) | E44: ឈ្មោះប្រទេសនាំចេញផលិតផល | O44: សរុបពីដើមឆ្នាំ
...
