Workbook

Sheet 01
A1: PAID | E1: REVENUE & EXPENSE | G1: THC | M1: Saturday
A2: CHEA PAYMENT | B2: PORT NUMBER | C2: PORT CODE | D2: PORT NAME | E2: DECLARE | F2: DATE | G2: CLIENT | H2: INV | I2: DISBURSEMENT | J2: DN | K2: DATE | L2: EXCHANGE RATE | M2: weekday | N2: CLEAR FEE | O2: THC | P2: CM | Q2: INV (REVENUE) | R2: REIM | S2: VAT 10% | T2: DN | U2: NET PROFIT | V2: MARK
A3: PAID | B3: 11 | C3: =INDEX(PORT!$B$2:$B$20,MATCH('01'!B3,PORT!$A$2:$A$20)) -> SHV11 | D3: =INDEX(PORT!$C$2:$C$20,MATCH('01'!B3,PORT!$A$2:$A$20)) -> SHV PORT | E3: I 4718 | F3: 46032 | G3: JR | H3: GS26-017 | I3: DIS017 | J3: JR2601001 | K3: 46034 | L3: 4025 | M3: =TEXT(K3,"dddd") -> Monday | N3: 620.2 | O3: 683 | P3: 5 | Q3: 180 | R3: 778.2 | S3: =ROUND(Q3*10%,2) -> 18 | T3: 620 | U3: =(Q3+R3+T3)-(N3+O3+P3) -> 270
A4: PAID | B4: 11 | C4: =INDEX(PORT!$B$2:$B$20,MATCH('01'!B4,PORT!$A$2:$A$20)) -> SHV11 | D4: =INDEX(PORT!$C$2:$C$20,MATCH('01'!B4,PORT!$A$2:$A$20)) -> SHV PORT | E4: I 4728 | F4: 46032 | G4: JR | K4: 46034 | L4: 4025 | M4: =TEXT(K4,"dddd") -> Monday | S4: =ROUND(Q4*10%,2) -> 0 | U4: =(Q4+R4+T4)-(N4+O4+P4) -> 0
A5: PAID | B5: 11 | C5: =INDEX(PORT!$B$2:$B$20,MATCH('01'!B5,PORT!$A$2:$A$20)) -> SHV11 | D5: =INDEX(PORT!$C$2:$C$20,MATCH('01'!B5,PORT!$A$2:$A$20)) -> SHV PORT | E5: I 14254 | F5: 46050 | G5: JR | H5: GS26-034 | I5: DIS034 | J5: JR2601002 | K5: 46051 | L5: 4027 | M5: =TEXT(K5,"dddd") -> Thursday | N5: 569.45 | O5: 691.5 | P5: 5 | Q5: 200 | R5: 805.95 | S5: =ROUND(Q5*10%,2) -> 20 | T5: 560 | U5: =(Q5+R5+T5)-(N5+O5+P5) -> 300
A6: PAID | B6: 11 | C6: =INDEX(PORT!$B$2:$B$20,MATCH('01'!B6,PORT!$A$2:$A$20)) -> SHV11 | D6: =INDEX(PORT!$C$2:$C$20,MATCH('01'!B6,PORT!$A$2:$A$20)) -> SHV PORT | E6: I 15940 | F6: 46052 | G6: JR | H6: GS26-036 | I6: DIS036 | J6: JR2601003 | K6: 46052 | L6: 4026 | M6: =TEXT(K6,"dddd") -> Friday | N6: 446.45 | O6: 476.5 | P6: 5 | Q6: 180 | R6: 557.95 | S6: =ROUND(Q6*10%,2) -> 18 | T6: 460 | U6: =(Q6+R6+T6)-(N6+O6+P6) -> 270
A7: PAID | B7: 1 | C7: =INDEX(PORT!$B$2:$B$20,MATCH('01'!B7,PORT!$A$2:$A$20)) -> PNH01 | D7: =INDEX(PORT!$C$2:$C$20,MATCH('01'!B7,PORT!$A$2:$A$20)) -> KTI AIR PORT | E7: E 222 | F7: 46025 | G7: JIN YUAN XI | H7: GS26-007 | I7: DIS007 | J7: JYX2601001 | K7: 46027 | L7: 4018 | M7: =TEXT(K7,"dddd") -> Monday | N7: 191.48 | P7: 50 | Q7: 175 | R7: 71.48 | S7: =ROUND(Q7*10%,2) -> 17.5 | T7: 180 | U7: =(Q7+R7+T7)-(N7+O7+P7) -> 185
A8: PAID | B8: 4 | C8: =INDEX(PORT!$B$2:$B$20,MATCH('01'!B8,PORT!$A$2:$A$20)) -> PNH04 | D8: =INDEX(PORT!$C$2:$C$20,MATCH('01'!B8,PORT!$A$2:$A$20)) -> PNH PORT | E8: E 4763 | F8: 46025 | G8: JIN YUAN XI | H8: GS26-008 | I8: DIS008 | J8: JYX2601002 | K8: 46027 | L8: 4018 | M8: =TEXT(K8,"dddd") -> Monday | N8: 538.85 | P8: 50 | Q8: 215 | R8: 93.85 | S8: =ROUND(Q8*10%,2) -> 21.5 | T8: 724 | U8: =(Q8+R8+T8)-(N8+O8+P8) -> 444
A9: PAID | B9: 1 | C9: =INDEX(PORT!$B$2:$B$20,MATCH('01'!B9,PORT!$A$2:$A$20)) -> PNH01 | D9: =INDEX(PORT!$C$2:$C$20,MATCH('01'!B9,PORT!$A$2:$A$20)) -> KTI AIR PORT | E9: I 672 | F9: 46030 | G9: JIN YUAN XI | H9: GS26-013 | I9: DIS013 | J9: JYX2601003 | K9: 46031 | L9: 4021 | M9: =TEXT(K9,"dddd") -> Friday | N9: 222.38 | P9: 50 | Q9: 150 | R9: 27.38 | S9: =ROUND(Q9*10%,2) -> 15 | T9: 195 | U9: =(Q9+R9+T9)-(N9+O9+P9) -> 100
A10: PAID | B10: 11 | C10: =INDEX(PORT!$B$2:$B$20,MATCH('01'!B10,PORT!$A$2:$A$20)) -> SHV11 | D10: =INDEX(PORT!$C$2:$C$20,MATCH('01'!B10,PORT!$A$2:$A$20)) -> SHV PORT | E10: E 7388 | F10: 46031 | G10: JIN YUAN XI | H10: GS26-015 | I10: DIS015 | J10: JYX2601004 | K10: 46034 | L10: 4025 | M10: =TEXT(K10,"dddd") -> Monday | N10: 373.95 | P10: 50 | Q10: 245 | R10: 73.95 | S10: =ROUND(Q10*10%,2) -> 24.5 | T10: 305 | U10: =(Q10+R10+T10)-(N10+O10+P10) -> 200
A11: PAID | B11: 1 | C11: =INDEX(PORT!$B$2:$B$20,MATCH('01'!B11,PORT!$A$2:$A$20)) -> PNH01 | D11: =INDEX(PORT!$C$2:$C$20,MATCH('01'!B11,PORT!$A$2:$A$20)) -> KTI AIR PORT | E11: E 1215 | F11: 46032 | G11: JIN YUAN XI | H11: GS26-016 | I11: DIS016 | J11: JXY2601005 | K11: 46034 | L11: 4025 | M11: =TEXT(K11,"dddd") -> Monday | N11: 308.34 | P11: 50 | Q11: 220 | R11: 188.34 | S11: =ROUND(Q11*10%,2) -> 22 | T11: 180 | U11: =(Q11+R11+T11)-(N11+O11+P11) -> 230
A12: PAID | B12: 1 | C12: =INDEX(PORT!$B$2:$B$20,MATCH('01'!B12,PORT!$A$2:$A$20)) -> PNH01 | D12: =INDEX(PORT!$C$2:$C$20,MATCH('01'!B12,PORT!$A$2:$A$20)) -> KTI AIR PORT | E12: I 1438 | F12: 46037 | G12: JIN YUAN XI | H12: GS26-021 | I12: DIS021 | J12: JYX2601006 | K12: 46038 | L12: 4026 | M12: =TEXT(K12,"dddd") -> Friday | N12: 242.62 | P12: 50 | Q12: 150 | R12: 47.62 | S12: =ROUND(Q12*10%,2) -> 15 | T12: 195 | U12: =(Q12+R12+T12)-(N12+O12+P12) -> 100
A13: PAID | B13: 11 | C13: =INDEX(PORT!$B$2:$B$20,MATCH('01'!B13,PORT!$A$2:$A$20)) -> SHV11 | D13: =INDEX(PORT!$C$2:$C$20,MATCH('01'!B13,PORT!$A$2:$A$20)) -> SHV PORT | E13: E 18060 | F13: 46038 | G13: JIN YUAN XI | H13: GS26-022 | I13: DIS022 | J13: JYX2601007 | K13: 46041 | L13: 4027 | M13: =TEXT(K13,"dddd") -> Monday | N13: 958.54 | P13: 50 | Q13: 490 | R13: 198.55 | S13: =ROUND(Q13*10%,2) -> 49 | T13: 955 | U13: =(Q13+R13+T13)-(N13+O13+P13) -> 635.01
A14: PAID | B14: 11 | C14: =INDEX(PORT!$B$2:$B$20,MATCH('01'!B14,PORT!$A$2:$A$20)) -> SHV11 | D14: =INDEX(PORT!$C$2:$C$20,MATCH('01'!B14,PORT!$A$2:$A$20)) -> SHV PORT | E14: E 19191 | F14: 46039 | G14: JIN YUAN XI | H14: GS26-024 | I14: DIS024 | J14: JYX2601008 | K14: 46041 | L14: 4027 | M14: =TEXT(K14,"dddd") -> Monday | N14: 678.84 | P14: 50 | Q14: 245 | R14: 118.84 | S14: =ROUND(Q14*10%,2) -> 24.5 | T14: 879 | U14: =(Q14+R14+T14)-(N14+O14+P14) -> 514
A15: PAID | B15: 1 | C15: =INDEX(PORT!$B$2:$B$20,MATCH('01'!B15,PORT!$A$2:$A$20)) -> PNH01 | D15: =INDEX(PORT!$C$2:$C$20,MATCH('01'!B15,PORT!$A$2:$A$20)) -> KTI AIR PORT | E15: E 3591 | F15: 46046 | G15: JIN YUAN XI | H15: GS26-030 | I15: DIS030 | J15: JYX2601009 | K15: 46048 | L15: 4029 | M15: =TEXT(K15,"dddd") -> Monday | N15: 344.77 | P15: 50 | Q15: 220 | R15: 224.77 | S15: =ROUND(Q15*10%,2) -> 22 | T15: 180 | U15: =(Q15+R15+T15)-(N15+O15+P15) -> 230
A16: PAID | B16: 1 | C16: =INDEX(PORT!$B$2:$B$20,MATCH('01'!B16,PORT!$A$2:$A$20)) -> PNH01 | D16: =INDEX(PORT!$C$2:$C$20,MATCH('01'!B16,PORT!$A$2:$A$20)) -> KTI AIR PORT | E16: E 3640 | F16: 46046 | G16: JIN YUAN XI | H16: GS26-031 | I16: DIS031 | J16: JYX2601010 | K16: 46048 | L16: 4029 | M16: =TEXT(K16,"dddd") -> Monday | N16: 152.93 | P16: 50 | Q16: 140 | R16: 32.93 | S16: =ROUND(Q16*10%,2) -> 14 | T16: 180 | U16: =(Q16+R16+T16)-(N16+O16+P16) -> 150
A17: PAID | B17: 23 | C17: =INDEX(PORT!$B$2:$B$20,MATCH('01'!B17,PORT!$A$2:$A$20)) -> PNH23 | D17: =INDEX(PORT!$C$2:$C$20,MATCH('01'!B17,PORT!$A$2:$A$20)) -> UNION DRY PORT | E17: I 80 | F17: 46049 | G17: JIN YUAN XI | H17: GS26-032 | I17: DIS032 | J17: JYX2601011 | K17: 46050 | L17: 4025 | M17: =TEXT(K17,"dddd") -> Wednesday | N17: 343.21 | O17: 456.89 | P17: 50 | Q17: 150 | R17: 560.1 | S17: =ROUND(Q17*10%,2) -> 15 | T17: 350 | U17: =(Q17+R17+T17)-(N17+O17+P17) -> 210
A18: PAID | B18: 1 | C18: =INDEX(PORT!$B$2:$B$20,MATCH('01'!B18,PORT!$A$2:$A$20)) -> PNH01 | D18: =INDEX(PORT!$C$2:$C$20,MATCH('01'!B18,PORT!$A$2:$A$20)) -> KTI AIR PORT | E18: I 3142 | F18: 46052 | G18: JIN YUAN XI | H18: GS26-035 | I18: DIS035 | J18: JYX2601012 | K18: 46052 | L18: 4026 | M18: =TEXT(K18,"dddd") -> Friday | N18: 310.38 | P18: 50 | Q18: 185 | R18: 115.38 | S18: =ROUND(Q18*10%,2) -> 18.5 | T18: 195 | U18: =(Q18+R18+T18)-(N18+O18+P18) -> 135
A19: PAID | B19: 21 | C19: =INDEX(PORT!$B$2:$B$20,MATCH('01'!B19,PORT!$A$2:$A$20)) -> PNH21 | D19: =INDEX(PORT!$C$2:$C$20,MATCH('01'!B19,PORT!$A$2:$A$20)) -> OLAIR DRY PORT | E19: I 30 | F19: 46024 | G19: SPORTLINE | H19: GS26-006 | I19: DIS006 | J19: SAK2601001 | K19: 46027 | L19: 4018 | M19: =TEXT(K19,"dddd") -> Monday | N19: 132.58 | P19: 50 | Q19: 150 | R19: 27.58 | S19: =ROUND(Q19*10%,2) -> 15 | T19: 120 | U19: =(Q19+R19+T19)-(N19+O19+P19) -> 115
A20: PAID | B20: 4 | C20: =INDEX(PORT!$B$2:$B$20,MATCH('01'!B20,PORT!$A$2:$A$20)) -> PNH04 | D20: =INDEX(PORT!$C$2:$C$20,MATCH('01'!B20,PORT!$A$2:$A$20)) -> PNH PORT | E20: E 10353 | F20: 46031 | G20: SPORTLINE | H20: GS26-014 | I20: DIS014 | J20: SAK2601002 | K20: 46034 | L20: 4025 | M20: =TEXT(K20,"dddd") -> Monday | N20: 937.76 | P20: 50 | Q20: 490 | R20: 267.76 | S20: =ROUND(Q20*10%,2) -> 49 | T20: 740 | U20: =(Q20+R20+T20)-(N20+O20+P20) -> 510
A21: PAID | B21: 21 | C21: =INDEX(PORT!$B$2:$B$20,MATCH('01'!B21,PORT!$A$2:$A$20)) -> PNH21 | D21: =INDEX(PORT!$C$2:$C$20,MATCH('01'!B21,PORT!$A$2:$A$20)) -> OLAIR DRY PORT | E21: I 242 | F21: 46035 | G21: SPORTLINE | H21: GS26-019 | I21: DIS019 | J21: SAK2601003 | K21: 46036 | L21: 4025 | M21: =TEXT(K21,"dddd") -> Wednesday | N21: 177.18 | O21: 449.63 | P21: 50 | Q21: 150 | R21: 511.81 | S21: =ROUND(Q21*10%,2) -> 15 | T21: 145 | U21: =(Q21+R21+T21)-(N21+O21+P21) -> 130
A22: PAID | D22: HP260134-1/30 | E22: THC | I22: DIS038 | K22: 46053 | O22: 344.43 | R22: 344.43 | U22: =(Q22+R22+T22)-(N22+O22+P22) -> 0
A23: PAID | B23: 1 | C23: =INDEX(PORT!$B$2:$B$20,MATCH('01'!B23,PORT!$A$2:$A$20)) -> PNH01 | D23: =INDEX(PORT!$C$2:$C$20,MATCH('01'!B23,PORT!$A$2:$A$20)) -> KTI AIR PORT | E23: E 94 | F23: 46024 | G23: VFL | H23: GS26-001 | I23: DIS001 | J23: VFL2601001 | K23: 46027 | L23: 4018 | M23: =TEXT(K23,"dddd") -> Monday | N23: 113.76 | P23: 50 | Q23: 150 | R23: 43.76 | S23: =ROUND(Q23*10%,2) -> 15 | T23: 60 | U23: =(Q23+R23+T23)-(N23+O23+P23) -> 90
A24: PAID | B24: 11 | C24: =INDEX(PORT!$B$2:$B$20,MATCH('01'!B24,PORT!$A$2:$A$20)) -> SHV11 | D24: =INDEX(PORT!$C$2:$C$20,MATCH('01'!B24,PORT!$A$2:$A$20)) -> SHV PORT | E24: E 3685 | F24: 46024 | G24: VFL | H24: GS26-002 | I24: DIS002 | J24: VFL2601002 | K24: 46027 | L24: 4018 | M24: =TEXT(K24,"dddd") -> Monday | N24: 400.95 | P24: 50 | Q24: 215 | R24: 95.95 | S24: =ROUND(Q24*10%,2) -> 21.5 | T24: 285 | U24: =(Q24+R24+T24)-(N24+O24+P24) -> 145
A25: PAID | B25: 1 | C25: =INDEX(PORT!$B$2:$B$20,MATCH('01'!B25,PORT!$A$2:$A$20)) -> PNH01 | D25: =INDEX(PORT!$C$2:$C$20,MATCH('01'!B25,PORT!$A$2:$A$20)) -> KTI AIR PORT | E25: I 21 | F25: 46024 | G25: VFL | H25: GS26-003 | I25: DIS003 | J25: VFL2601003 | K25: 46027 | L25: 4018 | M25: =TEXT(K25,"dddd") -> Monday | N25: 151.05 | P25: 50 | Q25: 150 | R25: 9.55 | S25: =ROUND(Q25*10%,2) -> 15 | T25: 106.5 | U25: =(Q25+R25+T25)-(N25+O25+P25) -> 65
A26: PAID | B26: 21 | C26: =INDEX(PORT!$B$2:$B$20,MATCH('01'!B26,PORT!$A$2:$A$20)) -> PNH21 | D26: =INDEX(PORT!$C$2:$C$20,MATCH('01'!B26,PORT!$A$2:$A$20)) -> OLAIR DRY PORT | E26: I 23 | F26: 46024 | G26: VFL | H26: GS26-004 | I26: DIS004 | J26: VFL2601004 | K26: 46027 | L26: 4018 | M26: =TEXT(K26,"dddd") -> Monday | N26: 113.23 | P26: 50 | Q26: 150 | R26: 28.23 | S26: =ROUND(Q26*10%,2) -> 15 | T26: 90 | U26: =(Q26+R26+T26)-(N26+O26+P26) -> 105
A27: PAID | B27: 11 | C27: =INDEX(PORT!$B$2:$B$20,MATCH('01'!B27,PORT!$A$2:$A$20)) -> SHV11 | D27: =INDEX(PORT!$C$2:$C$20,MATCH('01'!B27,PORT!$A$2:$A$20)) -> SHV PORT | E27: I 342 | F27: 46024 | G27: VFL | H27: GS26-005 | I27: DIS005 | J27: VFL2601005 | K27: 46027 | L27: 4018 | M27: =TEXT(K27,"dddd") -> Monday | N27: 164.49 | P27: 50 | Q27: 150 | R27: 17.12 | S27: =ROUND(Q27*10%,2) -> 15 | T27: 106.38 | U27: =(Q27+R27+T27)-(N27+O27+P27) -> 59.01
A28: PAID | B28: 1 | C28: =INDEX(PORT!$B$2:$B$20,MATCH('01'!B28,PORT!$A$2:$A$20)) -> PNH01 | D28: =INDEX(PORT!$C$2:$C$20,MATCH('01'!B28,PORT!$A$2:$A$20)) -> KTI AIR PORT | E28: E 575 | F28: 46028 | G28: VFL | H28: GS26-009 | I28: DIS009 | J28: VFL2601006 | K28: 46030 | L28: 4021 | M28: =TEXT(K28,"dddd") -> Thursday | N28: 102.76 | O28: 60.5 | P28: 50 | Q28: 140 | R28: 32.76 | S28: =ROUND(Q28*10%,2) -> 14 | T28: 60 | U28: =(Q28+R28+T28)-(N28+O28+P28) -> 19.5
A29: PAID | B29: 16 | C29: =INDEX(PORT!$B$2:$B$20,MATCH('01'!B29,PORT!$A$2:$A$20)) -> PNH16 | D29: =INDEX(PORT!$C$2:$C$20,MATCH('01'!B29,PORT!$A$2:$A$20)) -> DRYPORT ROYAL RAILWAY | E29: I 23 | F29: 46028 | G29: VFL | H29: GS26-010 | I29: DIS010 | J29: VFL2601007 | K29: 46030 | L29: 4021 | M29: =TEXT(K29,"dddd") -> Thursday | N29: 150.36 | O29: 194.61 | P29: 50 | Q29: 150 | R29: 259.97 | S29: =ROUND(Q29*10%,2) -> 15 | T29: 90 | U29: =(Q29+R29+T29)-(N29+O29+P29) -> 105
A30: PAID | B30: 1 | C30: =INDEX(PORT!$B$2:$B$20,MATCH('01'!B30,PORT!$A$2:$A$20)) -> PNH01 | D30: =INDEX(PORT!$C$2:$C$20,MATCH('01'!B30,PORT!$A$2:$A$20)) -> KTI AIR PORT | E30: I 432 | F30: 46028 | G30: VFL | H30: GS26-011 | I30: DIS011 | J30: VFL2601008 | K30: 46030 | L30: 4021 | M30: =TEXT(K30,"dddd") -> Thursday | N30: 156.95 | P30: 50 | Q30: 150 | R30: 15.45 | S30: =ROUND(Q30*10%,2) -> 15 | T30: 106.5 | U30: =(Q30+R30+T30)-(N30+O30+P30) -> 65
A31: PAID | B31: 1 | C31: =INDEX(PORT!$B$2:$B$20,MATCH('01'!B31,PORT!$A$2:$A$20)) -> PNH01 | D31: =INDEX(PORT!$C$2:$C$20,MATCH('01'!B31,PORT!$A$2:$A$20)) -> KTI AIR PORT | E31: I 595 | F31: 46030 | G31: VFL | H31: GS26-012 | I31: DIS012 | J31: VFL2601009 | K31: 46031 | L31: 4021 | M31: =TEXT(K31,"dddd") -> Friday | N31: 153.52 | O31: 60.5 | P31: 50 | Q31: 150 | R31: 72.52 | S31: =ROUND(Q31*10%,2) -> 15 | T31: 106.5 | U31: =(Q31+R31+T31)-(N31+O31+P31) -> 65
A32: PAID | B32: 1 | C32: =INDEX(PORT!$B$2:$B$20,MATCH('01'!B32,PORT!$A$2:$A$20)) -> PNH01 | D32: =INDEX(PORT!$C$2:$C$20,MATCH('01'!B32,PORT!$A$2:$A$20)) -> KTI AIR PORT | E32: I 1202 | F32: 46035 | G32: VFL | H32: GS26-018 | I32: DIS018 | J32: VFL2601010 | K32: 46036 | L32: 4025 | M32: =TEXT(K32,"dddd") -> Wednesday | N32: 209.66 | P32: 50 | Q32: 150 | R32: 90.16 | S32: =ROUND(Q32*10%,2) -> 15 | T32: 215 | U32: =(Q32+R32+T32)-(N32+O32+P32) -> 195.5
A33: PAID | B33: 1 | C33: =INDEX(PORT!$B$2:$B$20,MATCH('01'!B33,PORT!$A$2:$A$20)) -> PNH01 | D33: =INDEX(PORT!$C$2:$C$20,MATCH('01'!B33,PORT!$A$2:$A$20)) -> KTI AIR PORT | E33: E 1692 | F33: 46036 | G33: VFL | H33: GS26-020 | I33: DIS020 | J33: VFL2601011 | K33: 46037 | L33: 4026 | M33: =TEXT(K33,"dddd") -> Thursday | N33: 111.47 | P33: 50 | Q33: 150 | R33: 41.47 | S33: =ROUND(Q33*10%,2) -> 15 | T33: 60 | U33: =(Q33+R33+T33)-(N33+O33+P33) -> 90
A34: PAID | B34: 11+ | C34: =INDEX(PORT!$B$2:$B$20,MATCH('01'!B34,PORT!$A$2:$A$20)) -> SVR11 | D34: =INDEX(PORT!$C$2:$C$20,MATCH('01'!B34,PORT!$A$2:$A$20)) -> BAVET CEO | E34: I 1541 | F34: 46039 | G34: VFL | H34: GS26-023 | I34: DIS023 | J34: VFL2601012 | K34: 46041 | L34: 4027 | M34: =TEXT(K34,"dddd") -> Monday | N34: 133.75 | P34: 50 | Q34: 230 | R34: 2.25 | S34: =ROUND(Q34*10%,2) -> 23 | T34: 66.5 | U34: =(Q34+R34+T34)-(N34+O34+P34) -> 115
A35: PAID | B35: 1 | C35: =INDEX(PORT!$B$2:$B$20,MATCH('01'!B35,PORT!$A$2:$A$20)) -> PNH01 | D35: =INDEX(PORT!$C$2:$C$20,MATCH('01'!B35,PORT!$A$2:$A$20)) -> KTI AIR PORT | E35: E 2274 | F35: 46039 | G35: VFL | H35: GS26-025 | I35: DIS025 | J35: VFL2601013 | K35: 46041 | L35: 4027 | M35: =TEXT(K35,"dddd") -> Monday | N35: 90.97 | P35: 50 | Q35: 140 | R35: 20.97 | S35: =ROUND(Q35*10%,2) -> 14 | T35: 60 | U35: =(Q35+R35+T35)-(N35+O35+P35) -> 80
A36: PAID | B36: 1 | C36: =INDEX(PORT!$B$2:$B$20,MATCH('01'!B36,PORT!$A$2:$A$20)) -> PNH01 | D36: =INDEX(PORT!$C$2:$C$20,MATCH('01'!B36,PORT!$A$2:$A$20)) -> KTI AIR PORT | E36: E 2398 | F36: 46041 | G36: VFL | H36: GS26-026 | I36: DIS026 | J36: VFL2601014 | K36: 46042 | L36: 4027 | M36: =TEXT(K36,"dddd") -> Tuesday | N36: 105.4 | P36: 50 | Q36: 140 | R36: 35.4 | S36: =ROUND(Q36*10%,2) -> 14 | T36: 60 | U36: =(Q36+R36+T36)-(N36+O36+P36) -> 80
A37: PAID | B37: 23 | C37: =INDEX(PORT!$B$2:$B$20,MATCH('01'!B37,PORT!$A$2:$A$20)) -> PNH23 | D37: =INDEX(PORT!$C$2:$C$20,MATCH('01'!B37,PORT!$A$2:$A$20)) -> UNION DRY PORT | E37: I 361 | F37: 46043 | G37: VFL | H37: GS26-027 | I37: DIS027 | J37: VFL2601015 | K37: 46044 | L37: 4030 | M37: =TEXT(K37,"dddd") -> Thursday | N37: 218.17 | O37: 674.58 | P37: 50 | Q37: 150 | R37: 772.5 | S37: =ROUND(Q37*10%,2) -> 15 | T37: 150 | U37: =(Q37+R37+T37)-(N37+O37+P37) -> 129.75
A38: PAID | B38: 1 | C38: =INDEX(PORT!$B$2:$B$20,MATCH('01'!B38,PORT!$A$2:$A$20)) -> PNH01 | D38: =INDEX(PORT!$C$2:$C$20,MATCH('01'!B38,PORT!$A$2:$A$20)) -> KTI AIR PORT | E38: E 3105 | F38: 46045 | G38: VFL | H38: GS26-028 | I38: DIS028 | J38: VFL2601016 | K38: 46048 | L38: 4029 | M38: =TEXT(K38,"dddd") -> Monday | N38: 90.17 | P38: 50 | Q38: 140 | R38: 20.17 | S38: =ROUND(Q38*10%,2) -> 14 | T38: 60 | U38: =(Q38+R38+T38)-(N38+O38+P38) -> 80
A39: PAID | B39: 11 | C39: =INDEX(PORT!$B$2:$B$20,MATCH('01'!B39,PORT!$A$2:$A$20)) -> SHV11 | D39: =INDEX(PORT!$C$2:$C$20,MATCH('01'!B39,PORT!$A$2:$A$20)) -> SHV PORT | E39: I 12059 | F39: 46045 | G39: VFL | H39: GS26-029 | I39: DIS029 | J39: VFL2601017 | K39: 46048 | L39: 4029 | M39: =TEXT(K39,"dddd") -> Monday | N39: 140.43 | O39: 299.2 | P39: 50 | Q39: 150 | R39: 314.63 | S39: =ROUND(Q39*10%,2) -> 15 | T39: 106.45 | U39: =(Q39+R39+T39)-(N39+O39+P39) -> 81.45
A40: PAID | B40: 1 | C40: =INDEX(PORT!$B$2:$B$20,MATCH('01'!B40,PORT!$A$2:$A$20)) -> PNH01 | D40: =INDEX(PORT!$C$2:$C$20,MATCH('01'!B40,PORT!$A$2:$A$20)) -> KTI AIR PORT | E40: I 2739 | F40: 46049 | G40: VFL | H40: GS26-033 | I40: DIS033 | J40: VFL2601018 | K40: 46050 | L40: 4025 | M40: =TEXT(K40,"dddd") -> Wednesday | N40: 152.8 | O40: 110 | P40: 50 | Q40: 150 | R40: 132.8 | S40: =ROUND(Q40*10%,2) -> 15 | T40: 95 | U40: =(Q40+R40+T40)-(N40+O40+P40) -> 65
...

Sheet 02
E1: REVENUE & EXPENSE | M1: Saturday
A2: CHEA PAYMENT | B2: PORT NUMBER | C2: PORT CODE | D2: PORT NAME | E2: DECLARE | F2: DATE | G2: CLIENT | H2: INV | I2: DISBURSEMENT | J2: DN | K2: DATE | L2: EXCHANGE RATE | M2: weekday | N2: CLEAR FEE | O2: THC | P2: CM | Q2: INV (REVENUE) | R2: REIM | S2: VAT 10% | T2: DN | U2: NET PROFIT | V2: MARK
A3: PAID | B3: 1 | C3: =INDEX(PORT!$B$2:$B$20,MATCH('02'!B3,PORT!$A$2:$A$20)) -> PNH01 | D3: =INDEX(PORT!$C$2:$C$20,MATCH('02'!B3,PORT!$A$2:$A$20)) -> KTI AIR PORT | E3: I 3370 | F3: 46055 | G3: JIN YUAN XI | H3: GS26-037 | I3: DIS039 | J3: JYX2602001 | K3: 46056 | L3: =VLOOKUP(K3,'[1]Exchange Rate'!$A$3:$C$15,3,FALSE) -> 4031 | M3: =TEXT(K3,"dddd") -> Tuesday | N3: 312.14 | P3: 50 | Q3: 185 | R3: 117.14 | S3: =ROUND(Q3*10%,2) -> 18.5 | T3: 195 | U3: =(Q3+R3+T3)-(N3+O3+P3) -> 135
A4: PAID | B4: 21 | C4: =INDEX(PORT!$B$2:$B$20,MATCH('02'!B4,PORT!$A$2:$A$20)) -> PNH21 | D4: =INDEX(PORT!$C$2:$C$20,MATCH('02'!B4,PORT!$A$2:$A$20)) -> OLAIR DRY PORT | E4: I 491 | F4: 46055 | G4: SPORTLINE | H4: GS26-038 | I4: DIS040 | J4: SAK2602001 | K4: 46056 | L4: =VLOOKUP(K4,'[1]Exchange Rate'!$A$3:$C$15,3,FALSE) -> 4031 | M4: =TEXT(K4,"dddd") -> Tuesday | N4: 154.34 | O4: 344.43 | P4: 50 | Q4: 150 | R4: 39.34 | S4: =ROUND(Q4*10%,2) -> 15 | T4: 145 | U4: =(Q4+R4+T4)-(N4+P4) -> 130
A5: PAID | B5: 1 | C5: =INDEX(PORT!$B$2:$B$20,MATCH('02'!B5,PORT!$A$2:$A$20)) -> PNH01 | D5: =INDEX(PORT!$C$2:$C$20,MATCH('02'!B5,PORT!$A$2:$A$20)) -> KTI AIR PORT | E5: I 3378 | F5: 46055 | G5: SPORTLINE | H5: GS26-039 | I5: DIS041 | J5: SAK2602002 | K5: 46056 | L5: =VLOOKUP(K5,'[1]Exchange Rate'!$A$3:$C$15,3,FALSE) -> 4031 | M5: =TEXT(K5,"dddd") -> Tuesday | N5: 174.38 | O5: 60.5 | P5: 50 | Q5: 150 | R5: 84.88 | S5: =ROUND(Q5*10%,2) -> 15 | T5: 165 | U5: =(Q5+R5+T5)-(N5+O5+P5) -> 115
A6: PAID | B6: 1 | C6: =INDEX(PORT!$B$2:$B$20,MATCH('02'!B6,PORT!$A$2:$A$20)) -> PNH01 | D6: =INDEX(PORT!$C$2:$C$20,MATCH('02'!B6,PORT!$A$2:$A$20)) -> KTI AIR PORT | E6: E 5316 | F6: 46057 | G6: VFL | H6: GS26-040 | I6: DIS042 | J6: VFL2602001 | K6: 46058 | L6: =VLOOKUP(K6,'[1]Exchange Rate'!$A$3:$C$15,3,FALSE) -> 4033 | M6: =TEXT(K6,"dddd") -> Thursday | N6: 104.43 | O6: 0 | P6: 50 | Q6: 140 | R6: 34.43 | S6: =ROUND(Q6*10%,2) -> 14 | T6: 60 | U6: =(Q6+R6+T6)-(N6+O6+P6) -> 80
A7: PAID | B7: 19 | C7: =INDEX(PORT!$B$2:$B$20,MATCH('02'!B7,PORT!$A$2:$A$20)) -> PNH19 | D7: =INDEX(PORT!$C$2:$C$20,MATCH('02'!B7,PORT!$A$2:$A$20)) -> TEC SRUN DRYPORT | E7: I 420 | F7: 46057 | G7: VFL | H7: GS26-041 | I7: DIS043 | J7: VFL2602002 | K7: 46058 | L7: =VLOOKUP(K7,'[1]Exchange Rate'!$A$3:$C$15,3,FALSE) -> 4033 | M7: =TEXT(K7,"dddd") -> Thursday | N7: 111.1 | O7: 204.97 | P7: 50 | Q7: 150 | R7: 231.07 | S7: =ROUND(Q7*10%,2) -> 15 | T7: 90 | U7: =(Q7+R7+T7)-(N7+O7+P7) -> 105
A8: PAID | B8: 19 | C8: =INDEX(PORT!$B$2:$B$20,MATCH('02'!B8,PORT!$A$2:$A$20)) -> PNH19 | D8: =INDEX(PORT!$C$2:$C$20,MATCH('02'!B8,PORT!$A$2:$A$20)) -> TEC SRUN DRYPORT | E8: I 421 | F8: 46057 | G8: SPORTLINE | H8: GS26-042 | I8: DIS044 | J8: SAK2602003 | K8: 46058 | L8: =VLOOKUP(K8,'[1]Exchange Rate'!$A$3:$C$15,3,FALSE) -> 4033 | M8: =TEXT(K8,"dddd") -> Thursday | N8: 160.06 | O8: 403.19 | P8: 50 | Q8: 150 | R8: 448.25 | S8: =ROUND(Q8*10%,2) -> 15 | T8: 145 | U8: =(Q8+R8+T8)-(N8+O8+P8) -> 130
A9: PAID | B9: 1 | C9: =INDEX(PORT!$B$2:$B$20,MATCH('02'!B9,PORT!$A$2:$A$20)) -> PNH01 | D9: =INDEX(PORT!$C$2:$C$20,MATCH('02'!B9,PORT!$A$2:$A$20)) -> KTI AIR PORT | E9: E 5458 | F9: 46058 | G9: VFL | H9: GS26-043 | I9: DIS045 | J9: VFL2602003 | K9: 46059 | L9: =VLOOKUP(K9,'[1]Exchange Rate'!$A$3:$C$15,3,FALSE) -> 4033 | M9: =TEXT(K9,"dddd") -> Friday | N9: 83.75 | O9: 0 | P9: 50 | Q9: 140 | R9: 2 | S9: =ROUND(Q9*10%,2) -> 14 | T9: 71.75 | U9: =(Q9+R9+T9)-(N9+O9+P9) -> 80
A10: PAID | B10: 1 | C10: =INDEX(PORT!$B$2:$B$20,MATCH('02'!B10,PORT!$A$2:$A$20)) -> PNH01 | D10: =INDEX(PORT!$C$2:$C$20,MATCH('02'!B10,PORT!$A$2:$A$20)) -> KTI AIR PORT | E10: E 5466 | F10: 46058 | G10: VFL | H10: GS26-044 | I10: DIS046 | J10: VFL2602004 | K10: 46059 | L10: =VLOOKUP(K10,'[1]Exchange Rate'!$A$3:$C$15,3,FALSE) -> 4033 | M10: =TEXT(K10,"dddd") -> Friday | N10: 88.24 | O10: 0 | P10: 50 | Q10: 140 | R10: 18.24 | S10: =ROUND(Q10*10%,2) -> 14 | T10: 60 | U10: =(Q10+R10+T10)-(N10+O10+P10) -> 80
A11: PAID | B11: 1 | C11: =INDEX(PORT!$B$2:$B$20,MATCH('02'!B11,PORT!$A$2:$A$20)) -> PNH01 | D11: =INDEX(PORT!$C$2:$C$20,MATCH('02'!B11,PORT!$A$2:$A$20)) -> KTI AIR PORT | E11: E 5467 | F11: 46058 | G11: JIN YUAN XI | H11: GS26-045 | I11: DIS047 | J11: JYX2602002 | K11: 46059 | L11: =VLOOKUP(K11,'[1]Exchange Rate'!$A$3:$C$15,3,FALSE) -> 4033 | M11: =TEXT(K11,"dddd") -> Friday | N11: 182.24 | O11: 0 | P11: 50 | Q11: 175 | R11: 62.24 | S11: =ROUND(Q11*10%,2) -> 17.5 | T11: 180 | U11: =(Q11+R11+T11)-(N11+O11+P11) -> 185
A12: PAID | B12: 1 | C12: =INDEX(PORT!$B$2:$B$20,MATCH('02'!B12,PORT!$A$2:$A$20)) -> PNH01 | D12: =INDEX(PORT!$C$2:$C$20,MATCH('02'!B12,PORT!$A$2:$A$20)) -> KTI AIR PORT | E12: I 3813 | F12: 46058 | G12: JIN YUAN XI | H12: GS26-046 | I12: DIS048 | J12: JYX2602003 | K12: 46059 | L12: =VLOOKUP(K12,'[1]Exchange Rate'!$A$3:$C$15,3,FALSE) -> 4033 | M12: =TEXT(K12,"dddd") -> Friday | N12: 288.02 | O12: 0 | P12: 50 | Q12: 165 | R12: 93.02 | S12: =ROUND(Q12*10%,2) -> 16.5 | T12: 195 | U12: =(Q12+R12+T12)-(N12+O12+P12) -> 115
A13: PAID | B13: 4 | C13: =INDEX(PORT!$B$2:$B$20,MATCH('02'!B13,PORT!$A$2:$A$20)) -> PNH04 | D13: =INDEX(PORT!$C$2:$C$20,MATCH('02'!B13,PORT!$A$2:$A$20)) -> PNH PORT | E13: E 35089 | F13: 46058 | G13: SPORTLINE | H13: GS26-047 | I13: DIS049 | J13: SAK2602004 | K13: 46059 | L13: =VLOOKUP(K13,'[1]Exchange Rate'!$A$3:$C$15,3,FALSE) -> 4033 | M13: =TEXT(K13,"dddd") -> Friday | N13: 495.75 | O13: 0 | P13: 50 | Q13: 245 | R13: 135.75 | S13: =ROUND(Q13*10%,2) -> 24.5 | T13: 405 | U13: =(Q13+R13+T13)-(N13+O13+P13) -> 240
A14: PAID | B14: 11 | C14: =INDEX(PORT!$B$2:$B$20,MATCH('02'!B14,PORT!$A$2:$A$20)) -> SHV11 | D14: =INDEX(PORT!$C$2:$C$20,MATCH('02'!B14,PORT!$A$2:$A$20)) -> SHV PORT | E14: I 21065 | F14: 46062 | G14: JR | H14: GS26-048 | I14: DIS050 | J14: JR2602001 | K14: 46063 | L14: =VLOOKUP(K14,'[1]Exchange Rate'!$A$3:$C$15,3,FALSE) -> 4031 | M14: =TEXT(K14,"dddd") -> Tuesday | N14: 569.45 | O14: 691.5 | P14: 5 | Q14: 200 | R14: 805.95 | S14: =ROUND(Q14*10%,2) -> 20 | T14: 605 | U14: =(Q14+R14+T14)-(N14+O14+P14) -> 345
G15: JR | J15: JR2602002 | K15: 46070 | M15: =TEXT(K15,"dddd") -> Tuesday | N15: 120 | O15: 0 | P15: 0 | T15: 120 | U15: =(Q15+R15+T15)-(N15+O15+P15) -> 0
A16: PAID | B16: 1 | C16: =INDEX(PORT!$B$2:$B$20,MATCH('02'!B16,PORT!$A$2:$A$20)) -> PNH01 | D16: =INDEX(PORT!$C$2:$C$20,MATCH('02'!B16,PORT!$A$2:$A$20)) -> KTI AIR PORT | E16: I 4343 | F16: 46063 | G16: VFL | H16: GS26-049 | I16: DIS051 | J16: VFL2602005 | K16: 46064 | L16: =VLOOKUP(K16,'[1]Exchange Rate'!$A$3:$C$15,3,FALSE) -> 4029 | M16: =TEXT(K16,"dddd") -> Wednesday | N16: 151.92 | O16: 60.5 | P16: 50 | Q16: 150 | R16: 82.42 | S16: =ROUND(Q16*10%,2) -> 15 | T16: 95 | U16: =(Q16+R16+T16)-(N16+O16+P16) -> 65
A17: PAID | B17: 1 | C17: =INDEX(PORT!$B$2:$B$20,MATCH('02'!B17,PORT!$A$2:$A$20)) -> PNH01 | D17: =INDEX(PORT!$C$2:$C$20,MATCH('02'!B17,PORT!$A$2:$A$20)) -> KTI AIR PORT | E17: E 6104 | F17: 46063 | G17: JIN YUAN XI | H17: GS26-050 | I17: DIS052 | J17: JYX2602004 | K17: 46064 | L17: =VLOOKUP(K17,'[1]Exchange Rate'!$A$3:$C$15,3,FALSE) -> 4029 | M17: =TEXT(K17,"dddd") -> Wednesday | N17: 86.48 | O17: 0 | P17: 50 | Q17: 140 | R17: 16.48 | S17: =ROUND(Q17*10%,2) -> 14 | T17: 60 | U17: =(Q17+R17+T17)-(N17+O17+P17) -> 80
A18: PAID | B18: 21 | C18: =INDEX(PORT!$B$2:$B$20,MATCH('02'!B18,PORT!$A$2:$A$20)) -> PNH21 | D18: =INDEX(PORT!$C$2:$C$20,MATCH('02'!B18,PORT!$A$2:$A$20)) -> OLAIR DRY PORT | E18: I 588 | F18: 46063 | G18: SPORTLINE | H18: GS26-051 | I18: DIS053 | J18: SAK2602005 | K18: 46064 | L18: =VLOOKUP(K18,'[1]Exchange Rate'!$A$3:$C$15,3,FALSE) -> 4029 | M18: =TEXT(K18,"dddd") -> Wednesday | N18: 232.82 | O18: 549.18 | P18: 50 | Q18: 150 | R18: 632 | S18: =ROUND(Q18*10%,2) -> 15 | T18: 180 | U18: =(Q18+R18+T18)-(N18+O18+P18) -> 130
A19: PAID | B19: 21 | C19: =INDEX(PORT!$B$2:$B$20,MATCH('02'!B19,PORT!$A$2:$A$20)) -> PNH21 | D19: =INDEX(PORT!$C$2:$C$20,MATCH('02'!B19,PORT!$A$2:$A$20)) -> OLAIR DRY PORT | E19: I 586 | F19: 46063 | G19: VFL | H19: GS26-052 | I19: DIS054 | J19: VFL2602006 | K19: 46064 | L19: =VLOOKUP(K19,'[1]Exchange Rate'!$A$3:$C$15,3,FALSE) -> 4029 | M19: =TEXT(K19,"dddd") -> Wednesday | N19: 218.88 | O19: 647.63 | P19: 50 | Q19: 150 | R19: 746.51 | S19: =ROUND(Q19*10%,2) -> 15 | T19: 150 | U19: =(Q19+R19+T19)-(N19+O19+P19) -> 130
A20: PAID | B20: 1 | C20: =INDEX(PORT!$B$2:$B$20,MATCH('02'!B20,PORT!$A$2:$A$20)) -> PNH01 | D20: =INDEX(PORT!$C$2:$C$20,MATCH('02'!B20,PORT!$A$2:$A$20)) -> KTI AIR PORT | E20: E 6539 | F20: 46066 | G20: JIN YUAN XI | H20: GS26-053 | I20: DIS055 | J20: JYX2602005 | K20: 46069 | L20: =VLOOKUP(K20,'[1]Exchange Rate'!$A$3:$C$15,3,FALSE) -> 4023 | M20: =TEXT(K20,"dddd") -> Monday | N20: 135.67 | O20: 0 | P20: 50 | Q20: 175 | R20: 65.67 | S20: =ROUND(Q20*10%,2) -> 17.5 | T20: 60 | U20: =(Q20+R20+T20)-(N20+O20+P20) -> 115
A21: PAID | B21: 1 | C21: =INDEX(PORT!$B$2:$B$20,MATCH('02'!B21,PORT!$A$2:$A$20)) -> PNH01 | D21: =INDEX(PORT!$C$2:$C$20,MATCH('02'!B21,PORT!$A$2:$A$20)) -> KTI AIR PORT | E21: E 6710 | F21: 46067 | G21: JIN YUAN XI | H21: GS26-054 | I21: DIS056 | J21: JYX2602006 | K21: 46069 | L21: =VLOOKUP(K21,'[1]Exchange Rate'!$A$3:$C$15,3,FALSE) -> 4023 | M21: =TEXT(K21,"dddd") -> Monday | N21: 330.33 | O21: 0 | P21: 50 | Q21: 210 | R21: 260.33 | S21: =ROUND(Q21*10%,2) -> 21 | T21: 60 | U21: =(Q21+R21+T21)-(N21+O21+P21) -> 150
A22: PAID | B22: 11 | C22: =INDEX(PORT!$B$2:$B$20,MATCH('02'!B22,PORT!$A$2:$A$20)) -> SHV11 | D22: =INDEX(PORT!$C$2:$C$20,MATCH('02'!B22,PORT!$A$2:$A$20)) -> SHV PORT | E22: I 26265 | F22: 46071 | G22: VFL | H22: GS26-055 | I22: DIS057 | J22: VFL2602007 | K22: 46072 | L22: =VLOOKUP(K22,'[2]Exchange Rate'!$A$3:$C$23,3,FALSE) -> 4022 | M22: =TEXT(K22,"dddd") -> Thursday | N22: 217.45 | O22: 488.4 | P22: 50 | Q22: 150 | R22: 512.25 | S22: =ROUND(Q22*10%,2) -> 15 | T22: 177.54 | U22: =(Q22+R22+T22)-(N22+O22+P22) -> 83.94
A23: PAID | B23: 11 | C23: =INDEX(PORT!$B$2:$B$20,MATCH('02'!B23,PORT!$A$2:$A$20)) -> SHV11 | D23: =INDEX(PORT!$C$2:$C$20,MATCH('02'!B23,PORT!$A$2:$A$20)) -> SHV PORT | E23: I 26270 | F23: 46071 | G23: VFL | H23: GS26-056 | I23: DIS058 | J23: VFL2602008 | K23: 46072 | L23: =VLOOKUP(K23,'[2]Exchange Rate'!$A$3:$C$23,3,FALSE) -> 4022 | M23: =TEXT(K23,"dddd") -> Thursday | N23: 158.57 | O23: 321.41 | P23: 50 | Q23: 150 | R23: 338.53 | S23: =ROUND(Q23*10%,2) -> 15 | T23: 97.9 | U23: =(Q23+R23+T23)-(N23+O23+P23) -> 56.45
A24: PAID | B24: 23 | C24: =INDEX(PORT!$B$2:$B$20,MATCH('02'!B24,PORT!$A$2:$A$20)) -> PNH23 | D24: =INDEX(PORT!$C$2:$C$20,MATCH('02'!B24,PORT!$A$2:$A$20)) -> UNION DRY PORT | E24: I 123 | F24: 46071 | G24: JIN YUAN XI | H24: GS26-057 | I24: DIS059 | J24: JYX2602007 | K24: 46072 | L24: =VLOOKUP(K24,'[2]Exchange Rate'!$A$3:$C$23,3,FALSE) -> 4022 | M24: =TEXT(K24,"dddd") -> Thursday | N24: 329.75 | O24: 546.26 | P24: 50 | Q24: 150 | R24: 651.01 | S24: =ROUND(Q24*10%,2) -> 15 | T24: 295 | U24: =(Q24+R24+T24)-(N24+O24+P24) -> 170
A25: PAID | B25: 11 | C25: =INDEX(PORT!$B$2:$B$20,MATCH('02'!B25,PORT!$A$2:$A$20)) -> SHV11 | D25: =INDEX(PORT!$C$2:$C$20,MATCH('02'!B25,PORT!$A$2:$A$20)) -> SHV PORT | E25: I 26260 | F25: 46071 | G25: SPORTLINE | H25: GS26-058 | I25: DIS060 | J25: SAK2602006 | K25: 46072 | L25: =VLOOKUP(K25,'[2]Exchange Rate'!$A$3:$C$23,3,FALSE) -> 4022 | M25: =TEXT(K25,"dddd") -> Thursday | N25: 230.25 | O25: 553.08 | P25: 50 | Q25: 150 | R25: 573.56 | S25: =ROUND(Q25*10%,2) -> 15 | T25: 241.05 | U25: =(Q25+R25+T25)-(N25+O25+P25) -> 131.28
A26: PAID | B26: 1 | C26: =INDEX(PORT!$B$2:$B$20,MATCH('02'!B26,PORT!$A$2:$A$20)) -> PNH01 | D26: =INDEX(PORT!$C$2:$C$20,MATCH('02'!B26,PORT!$A$2:$A$20)) -> KTI AIR PORT | E26: E 7265 | F26: 46072 | G26: JIN YUAN XI | H26: GS26-059 | I26: DIS061 | J26: JYX2602008 | K26: 46073 | L26: =VLOOKUP(K26,'[2]Exchange Rate'!$A$3:$C$23,3,FALSE) -> 4021 | M26: =TEXT(K26,"dddd") -> Friday | N26: 151.42 | O26: 0 | P26: 50 | Q26: 175 | R26: 81.42 | S26: =ROUND(Q26*10%,2) -> 17.5 | T26: 60 | U26: =(Q26+R26+T26)-(N26+O26+P26) -> 115
A27: PAID | B27: 11 | C27: =INDEX(PORT!$B$2:$B$20,MATCH('02'!B27,PORT!$A$2:$A$20)) -> SHV11 | D27: =INDEX(PORT!$C$2:$C$20,MATCH('02'!B27,PORT!$A$2:$A$20)) -> SHV PORT | E27: E 51647 | F27: 46073 | G27: JIN YUAN XI | H27: GS26-060 | I27: DIS062 | J27: JYX2602009 | K27: 46076 | L27: =VLOOKUP(K27,'[2]Exchange Rate'!$A$3:$C$23,3,FALSE) -> 4017 | M27: =TEXT(K27,"dddd") -> Monday | N27: 417.7 | O27: 0 | P27: 50 | Q27: 245 | R27: 87.7 | S27: =ROUND(Q27*10%,2) -> 24.5 | T27: 362.5 | U27: =(Q27+R27+T27)-(N27+O27+P27) -> 227.5
A28: PAID | B28: 11 | C28: =INDEX(PORT!$B$2:$B$20,MATCH('02'!B28,PORT!$A$2:$A$20)) -> SHV11 | D28: =INDEX(PORT!$C$2:$C$20,MATCH('02'!B28,PORT!$A$2:$A$20)) -> SHV PORT | E28: E 51619 | F28: 46073 | G28: JIN YUAN XI | H28: PART | S28: =ROUND(Q28*10%,2) -> 0 | U28: =(Q28+R28+T28)-(N28+O28+P28) -> 0
A29: PAID | B29: 11 | C29: =INDEX(PORT!$B$2:$B$20,MATCH('02'!B29,PORT!$A$2:$A$20)) -> SHV11 | D29: =INDEX(PORT!$C$2:$C$20,MATCH('02'!B29,PORT!$A$2:$A$20)) -> SHV PORT | E29: E 52971 | F29: 46073 | G29: JR | H29: GS26-061 | I29: DIS063 | J29: JR2602002 | K29: 46076 | L29: =VLOOKUP(K29,'[2]Exchange Rate'!$A$3:$C$23,3,FALSE) -> 4017 | M29: =TEXT(K29,"dddd") -> Monday | N29: 444.75 | O29: 0 | P29: 5 | Q29: 215 | R29: 64.75 | S29: =ROUND(Q29*10%,2) -> 21.5 | T29: 529 | U29: =(Q29+R29+T29)-(N29+O29+P29) -> 359
A30: PAID | B30: 11 | C30: =INDEX(PORT!$B$2:$B$20,MATCH('02'!B30,PORT!$A$2:$A$20)) -> SHV11 | D30: =INDEX(PORT!$C$2:$C$20,MATCH('02'!B30,PORT!$A$2:$A$20)) -> SHV PORT | E30: I 27779 | F30: 46073 | G30: JR | H30: GS26-062 | I30: DIS064 | J30: JR2602003 | K30: 46076 | L30: =VLOOKUP(K30,'[2]Exchange Rate'!$A$3:$C$23,3,FALSE) -> 4017 | M30: =TEXT(K30,"dddd") -> Monday | N30: 589.45 | O30: 691.5 | P30: 5 | Q30: 200 | R30: 805.95 | S30: =ROUND(Q30*10%,2) -> 20 | T30: 760 | U30: =(Q30+R30+T30)-(N30+O30+P30) -> 480
A31: PAID | B31: 1 | C31: =INDEX(PORT!$B$2:$B$20,MATCH('02'!B31,PORT!$A$2:$A$20)) -> PNH01 | D31: =INDEX(PORT!$C$2:$C$20,MATCH('02'!B31,PORT!$A$2:$A$20)) -> KTI AIR PORT | E31: E 7615 | F31: 46076 | G31: JIN YUAN XI | H31: GS26-063 | I31: DIS065 | J31: JYX2602010 | K31: 46077 | L31: =VLOOKUP(K31,'[2]Exchange Rate'!$A$3:$C$23,3,FALSE) -> 4017 | M31: =TEXT(K31,"dddd") -> Tuesday | N31: 126.08 | O31: 0 | P31: 50 | Q31: 150 | R31: 56.08 | S31: =ROUND(Q31*10%,2) -> 15 | T31: 60 | U31: =(Q31+R31+T31)-(N31+O31+P31) -> 90
A32: PAID | B32: 1 | C32: =INDEX(PORT!$B$2:$B$20,MATCH('02'!B32,PORT!$A$2:$A$20)) -> PNH01 | D32: =INDEX(PORT!$C$2:$C$20,MATCH('02'!B32,PORT!$A$2:$A$20)) -> KTI AIR PORT | E32: E 7616 | F32: 46076 | G32: JIN YUAN XI | H32: GS26-064 | I32: DIS066 | J32: JYX2602011 | K32: 46077 | L32: =VLOOKUP(K32,'[2]Exchange Rate'!$A$3:$C$23,3,FALSE) -> 4017 | M32: =TEXT(K32,"dddd") -> Tuesday | N32: 167 | O32: 0 | P32: 50 | Q32: 175 | R32: 97 | S32: =ROUND(Q32*10%,2) -> 17.5 | T32: 60 | U32: =(Q32+R32+T32)-(N32+O32+P32) -> 115
A33: PAID | B33: 11 | C33: =INDEX(PORT!$B$2:$B$20,MATCH('02'!B33,PORT!$A$2:$A$20)) -> SHV11 | D33: =INDEX(PORT!$C$2:$C$20,MATCH('02'!B33,PORT!$A$2:$A$20)) -> SHV PORT | E33: I 32157 | F33: 46081 | G33: VFL | H33: GS26-069 | I33: DIS071 | J33: VFL2602009 | K33: 46081 | L33: =VLOOKUP(K33,'[2]Exchange Rate'!$A$3:$C$23,3,FALSE) -> 4010 | M33: =TEXT(K33,"dddd") -> Saturday | N33: 179.23 | O33: 335.72 | P33: 50 | Q33: 150 | R33: 354.52 | S33: =ROUND(Q33*10%,2) -> 15 | T33: 116.95 | U33: =(Q33+R33+T33)-(N33+O33+P33) -> 56.52
A34: PAID | B34: 4 | C34: =INDEX(PORT!$B$2:$B$20,MATCH('02'!B34,PORT!$A$2:$A$20)) -> PNH04 | D34: =INDEX(PORT!$C$2:$C$20,MATCH('02'!B34,PORT!$A$2:$A$20)) -> PNH PORT | E34: E 58276 | F34: 46080 | G34: VFL | H34: GS26-071 | I34: DIS073 | J34: VFL2602010 | K34: 46081 | L34: =VLOOKUP(K34,'[2]Exchange Rate'!$A$3:$C$23,3,FALSE) -> 4010 | M34: =TEXT(K34,"dddd") -> Saturday | N34: 359.85 | O34: 0 | P34: 50 | Q34: 215 | R34: 94.85 | S34: =ROUND(Q34*10%,2) -> 21.5 | T34: 255 | U34: =(Q34+R34+T34)-(N34+O34+P34) -> 155
A35: PAID | B35: 4 | C35: =INDEX(PORT!$B$2:$B$20,MATCH('02'!B35,PORT!$A$2:$A$20)) -> PNH04 | D35: =INDEX(PORT!$C$2:$C$20,MATCH('02'!B35,PORT!$A$2:$A$20)) -> PNH PORT | E35: E 55816 | F35: 46080 | G35: SPORTLINE | H35: GS26-067 | I35: DIS069 | J35: SAK2602007 | K35: 46081 | L35: =VLOOKUP(K35,'[2]Exchange Rate'!$A$3:$C$23,3,FALSE) -> 4010 | M35: =TEXT(K35,"dddd") -> Saturday | N35: 930.26 | O35: 0 | P35: 50 | Q35: 490 | R35: 260.26 | S35: =ROUND(Q35*10%,2) -> 49 | T35: 739 | U35: =(Q35+R35+T35)-(N35+O35+P35) -> 509
A36: PAID | B36: 4 | C36: =INDEX(PORT!$B$2:$B$20,MATCH('02'!B36,PORT!$A$2:$A$20)) -> PNH04 | D36: =INDEX(PORT!$C$2:$C$20,MATCH('02'!B36,PORT!$A$2:$A$20)) -> PNH PORT | E36: E 58393 | F36: 46080 | G36: JR | H36: GS26-068 | I36: DIS070 | J36: JR2602004 | K36: 46081 | L36: =VLOOKUP(K36,'[2]Exchange Rate'!$A$3:$C$23,3,FALSE) -> 4010 | M36: =TEXT(K36,"dddd") -> Saturday | N36: 480.75 | O36: 0 | P36: 5 | Q36: 242 | R36: 135.75 | S36: =ROUND(Q36*10%,2) -> 24.2 | T36: 449 | U36: =(Q36+R36+T36)-(N36+O36+P36) -> 341
A37: PAID | B37: 11 | C37: =INDEX(PORT!$B$2:$B$20,MATCH('02'!B37,PORT!$A$2:$A$20)) -> SHV11 | D37: =INDEX(PORT!$C$2:$C$20,MATCH('02'!B37,PORT!$A$2:$A$20)) -> SHV PORT | E37: I 32164 | F37: 46081 | G37: SPORTLINE | H37: GS26-070 | I37: DIS072 | J37: SAK2602008 | K37: 46081 | L37: =VLOOKUP(K37,'[2]Exchange Rate'!$A$3:$C$23,3,FALSE) -> 4010 | M37: =TEXT(K37,"dddd") -> Saturday | N37: 246.18 | O37: 295.24 | P37: 50 | Q37: 150 | R37: 326.11 | S37: =ROUND(Q37*10%,2) -> 15 | T37: 210.15 | U37: =(Q37+R37+T37)-(N37+O37+P37) -> 94.84
A38: PAID | B38: 11 | C38: =INDEX(PORT!$B$2:$B$20,MATCH('02'!B38,PORT!$A$2:$A$20)) -> SHV11 | D38: =INDEX(PORT!$C$2:$C$20,MATCH('02'!B38,PORT!$A$2:$A$20)) -> SHV PORT | E38: I 32162 | F38: 46081 | G38: SPORTLINE | H38: PART | S38: =ROUND(Q38*10%,2) -> 0 | U38: =(Q38+R38+T38)-(N38+O38+P38) -> 0
A39: PAID | B39: 11 | C39: SHV11 | D39: SHV PORT | E39: I 30715 | F39: 46078 | G39: JIN YUAN XI | H39: GS26-065 | I39: DIS067 | J39: JYX2602012 | K39: 46079 | L39: 4011 | M39: =TEXT(K39,"dddd") -> Thursday | N39: 163.75 | P39: 50 | Q39: 150 | R39: 314.75 | S39: =ROUND(Q39*10%,2) -> 15 | T39: 100 | U39: =(Q39+R39+T39)-(N39+O39+P39) -> 351
A40: PAID | B40: 1 | C40: =INDEX(PORT!$B$2:$B$20,MATCH('02'!B40,PORT!$A$2:$A$20)) -> PNH01 | D40: =INDEX(PORT!$C$2:$C$20,MATCH('02'!B40,PORT!$A$2:$A$20)) -> KTI AIR PORT | E40: E 8171 | F40: 46079 | G40: JIN YUAN XI | H40: GS26-066 | I40: DIS068 | J40: JYX2602013 | K40: 46081 | L40: =VLOOKUP(K40,'[2]Exchange Rate'!$A$3:$C$23,3,FALSE) -> 4010 | M40: =TEXT(K40,"dddd") -> Saturday | N40: 181.78 | O40: 0 | P40: 50 | Q40: 210 | R40: 111.78 | S40: =ROUND(Q40*10%,2) -> 21 | T40: 180 | U40: =(Q40+R40+T40)-(N40+O40+P40) -> 270
...

Sheet 03
E1: REVENUE & EXPENSE | M1: Saturday
A2: CHEA PAYMENT | B2: PORT NUMBER | C2: PORT CODE | D2: PORT NAME | E2: DECLARE | F2: DATE | G2: CLIENT | H2: INV | I2: DISBURSEMENT | J2: DN | K2: DATE | L2: EXCHANGE RATE | M2: weekday | N2: CLEAR FEE | O2: THC | P2: CM | Q2: INV (REVENUE) | R2: REIM | S2: VAT 10% | T2: DN | U2: NET PROFIT | V2: MARK
A3: PAID | B3: 1 | C3: =INDEX(PORT!$B$2:$B$20,MATCH('03'!B3,PORT!$A$2:$A$20)) -> PNH01 | D3: =INDEX(PORT!$C$2:$C$20,MATCH('03'!B3,PORT!$A$2:$A$20)) -> KTI AIR PORT | E3: E 8725 | F3: 46083 | G3: VFL | H3: GS26-072 | I3: DIS074 | J3: VFL2603001 | K3: 46084 | L3: =VLOOKUP(K3,'[3]Exchange Rate'!$A$3:$C$24,3,FALSE) -> 4013 | M3: =TEXT(K3,"dddd") -> Tuesday | N3: 83.75 | O3: 0 | P3: 50 | Q3: 140 | R3: 13.75 | S3: =ROUND(Q3*10%,2) -> 14 | T3: 60 | U3: =(Q3+R3+T3)-(N3+O3+P3) -> 80
A4: PAID | B4: 1 | C4: =INDEX(PORT!$B$2:$B$20,MATCH('03'!B4,PORT!$A$2:$A$20)) -> PNH01 | D4: =INDEX(PORT!$C$2:$C$20,MATCH('03'!B4,PORT!$A$2:$A$20)) -> KTI AIR PORT | E4: E 8729 | F4: 46083 | G4: VFL | H4: GS26-073 | I4: DIS075 | J4: VFL2603002 | K4: 46084 | L4: =VLOOKUP(K4,'[3]Exchange Rate'!$A$3:$C$24,3,FALSE) -> 4013 | M4: =TEXT(K4,"dddd") -> Tuesday | N4: 83.75 | O4: 0 | P4: 50 | Q4: 140 | R4: 13.75 | S4: =ROUND(Q4*10%,2) -> 14 | T4: 60 | U4: =(Q4+R4+T4)-(N4+O4+P4) -> 80
A5: PAID | B5: 11 | C5: =INDEX(PORT!$B$2:$B$20,MATCH('03'!B5,PORT!$A$2:$A$20)) -> SHV11 | D5: =INDEX(PORT!$C$2:$C$20,MATCH('03'!B5,PORT!$A$2:$A$20)) -> SHV PORT | E5: I 32408 | F5: 46083 | G5: JR | H5: GS26-074 | I5: DIS076 | J5: JR2603001 | K5: 46084 | L5: =VLOOKUP(K5,'[3]Exchange Rate'!$A$3:$C$24,3,FALSE) -> 4013 | M5: =TEXT(K5,"dddd") -> Tuesday | N5: 569.45 | O5: 691.5 | P5: 0 | Q5: 200 | R5: 805.95 | S5: =ROUND(Q5*10%,2) -> 20 | T5: 585 | U5: =(Q5+R5+T5)-(N5+O5+P5) -> 330
A6: PAID | B6: 11 | C6: =INDEX(PORT!$B$2:$B$20,MATCH('03'!B6,PORT!$A$2:$A$20)) -> SHV11 | D6: =INDEX(PORT!$C$2:$C$20,MATCH('03'!B6,PORT!$A$2:$A$20)) -> SHV PORT | E6: I 32429 | F6: 46083 | G6: JR | H6: GS26-075 | I6: DIS077 | J6: JR2603002 | K6: 46084 | L6: =VLOOKUP(K6,'[3]Exchange Rate'!$A$3:$C$24,3,FALSE) -> 4013 | M6: =TEXT(K6,"dddd") -> Tuesday | N6: 526.45 | O6: 476.5 | P6: 0 | Q6: 180 | R6: 557.95 | S6: =ROUND(Q6*10%,2) -> 18 | T6: 485 | U6: =(Q6+R6+T6)-(N6+O6+P6) -> 220
A7: PAID | B7: 1 | C7: =INDEX(PORT!$B$2:$B$20,MATCH('03'!B7,PORT!$A$2:$A$20)) -> PNH01 | D7: =INDEX(PORT!$C$2:$C$20,MATCH('03'!B7,PORT!$A$2:$A$20)) -> KTI AIR PORT | E7: E 9314 | F7: 46088 | G7: VFL | H7: GS26-076 | I7: DIS078 | J7: VFL2603003 | K7: 46090 | L7: =VLOOKUP(K7,'[3]Exchange Rate'!$A$3:$C$24,3,FALSE) -> 4013 | M7: =TEXT(K7,"dddd") -> Monday | N7: 83.75 | O7: 0 | P7: 50 | Q7: 140 | R7: 13.75 | S7: =ROUND(Q7*10%,2) -> 14 | T7: 60 | U7: =(Q7+R7+T7)-(N7+O7+P7) -> 80
A8: PAID | B8: 1 | C8: =INDEX(PORT!$B$2:$B$20,MATCH('03'!B8,PORT!$A$2:$A$20)) -> PNH01 | D8: =INDEX(PORT!$C$2:$C$20,MATCH('03'!B8,PORT!$A$2:$A$20)) -> KTI AIR PORT | E8: E 9095 | F8: 46087 | G8: JIN YUAN XI | H8: GS26-077 | I8: DIS079 | J8: JYX2603001 | K8: 46090 | L8: =VLOOKUP(K8,'[3]Exchange Rate'!$A$3:$C$24,3,FALSE) -> 4013 | M8: =TEXT(K8,"dddd") -> Monday | N8: 128.63 | O8: 0 | P8: 50 | Q8: 175 | R8: 58.63 | S8: =ROUND(Q8*10%,2) -> 17.5 | T8: 60 | U8: =(Q8+R8+T8)-(N8+O8+P8) -> 115
A9: PAID | B9: 1 | C9: =INDEX(PORT!$B$2:$B$20,MATCH('03'!B9,PORT!$A$2:$A$20)) -> PNH01 | D9: =INDEX(PORT!$C$2:$C$20,MATCH('03'!B9,PORT!$A$2:$A$20)) -> KTI AIR PORT | E9: E 9216 | F9: 46087 | G9: JIN YUAN XI | H9: GS26-078 | I9: DIS080 | J9: JYX2603002 | K9: 46090 | L9: =VLOOKUP(K9,'[3]Exchange Rate'!$A$3:$C$24,3,FALSE) -> 4013 | M9: =TEXT(K9,"dddd") -> Monday | N9: 206.42 | O9: 0 | P9: 50 | Q9: 210 | R9: 136.42 | S9: =ROUND(Q9*10%,2) -> 21 | T9: 60 | U9: =(Q9+R9+T9)-(N9+O9+P9) -> 150
A10: PAID | B10: 1 | C10: =INDEX(PORT!$B$2:$B$20,MATCH('03'!B10,PORT!$A$2:$A$20)) -> PNH01 | D10: =INDEX(PORT!$C$2:$C$20,MATCH('03'!B10,PORT!$A$2:$A$20)) -> KTI AIR PORT | E10: E 9303 | F10: 46088 | G10: JIN YUAN XI | H10: GS26-079 | I10: DIS081 | J10: JYX2603003 | K10: 46090 | L10: =VLOOKUP(K10,'[3]Exchange Rate'!$A$3:$C$24,3,FALSE) -> 4013 | M10: =TEXT(K10,"dddd") -> Monday | N10: 604.02 | O10: 0 | P10: 50 | Q10: 230 | R10: 484.02 | S10: =ROUND(Q10*10%,2) -> 23 | T10: 180 | U10: =(Q10+R10+T10)-(N10+O10+P10) -> 240
A11: PAID | B11: 4 | C11: =INDEX(PORT!$B$2:$B$20,MATCH('03'!B11,PORT!$A$2:$A$20)) -> PNH04 | D11: =INDEX(PORT!$C$2:$C$20,MATCH('03'!B11,PORT!$A$2:$A$20)) -> PNH PORT | E11: E 64094 | F11: 46087 | G11: JR | H11: GS26-080 | I11: DIS082 | J11: JR2603003 | K11: 46090 | L11: =VLOOKUP(K11,'[3]Exchange Rate'!$A$3:$C$24,3,FALSE) -> 4013 | M11: =TEXT(K11,"dddd") -> Monday | N11: 517.75 | O11: 528 | P11: 0 | Q11: 242 | R11: =916.45-N12 -> 903.25 | S11: =ROUND(Q11*10%,2) -> 24.2 | T11: 729 | U11: =(Q11+R11+T11)-(N11+O11+P11) -> 828.5 | V11: HBL
A12: PAID | B12: 4 | C12: =INDEX(PORT!$B$2:$B$20,MATCH('03'!B12,PORT!$A$2:$A$20)) -> PNH04 | D12: =INDEX(PORT!$C$2:$C$20,MATCH('03'!B12,PORT!$A$2:$A$20)) -> PNH PORT | E12: E 64094 | F12: 46087 | G12: JR | K12: 46090 | L12: =VLOOKUP(K12,'[3]Exchange Rate'!$A$3:$C$24,3,FALSE) -> 4013 | M12: =TEXT(K12,"dddd") -> Monday | N12: 13.2 | O12: 0 | P12: 0 | R12: 13.2 | S12: =ROUND(Q12*10%,2) -> 0 | U12: =(Q12+R12+T12)-(N12+O12+P12) -> 0 | V12: Lack storage fee
A13: PAID | B13: 4 | C13: =INDEX(PORT!$B$2:$B$20,MATCH('03'!B13,PORT!$A$2:$A$20)) -> PNH04 | D13: =INDEX(PORT!$C$2:$C$20,MATCH('03'!B13,PORT!$A$2:$A$20)) -> PNH PORT | E13: E 65834 | F13: 46087 | G13: JR | H13: GS26-081 | I13: DIS083 | J13: JR2603004 | K13: 46090 | L13: =VLOOKUP(K13,'[3]Exchange Rate'!$A$3:$C$24,3,FALSE) -> 4013 | M13: =TEXT(K13,"dddd") -> Monday | N13: 515.75 | O13: 506 | P13: 0 | Q13: 242 | R13: =691.75-N14 -> 371.75 | S13: =ROUND(Q13*10%,2) -> 24.2 | T13: 1219 | U13: =(Q13+R13+T13)-(N13+O13+P13) -> 811
A14: PAID | B14: 4 | C14: =INDEX(PORT!$B$2:$B$20,MATCH('03'!B14,PORT!$A$2:$A$20)) -> PNH04 | D14: =INDEX(PORT!$C$2:$C$20,MATCH('03'!B14,PORT!$A$2:$A$20)) -> PNH PORT | E14: E 65834 | F14: 46087 | G14: JR | K14: 46090 | L14: =VLOOKUP(K14,'[3]Exchange Rate'!$A$3:$C$24,3,FALSE) -> 4013 | M14: =TEXT(K14,"dddd") -> Monday | N14: 320 | O14: 0 | P14: 0 | R14: 320 | S14: =ROUND(Q14*10%,2) -> 0 | U14: =(Q14+R14+T14)-(N14+O14+P14) -> 0 | V14: Lack
A15: PAID | B15: 1 | C15: =INDEX(PORT!$B$2:$B$20,MATCH('03'!B15,PORT!$A$2:$A$20)) -> PNH01 | D15: =INDEX(PORT!$C$2:$C$20,MATCH('03'!B15,PORT!$A$2:$A$20)) -> KTI AIR PORT | E15: I 6739 | F15: 46090 | G15: VFL | H15: GS26-082 | I15: DIS084 | J15: VFL2603004 | K15: 46091 | L15: =VLOOKUP(K15,'[3]Exchange Rate'!$A$3:$C$24,3,FALSE) -> 4013 | M15: =TEXT(K15,"dddd") -> Tuesday | N15: 172.57 | O15: 60.5 | P15: 50 | Q15: 150 | R15: 93.07 | S15: =ROUND(Q15*10%,2) -> 15 | T15: 119.75 | U15: =(Q15+R15+T15)-(N15+O15+P15) -> 79.75
A16: PAID | B16: 1 | C16: =INDEX(PORT!$B$2:$B$20,MATCH('03'!B16,PORT!$A$2:$A$20)) -> PNH01 | D16: =INDEX(PORT!$C$2:$C$20,MATCH('03'!B16,PORT!$A$2:$A$20)) -> KTI AIR PORT | E16: I 6742 | F16: 46090 | G16: VFL | H16: GS26-083 | I16: DIS085 | J16: VFL2603005 | K16: 46091 | L16: =VLOOKUP(K16,'[3]Exchange Rate'!$A$3:$C$24,3,FALSE) -> 4013 | M16: =TEXT(K16,"dddd") -> Tuesday | N16: 175.14 | O16: 110 | P16: 50 | Q16: 150 | R16: 145.14 | S16: =ROUND(Q16*10%,2) -> 15 | T16: 119.75 | U16: =(Q16+R16+T16)-(N16+O16+P16) -> 79.75
A17: PAID | B17: 21 | C17: =INDEX(PORT!$B$2:$B$20,MATCH('03'!B17,PORT!$A$2:$A$20)) -> PNH21 | D17: =INDEX(PORT!$C$2:$C$20,MATCH('03'!B17,PORT!$A$2:$A$20)) -> OLAIR DRY PORT | E17: I 837 | F17: 46091 | G17: VFL | H17: GS26-084 | I17: DIS086 | J17: VFL2603006 | K17: 46092 | L17: =VLOOKUP(K17,'[3]Exchange Rate'!$A$3:$C$24,3,FALSE) -> 4013 | M17: =TEXT(K17,"dddd") -> Wednesday | N17: 115 | O17: 205.43 | P17: 50 | Q17: 150 | R17: 230.43 | S17: =ROUND(Q17*10%,2) -> 15 | T17: 103.5 | U17: =(Q17+R17+T17)-(N17+O17+P17) -> 113.5
A18: PAID | B18: 21 | C18: =INDEX(PORT!$B$2:$B$20,MATCH('03'!B18,PORT!$A$2:$A$20)) -> PNH21 | D18: =INDEX(PORT!$C$2:$C$20,MATCH('03'!B18,PORT!$A$2:$A$20)) -> OLAIR DRY PORT | E18: I 839 | F18: 46091 | G18: SPORTLINE | H18: GS26-085 | I18: DIS087 | J18: SAK2603001 | K18: 46092 | L18: =VLOOKUP(K18,'[3]Exchange Rate'!$A$3:$C$24,3,FALSE) -> 4013 | M18: =TEXT(K18,"dddd") -> Wednesday | N18: 145 | O18: 176 | P18: 50 | Q18: 150 | R18: 201 | S18: =ROUND(Q18*10%,2) -> 15 | T18: 181 | U18: =(Q18+R18+T18)-(N18+O18+P18) -> 161
A19: PAID | B19: 1 | C19: =INDEX(PORT!$B$2:$B$20,MATCH('03'!B19,PORT!$A$2:$A$20)) -> PNH01 | D19: =INDEX(PORT!$C$2:$C$20,MATCH('03'!B19,PORT!$A$2:$A$20)) -> KTI AIR PORT | E19: E 9849 | F19: 46093 | G19: VFL | H19: GS26-086 | I19: DIS088 | J19: VFL2603007 | K19: 46094 | L19: =VLOOKUP(K19,'[3]Exchange Rate'!$A$3:$C$24,3,FALSE) -> 4013 | M19: =TEXT(K19,"dddd") -> Friday | N19: 85.95 | O19: 0 | P19: 50 | Q19: 140 | R19: 15.95 | S19: =ROUND(Q19*10%,2) -> 14 | T19: 60 | U19: =(Q19+R19+T19)-(N19+O19+P19) -> 80
A20: PAID | B20: 1 | C20: =INDEX(PORT!$B$2:$B$20,MATCH('03'!B20,PORT!$A$2:$A$20)) -> PNH01 | D20: =INDEX(PORT!$C$2:$C$20,MATCH('03'!B20,PORT!$A$2:$A$20)) -> KTI AIR PORT | E20: I 7165 | F20: 46093 | G20: VFL | H20: GS26-087 | I20: DIS089 | J20: VFL2603008 | K20: 46094 | L20: =VLOOKUP(K20,'[3]Exchange Rate'!$A$3:$C$24,3,FALSE) -> 4013 | M20: =TEXT(K20,"dddd") -> Friday | N20: 158.4 | O20: 60.5 | P20: 50 | Q20: 150 | R20: 78.9 | S20: =ROUND(Q20*10%,2) -> 15 | T20: 119.75 | U20: =(Q20+R20+T20)-(N20+O20+P20) -> 79.75
A21: PAID | B21: 11 | C21: =INDEX(PORT!$B$2:$B$20,MATCH('03'!B21,PORT!$A$2:$A$20)) -> SHV11 | D21: =INDEX(PORT!$C$2:$C$20,MATCH('03'!B21,PORT!$A$2:$A$20)) -> SHV PORT | E21: I 35751 | F21: 46093 | G21: SPORTLINE | H21: GS26-088 | I21: DIS090 | J21: SAK2603002 | K21: 46094 | L21: =VLOOKUP(K21,'[3]Exchange Rate'!$A$3:$C$24,3,FALSE) -> 4013 | M21: =TEXT(K21,"dddd") -> Friday | N21: 271.99 | O21: 365.01 | P21: 50 | Q21: 150 | R21: 385.49 | S21: =ROUND(Q21*10%,2) -> 15 | T21: 243.84 | U21: =(Q21+R21+T21)-(N21+O21+P21) -> 92.33
A22: PAID | B22: 11 | C22: =INDEX(PORT!$B$2:$B$20,MATCH('03'!B22,PORT!$A$2:$A$20)) -> SHV11 | D22: =INDEX(PORT!$C$2:$C$20,MATCH('03'!B22,PORT!$A$2:$A$20)) -> SHV PORT | E22: I 35753 | F22: 46093 | G22: SPORTLINE | H22: GS26-089 | I22: DIS091 | J22: SAK2603003 | K22: 46094 | L22: =VLOOKUP(K22,'[3]Exchange Rate'!$A$3:$C$24,3,FALSE) -> 4013 | M22: =TEXT(K22,"dddd") -> Friday | N22: 202.51 | O22: 245.98 | P22: 50 | Q22: 150 | R22: 263.1 | S22: =ROUND(Q22*10%,2) -> 15 | T22: 152.84 | U22: =(Q22+R22+T22)-(N22+O22+P22) -> 67.45
A23: PAID | B23: 1 | C23: =INDEX(PORT!$B$2:$B$20,MATCH('03'!B23,PORT!$A$2:$A$20)) -> PNH01 | D23: =INDEX(PORT!$C$2:$C$20,MATCH('03'!B23,PORT!$A$2:$A$20)) -> KTI AIR PORT | E23: E 10005 | F23: 46094 | G23: VFL | H23: GS26-090 | I23: DIS092 | J23: VFL2603009 | K23: 46097 | L23: =VLOOKUP(K23,'[3]Exchange Rate'!$A$3:$C$24,3,FALSE) -> 4013 | M23: =TEXT(K23,"dddd") -> Monday | N23: 86.83 | O23: 0 | P23: 50 | Q23: 140 | R23: 16.83 | S23: =ROUND(Q23*10%,2) -> 14 | T23: 60 | U23: =(Q23+R23+T23)-(N23+O23+P23) -> 80
A24: PAID | B24: 1 | C24: =INDEX(PORT!$B$2:$B$20,MATCH('03'!B24,PORT!$A$2:$A$20)) -> PNH01 | D24: =INDEX(PORT!$C$2:$C$20,MATCH('03'!B24,PORT!$A$2:$A$20)) -> KTI AIR PORT | E24: E 10184 | F24: 46095 | G24: VFL | H24: GS26-091 | I24: DIS093 | J24: VFL2603010 | K24: 46097 | L24: =VLOOKUP(K24,'[3]Exchange Rate'!$A$3:$C$24,3,FALSE) -> 4013 | M24: =TEXT(K24,"dddd") -> Monday | N24: 90.26 | O24: 0 | P24: 50 | Q24: 140 | R24: 20.26 | S24: =ROUND(Q24*10%,2) -> 14 | T24: 60 | U24: =(Q24+R24+T24)-(N24+O24+P24) -> 80
A25: PAID | B25: 1 | C25: =INDEX(PORT!$B$2:$B$20,MATCH('03'!B25,PORT!$A$2:$A$20)) -> PNH01 | D25: =INDEX(PORT!$C$2:$C$20,MATCH('03'!B25,PORT!$A$2:$A$20)) -> KTI AIR PORT | E25: E 10205 | F25: 46095 | G25: VFL | H25: GS26-092 | I25: DIS094 | J25: VFL2603011 | K25: 46097 | L25: =VLOOKUP(K25,'[3]Exchange Rate'!$A$3:$C$24,3,FALSE) -> 4013 | M25: =TEXT(K25,"dddd") -> Monday | N25: 83.75 | O25: 0 | P25: 50 | Q25: 140 | R25: 13.75 | S25: =ROUND(Q25*10%,2) -> 14 | T25: 60 | U25: =(Q25+R25+T25)-(N25+O25+P25) -> 80
A26: PAID | B26: 11 | C26: =INDEX(PORT!$B$2:$B$20,MATCH('03'!B26,PORT!$A$2:$A$20)) -> SHV11 | D26: =INDEX(PORT!$C$2:$C$20,MATCH('03'!B26,PORT!$A$2:$A$20)) -> SHV PORT | E26: I 36325 | F26: 46095 | G26: VFL | H26: GS26-093 | I26: DIS095 | J26: VFL2603012 | K26: 46097 | L26: =VLOOKUP(K26,'[3]Exchange Rate'!$A$3:$C$24,3,FALSE) -> 4013 | M26: =TEXT(K26,"dddd") -> Monday | N26: 152.45 | O26: 238.92 | P26: 50 | Q26: 150 | R26: 254.35 | S26: =ROUND(Q26*10%,2) -> 15 | T26: 100.15 | U26: =(Q26+R26+T26)-(N26+O26+P26) -> 63.13
... A28: PAID | B28: 1 | C28: =INDEX(PORT!$B$2:$B$20,MATCH('03'!B28,PORT!$A$2:$A$20)) -> PNH01 | D28: =INDEX(PORT!$C$2:$C$20,MATCH('03'!B28,PORT!$A$2:$A$20)) -> KTI AIR PORT | E28: E 9979 | F28: 46094 | G28: JIN YUAN XI | H28: GS26-095 | I28: DIS097 | J28: JYX2603005 | K28: 46097 | L28: =VLOOKUP(K28,'[3]Exchange Rate'!$A$3:$C$24,3,FALSE) -> 4013 | M28: =TEXT(K28,"dddd") -> Monday | N28: 165.41 | O28: 0 | P28: 50 | Q28: 175 | R28: 95.41 | S28: =ROUND(Q28*10%,2) -> 17.5 | T28: 60 | U28: =(Q28+R28+T28)-(N28+O28+P28) -> 115
A29: PAID | B29: 4 | C29: =INDEX(PORT!$B$2:$B$20,MATCH('03'!B29,PORT!$A$2:$A$20)) -> PNH04 | D29: =INDEX(PORT!$C$2:$C$20,MATCH('03'!B29,PORT!$A$2:$A$20)) -> PNH PORT | E29: E 72299 | F29: 46094 | G29: JR | H29: GS26-096 | I29: DIS098 | J29: JR2603005 | K29: 46097 | L29: =VLOOKUP(K29,'[3]Exchange Rate'!$A$3:$C$24,3,FALSE) -> 4013 | M29: =TEXT(K29,"dddd") -> Monday | N29: 516.85 | O29: 466 | P29: 0 | Q29: 213 | R29: 567.85 | S29: =ROUND(Q29*10%,2) -> 21.3 | T29: 621.58 | U29: =(Q29+R29+T29)-(N29+O29+P29) -> 419.58 | V29: HBL
A30: PAID | B30: 11 | C30: =INDEX(PORT!$B$2:$B$20,MATCH('03'!B30,PORT!$A$2:$A$20)) -> SHV11 | D30: =INDEX(PORT!$C$2:$C$20,MATCH('03'!B30,PORT!$A$2:$A$20)) -> SHV PORT | E30: I 36309 | F30: 46095 | G30: SPORTLINE | H30: GS26-097 | I30: DIS099 | J30: SAK2603004 | K30: 46097 | L30: =VLOOKUP(K30,'[3]Exchange Rate'!$A$3:$C$24,3,FALSE) -> 4013 | M30: =TEXT(K30,"dddd") -> Monday | N30: 155.43 | O30: 198.4 | P30: 50 | Q30: 150 | R30: 213.83 | S30: =ROUND(Q30*10%,2) -> 15 | T30: 160.52 | U30: =(Q30+R30+T30)-(N30+O30+P30) -> 120.52
A31: PAID | B31: 19 | C31: =INDEX(PORT!$B$2:$B$20,MATCH('03'!B31,PORT!$A$2:$A$20)) -> PNH19 | D31: =INDEX(PORT!$C$2:$C$20,MATCH('03'!B31,PORT!$A$2:$A$20)) -> TEC SRUN DRYPORT | E31: I 769 | F31: 46097 | G31: VFL | H31: GS26-098 | I31: DIS100 | J31: VFL2603013 | K31: 46098 | L31: =VLOOKUP(K31,'[3]Exchange Rate'!$A$3:$C$24,3,FALSE) -> 4013 | M31: =TEXT(K31,"dddd") -> Tuesday | N31: 116.1 | O31: 194.13 | P31: 50 | Q31: 150 | R31: 220.23 | S31: =ROUND(Q31*10%,2) -> 15 | T31: 108.5 | U31: =(Q31+R31+T31)-(N31+O31+P31) -> 118.5
A32: PAID | B32: 19 | C32: =INDEX(PORT!$B$2:$B$20,MATCH('03'!B32,PORT!$A$2:$A$20)) -> PNH19 | D32: =INDEX(PORT!$C$2:$C$20,MATCH('03'!B32,PORT!$A$2:$A$20)) -> TEC SRUN DRYPORT | E32: I 770 | F32: 46097 | G32: SPORTLINE | H32: GS26-099 | I32: DIS101 | J32: SAK2603005 | K32: 46098 | L32: =VLOOKUP(K32,'[3]Exchange Rate'!$A$3:$C$24,3,FALSE) -> 4013 | M32: =TEXT(K32,"dddd") -> Tuesday | N32: 136.1 | O32: 194.13 | P32: 50 | Q32: 150 | R32: 220.23 | S32: =ROUND(Q32*10%,2) -> 15 | T32: 147 | U32: =(Q32+R32+T32)-(N32+O32+P32) -> 137
A33: PAID | B33: 11 | C33: =INDEX(PORT!$B$2:$B$20,MATCH('03'!B33,PORT!$A$2:$A$20)) -> SHV11 | D33: =INDEX(PORT!$C$2:$C$20,MATCH('03'!B33,PORT!$A$2:$A$20)) -> SHV PORT | E33: I 37892 | F33: 46099 | G33: VFL | H33: GS26-100 | I33: DIS102 | J33: VFL2603014 | K33: 46100 | L33: =VLOOKUP(K33,'[3]Exchange Rate'!$A$3:$C$24,3,FALSE) -> 4013 | M33: =TEXT(K33,"dddd") -> Thursday | N33: 168.06 | O33: 312.74 | P33: 50 | Q33: 150 | R33: 329.86 | S33: =ROUND(Q33*10%,2) -> 15 | T33: 108.64 | U33: =(Q33+R33+T33)-(N33+O33+P33) -> 57.7
A34: PAID | B34: 11 | C34: =INDEX(PORT!$B$2:$B$20,MATCH('03'!B34,PORT!$A$2:$A$20)) -> SHV11 | D34: =INDEX(PORT!$C$2:$C$20,MATCH('03'!B34,PORT!$A$2:$A$20)) -> SHV PORT | E34: I 37893 | F34: 46099 | G34: VFL | H34: GS26-101 | I34: DIS103 | J34: VFL2603015 | K34: 46100 | L34: =VLOOKUP(K34,'[3]Exchange Rate'!$A$3:$C$24,3,FALSE) -> 4013 | M34: =TEXT(K34,"dddd") -> Thursday | N34: 145.43 | O34: 206.25 | P34: 50 | Q34: 150 | R34: 221.68 | S34: =ROUND(Q34*10%,2) -> 15 | T34: 112.31 | U34: =(Q34+R34+T34)-(N34+O34+P34) -> 82.31
A35: PAID | B35: 11 | C35: =INDEX(PORT!$B$2:$B$20,MATCH('03'!B35,PORT!$A$2:$A$20)) -> SHV11 | D35: =INDEX(PORT!$C$2:$C$20,MATCH('03'!B35,PORT!$A$2:$A$20)) -> SHV PORT | E35: I 37897 | F35: 46099 | G35: SPORTLINE | H35: GS26-102 | I35: DIS104 | J35: SAK2603006 | K35: 46100 | L35: =VLOOKUP(K35,'[3]Exchange Rate'!$A$3:$C$24,3,FALSE) -> 4013 | M35: =TEXT(K35,"dddd") -> Thursday | N35: 219.3 | O35: 256.01 | P35: 50 | Q35: 150 | R35: 274.81 | S35: =ROUND(Q35*10%,2) -> 15 | T35: 196.9 | U35: =(Q35+R35+T35)-(N35+O35+P35) -> 96.4
A36: PAID | B36: 4 | C36: =INDEX(PORT!$B$2:$B$20,MATCH('03'!B36,PORT!$A$2:$A$20)) -> PNH04 | D36: =INDEX(PORT!$C$2:$C$20,MATCH('03'!B36,PORT!$A$2:$A$20)) -> PNH PORT | E36: E 74515 | F36: 46100 | G36: SPORTLINE | H36: GS26-103 | I36: DIS105 | J36: SAK2603007 | K36: 46101 | L36: =VLOOKUP(K36,'[3]Exchange Rate'!$A$3:$C$24,3,FALSE) -> 4011 | M36: =TEXT(K36,"dddd") -> Friday | N36: 1108.76 | O36: 0 | P36: 50 | Q36: 490 | R36: 286.75 | S36: =ROUND(Q36*10%,2) -> 49 | T36: 974 | U36: =(Q36+R36+T36)-(N36+O36+P36) -> 591.99
A37: PAID | B37: 1 | C37: =INDEX(PORT!$B$2:$B$20,MATCH('03'!B37,PORT!$A$2:$A$20)) -> PNH01 | D37: =INDEX(PORT!$C$2:$C$20,MATCH('03'!B37,PORT!$A$2:$A$20)) -> KTI AIR PORT | E37: E 11073 | F37: 46102 | G37: JIN YUAN XI | H37: GS26-104 | I37: DIS106 | J37: JYX2603006 | K37: 46104 | L37: =VLOOKUP(K37,'[3]Exchange Rate'!$A$3:$C$24,3,FALSE) -> 4010 | M37: =TEXT(K37,"dddd") -> Monday | N37: 173.35 | O37: 0 | P37: 50 | Q37: 175 | R37: 53.35 | S37: =ROUND(Q37*10%,2) -> 17.5 | T37: 180 | U37: =(Q37+R37+T37)-(N37+O37+P37) -> 185
A38: PAID | B38: 1 | C38: =INDEX(PORT!$B$2:$B$20,MATCH('03'!B38,PORT!$A$2:$A$20)) -> PNH01 | D38: =INDEX(PORT!$C$2:$C$20,MATCH('03'!B38,PORT!$A$2:$A$20)) -> KTI AIR PORT | E38: E 11095 | F38: 46102 | G38: JIN YUAN XI | H38: GS26-105 | I38: DIS107 | J38: JYX2603007 | K38: 46104 | L38: =VLOOKUP(K38,'[3]Exchange Rate'!$A$3:$C$24,3,FALSE) -> 4010 | M38: =TEXT(K38,"dddd") -> Monday | N38: 251.41 | O38: 0 | P38: 50 | Q38: 210 | R38: 131.41 | S38: =ROUND(Q38*10%,2) -> 21 | T38: 180 | U38: =(Q38+R38+T38)-(N38+O38+P38) -> 220
A39: PAID | B39: 4 | C39: =INDEX(PORT!$B$2:$B$20,MATCH('03'!B39,PORT!$A$2:$A$20)) -> PNH04 | D39: =INDEX(PORT!$C$2:$C$20,MATCH('03'!B39,PORT!$A$2:$A$20)) -> PNH PORT | E39: E 78635 | F39: 46101 | G39: SPORTLINE | H39: GS26-106 | I39: DIS108 | J39: SAK2603008 | K39: 46104 | L39: =VLOOKUP(K39,'[3]Exchange Rate'!$A$3:$C$24,3,FALSE) -> 4010 | M39: =TEXT(K39,"dddd") -> Monday | N39: 579.25 | O39: 0 | P39: 50 | Q39: 245 | R39: 143.25 | S39: =ROUND(Q39*10%,2) -> 24.5 | T39: 602 | U39: =(Q39+R39+T39)-(N39+O39+P39) -> 361
A40: PAID | B40: 4 | C40: =INDEX(PORT!$B$2:$B$20,MATCH('03'!B40,PORT!$A$2:$A$20)) -> PNH04 | D40: =INDEX(PORT!$C$2:$C$20,MATCH('03'!B40,PORT!$A$2:$A$20)) -> PNH PORT | E40: E 79749 | F40: 46101 | G40: JR | H40: GS26-107 | I40: DIS109 | J40: JR2603006 | K40: 46104 | L40: =VLOOKUP(K40,'[3]Exchange Rate'!$A$3:$C$24,3,FALSE) -> 4010 | M40: =TEXT(K40,"dddd") -> Monday | N40: 541.85 | O40: 462 | P40: 0 | Q40: 213 | R40: 725.85 | S40: =ROUND(Q40*10%,2) -> 21.3 | T40: 741.5 | U40: =(Q40+R40+T40)-(N40+O40+P40) -> 676.5 | V40: HBL
A41: PAID | B41: 1 | C41: =INDEX(PORT!$B$2:$B$20,MATCH('03'!B41,PORT!$A$2:$A$20)) -> PNH01 | D41: =INDEX(PORT!$C$2:$C$20,MATCH('03'!B41,PORT!$A$2:$A$20)) -> KTI AIR PORT | E41: E 11240 | F41: 46104 | G41: SPORTLINE | H41: GS26-108 | I41: DIS110 | J41: SAK2603009 | K41: 46105 | L41: =VLOOKUP(K41,'[3]Exchange Rate'!$A$3:$C$24,3,FALSE) -> 4007 | M41: =TEXT(K41,"dddd") -> Tuesday | N41: 83.75 | O41: 0 | P41: 50 | Q41: 140 | R41: 13.75 | S41: =ROUND(Q41*10%,2) -> 14 | T41: 60 | U41: =(Q41+R41+T41)-(N41+O41+P41) -> 80
...

Sheet 04
E1: REVENUE & EXPENSE | M1: Saturday
A2: CHEA PAYMENT | B2: PORT NUMBER | C2: PORT CODE | D2: PORT NAME | E2: DECLARE | F2: DATE | G2: CLIENT | H2: INV | I2: DISBURSEMENT | J2: DN | K2: DATE | L2: EXCHANGE RATE | M2: weekday | N2: CLEAR FEE | O2: THC | P2: CM | Q2: INV (REVENUE) | R2: REIM | S2: VAT 10% | T2: DN | U2: NET PROFIT | V2: MARK
A3: PAID | B3: 11 | C3: =INDEX(PORT!$B$2:$B$20,MATCH('04'!B3,PORT!$A$2:$A$20)) -> SHV11 | D3: =INDEX(PORT!$C$2:$C$20,MATCH('04'!B3,PORT!$A$2:$A$20)) -> SHV PORT | E3: I 44874 | F3: 46113 | G3: JR | H3: GS26-118 | I3: DIS127 | J3: JR2604001 | K3: 46114 | L3: =VLOOKUP(K3,'[4]Exchange Rate'!$A$3:$C$21,3,FALSE) -> 3999 | M3: =TEXT(K3,"dddd") -> Thursday | N3: 925.95 | O3: 721.5 | P3: 0 | Q3: 200 | R3: 835.95 | S3: =ROUND(Q3*10%,2) -> 20 | T3: 869 | U3: =(Q3+R3+T3)-(N3+O3+P3) -> 257.5 | V3: THC PAID ON MAR
A4: PAID | B4: 1 | C4: =INDEX(PORT!$B$2:$B$20,MATCH('04'!B4,PORT!$A$2:$A$20)) -> PNH01 | D4: =INDEX(PORT!$C$2:$C$20,MATCH('04'!B4,PORT!$A$2:$A$20)) -> KTI AIR PORT | E4: E 12322 | F4: 46113 | G4: VFL | H4: GS26-119 | I4: DIS128 | J4: VFL2604001 | K4: 46114 | L4: =VLOOKUP(K4,'[4]Exchange Rate'!$A$3:$C$21,3,FALSE) -> 3999 | M4: =TEXT(K4,"dddd") -> Thursday | N4: 85.95 | O4: 0 | P4: 50 | Q4: 140 | R4: 15.95 | S4: =ROUND(Q4*10%,2) -> 14 | T4: 60 | U4: =(Q4+R4+T4)-(N4+O4+P4) -> 80
A5: PAID | B5: 11 | C5: =INDEX(PORT!$B$2:$B$20,MATCH('04'!B5,PORT!$A$2:$A$20)) -> SHV11 | D5: =INDEX(PORT!$C$2:$C$20,MATCH('04'!B5,PORT!$A$2:$A$20)) -> SHV PORT | E5: I 44741 | F5: 46113 | G5: VFL | H5: GS26-120 | I5: DIS129 | J5: VFL2604002 | K5: 46114 | L5: =VLOOKUP(K5,'[4]Exchange Rate'!$A$3:$C$21,3,FALSE) -> 3999 | M5: =TEXT(K5,"dddd") -> Thursday | N5: 349.01 | O5: 803.44 | P5: 50 | Q5: 150 | R5: 30.58 | S5: =ROUND(Q5*10%,2) -> 15 | T5: 401.12 | U5: =(Q5+R5+T5)-(N5+O5+P5) -> -620.75 | V5: THC PAID ON MAR
A6: PAID | B6: 1 | C6: =INDEX(PORT!$B$2:$B$20,MATCH('04'!B6,PORT!$A$2:$A$20)) -> PNH01 | D6: =INDEX(PORT!$C$2:$C$20,MATCH('04'!B6,PORT!$A$2:$A$20)) -> KTI AIR PORT | E6: E 12666 | F6: 46115 | G6: JIN YUAN XI | H6: GS26-121 | I6: DIS130 | J6: JYX2604001 | K6: 46118 | L6: =VLOOKUP(K6,'[4]Exchange Rate'!$A$3:$C$21,3,FALSE) -> 3999 | M6: =TEXT(K6,"dddd") -> Monday | N6: 204.41 | O6: 0 | P6: 50 | Q6: 175 | R6: 84.41 | S6: =ROUND(Q6*10%,2) -> 17.5 | T6: 180 | U6: =(Q6+R6+T6)-(N6+O6+P6) -> 185
A7: PAID | B7: 1 | C7: =INDEX(PORT!$B$2:$B$20,MATCH('04'!B7,PORT!$A$2:$A$20)) -> PNH01 | D7: =INDEX(PORT!$C$2:$C$20,MATCH('04'!B7,PORT!$A$2:$A$20)) -> KTI AIR PORT | E7: E 12814 | F7: 46116 | G7: JIN YUAN XI | H7: GS26-122 | I7: DIS131 | J7: JYX2604002 | K7: 46118 | L7: =VLOOKUP(K7,'[4]Exchange Rate'!$A$3:$C$21,3,FALSE) -> 3999 | M7: =TEXT(K7,"dddd") -> Monday | N7: 373.39 | O7: 0 | P7: 50 | Q7: 220 | R7: 203.39 | S7: =ROUND(Q7*10%,2) -> 22 | T7: 280 | U7: =(Q7+R7+T7)-(N7+O7+P7) -> 280
A8: PAID | B8: 1 | C8: =INDEX(PORT!$B$2:$B$20,MATCH('04'!B8,PORT!$A$2:$A$20)) -> PNH01 | D8: =INDEX(PORT!$C$2:$C$20,MATCH('04'!B8,PORT!$A$2:$A$20)) -> KTI AIR PORT | E8: E 12839 | F8: 46117 | G8: JIN YUAN XI | H8: GS26-123 | I8: DIS132 | J8: JYX2604003 | K8: 46118 | L8: =VLOOKUP(K8,'[4]Exchange Rate'!$A$3:$C$21,3,FALSE) -> 3999 | M8: =TEXT(K8,"dddd") -> Monday | N8: 224.21 | O8: 0 | P8: 50 | Q8: 175 | R8: 74.21 | S8: =ROUND(Q8*10%,2) -> 17.5 | T8: 230 | U8: =(Q8+R8+T8)-(N8+O8+P8) -> 205
A9: PAID | B9: 1 | C9: =INDEX(PORT!$B$2:$B$20,MATCH('04'!B9,PORT!$A$2:$A$20)) -> PNH01 | D9: =INDEX(PORT!$C$2:$C$20,MATCH('04'!B9,PORT!$A$2:$A$20)) -> KTI AIR PORT | E9: E 12840 | F9: 46117 | G9: JIN YUAN XI | H9: GS26-124 | I9: DIS133 | J9: JYX2604004 | K9: 46118 | L9: =VLOOKUP(K9,'[4]Exchange Rate'!$A$3:$C$21,3,FALSE) -> 3999 | M9: =TEXT(K9,"dddd") -> Monday | N9: 205.9 | O9: 0 | P9: 50 | Q9: 150 | R9: 55.9 | S9: =ROUND(Q9*10%,2) -> 15 | T9: 230 | U9: =(Q9+R9+T9)-(N9+O9+P9) -> 180
